Workbook

Sheet ปก (1)
A5: สมุดบันทึกผลการพัฒนาคุณภาพผู้เรียนรายวิชา (ปพ.5)
A6: โรงเรียนบ้านขัวก่าย อำเภอวานรนิวาส จังหวัดสกลนคร
A7: สังกัด สำนักงานเขตพื้นที่การศึกษาประถมศึกษาสกลนคร เขต 3
A8: สำนักงานคณะกรรมการการศึกษาขั้นพื้นฐาน กระทรวงศึกษาธิการ
C9: ระดับชั้นมัธยมศึกษาปีที่ 3 | J9: ภาคเรียนที่ 2 | M9: ปีการศึกษา | O9: 2568
C10: รายวิชา | E10: คอมพิวเตอร์ | J10: รหัสวิชา | L10: ว23201
C11: เวลาเรียน | E11: 2 | F11: ชั่วโมง / สัปดาห์ | J11: จำนวนหน่วยการเรียน | N11: 1 | O11: หน่วยกิต
C12: ครูผู้สอน | E12: นายวรวุฒิ มุงธิสาร
C13: ครูที่ปรึกษา | E13: นางสุดาพร คำเกาะ
C14: ครูที่ปรึกษา | E14: นายกัลป์วรรษ ดกเอียร์
A15: จำนวนนักเรียนทั้งหมด | C15: สรุปผลการเรียน
C16: จำนวนนักเรียนที่ได้ระดับผลการเรียน | K16: นักเรียนที่มีผลการเรียน | N16: ผลการเรียนเฉลี่ย | P16: ค่าเบี่ยงเบนมาตรฐาน
C17: 4 | D17: 3.5 | E17: 3 | F17: 2.5 | G17: 2 | H17: 1.5 | I17: 1 | J17: 0 | K17: ร | L17: มส | M17: มก | N17: (X-bar) | P17: (SD)
A18: =SUM(C18:M18) -> 16 | C18: =COUNTIF('สรุปผลรวม (8)'!$R$7:$R$22,'ปก (1)'!C17) -> 11 | D18: =COUNTIF('สรุปผลรวม (8)'!$R$7:$R$22,'ปก (1)'!D17) -> 2 | E18: =COUNTIF('สรุปผลรวม (8)'!$R$7:$R$22,'ปก (1)'!E17) -> 1 | F18: =COUNTIF('สรุปผลรวม (8)'!$R$7:$R$22,'ปก (1)'!F17) -> 2 | G18: =COUNTIF('สรุปผลรวม (8)'!$R$7:$R$22,'ปก (1)'!G17) -> 0 | H18: =COUNTIF('สรุปผลรวม (8)'!$R$7:$R$22,'ปก (1)'!H17) -> 0 | I18: =COUNTIF('สรุปผลรวม (8)'!$R$7:$R$22,'ปก (1)'!I17) -> 0 | J18: =COUNTIF('สรุปผลรวม (8)'!$R$7:$R$22,'ปก (1)'!J17) -> 0 | ... M18: =COUNTIF('สรุปผลรวม (8)'!$R$7:$R$22,'ปก (1)'!M17) -> 0 | N18: =AVERAGE('สรุปผลรวม (8)'!$R$7:$R$22) -> 3.6875 | P18: =STDEV('สรุปผลรวม (8)'!$R$7:$R$22) -> 0.54390563
A20: จำนวนนักเรียนทั้งหมด | D20: ผลการประเมินคุณลักษณะอันพึงประสงค์ | H20: ผลการประเมินการอ่านคิดวิเคราะห์และเขียนสื่อความ | L20: ผลการประเมินสมรรถนะสำคัญของผู้เรียน
D21: 3 | E21: 2 | F21: 1 | G21: 0 | H21: 3 | I21: 2 | J21: 1 | K21: 0 | L21: 3 | M21: 2 | N21: 1 | O21: 0
A22: =A18 -> 16 | D22: =COUNTIF('คุณลักษณะ อ่าน สมรรถนะ (9)'!$K$5:$K$20,'ปก (1)'!D21) -> 16 | E22: =COUNTIF('คุณลักษณะ อ่าน สมรรถนะ (9)'!$K$5:$K$20,'ปก (1)'!E21) -> 0 | F22: =COUNTIF('คุณลักษณะ อ่าน สมรรถนะ (9)'!$K$5:$K$20,'ปก (1)'!F21) -> 0 | G22: =COUNTIF('คุณลักษณะ อ่าน สมรรถนะ (9)'!$K$5:$K$20,'ปก (1)'!G21) -> 0 | H22: =COUNTIF('คุณลักษณะ อ่าน สมรรถนะ (9)'!$R$5:$R$20,'ปก (1)'!H21) -> 14 | I22: =COUNTIF('คุณลักษณะ อ่าน สมรรถนะ (9)'!$R$5:$R$20,'ปก (1)'!I21) -> 2 | J22: =COUNTIF('คุณลักษณะ อ่าน สมรรถนะ (9)'!$R$5:$R$20,'ปก (1)'!J21) -> 0 | K22: =COUNTIF('คุณลักษณะ อ่าน สมรรถนะ (9)'!$R$5:$R$20,'ปก (1)'!K21) -> 0 | L22: =COUNTIF('คุณลักษณะ อ่าน สมรรถนะ (9)'!$Y$5:$Y$20,'ปก (1)'!L21) -> 13 | M22: =COUNTIF('คุณลักษณะ อ่าน สมรรถนะ (9)'!$Y$5:$Y$20,'ปก (1)'!M21) -> 3 | N22: =COUNTIF('คุณลักษณะ อ่าน สมรรถนะ (9)'!$Y$5:$Y$20,'ปก (1)'!N21) -> 0 | O22: =COUNTIF('คุณลักษณะ อ่าน สมรรถนะ (9)'!$Y$5:$Y$20,'ปก (1)'!O21) -> 0
A24: อนุมัติผลการเรียน
A25: ลงชื่อ……………………………………..ครูผู้สอน | I25: ลงชื่อ……………………………………หัวหน้ากลุ่มสาระการเรียนรู้
F27: ลงชื่อ…………………………………...………เจ้าหน้าที่วัดผลและประเมินผล
F29: ลงชื่อ………………………..…………...….…หัวหน้างานวัดผลและประเมินผล
A30: เรียนเสนอเพื่อพิจารณา
F32: ลงชื่อ…………………………………………….. | K32: หัวหน้ากลุ่มงานวิชาการ
E34: ☐ | F34: อนุมัติ | I34: ☐ | J34: ไม่อนุมัติ
F36: ลงชื่อ……………………………………………..
E37: ผู้อำนวยการโรงเรียนบ้านขัวก่าย
E38: ………/…………/……….

Sheet เวลาเรียน (2)
BB1: 2
A2: เลขที่ | B2: เลขประจำตัว | C2: ชื่อ - สกุล | D2: เดือน | G2: พ.ย. | N2: พ.ย. | U2: พ.ย. | AB2: พ.ย. | AI2: พ.ย. | AP2: ธ.ค. | AW2: ธ.ค.
D3: สัปดาห์ที่ | G3: 1 | N3: 2 | U3: 3 | AB3: 4 | AI3: 5 | AP3: 6 | AW3: 7
D4: วันที่ | G4: 2 | H4: 3 | I4: 4 | J4: 5 | K4: 6 | L4: 7 | M4: 8 | N4: 9 | O4: 10 | P4: 11 | Q4: 12 | R4: 13 | S4: 14 | T4: 15 | U4: 16 | V4: 17 | W4: 18 | X4: 19 | Y4: 20 | Z4: 21 | AA4: 22 | AB4: 23 | AC4: 24 | AD4: 25 | AE4: 26 | AF4: 27 | AG4: 28 | AH4: 29 | AI4: 30 | AJ4: 1 | AK4: 2 | AL4: 3 | AM4: 4 | AN4: 5 | AO4: 6 | AP4: 7 | AQ4: 8 | AR4: 9 | AS4: 10 | AT4: 11 | AU4: 12 | AV4: 13 | AW4: 14 | AX4: 15 | AY4: 16 | AZ4: 17 | BA4: 18 | BB4: 19 | BC4: 20
D5: ชั่วโมงที่
A6: 1 | B6: 4833 | C6: เด็กชายพงษ์ศิริ พิมโยธา
A7: 2 | B7: 4832 | C7: เด็กชายพงศ์พิเชษฐ์ มาสีปา
A8: 3 | B8: 4836 | C8: เด็กชายรพีภัทร แสดคง
A9: 4 | B9: 4837 | C9: เด็กชายวัชรากร โพธิ์ศรี
A10: 5 | B10: 4897 | C10: เด็กชายธนกฤต ดกเอียร์
A11: 6 | B11: 4927 | C11: เด็กชายขัตติยะ ไตรวงค์ย้อย
A12: 7 | B12: 4835 | C12: เด็กชายภูวนัตถ์ บุญมาก
A13: 8 | B13: 4842 | C13: เด็กหญิงบงกช แสงนนท์
A14: 9 | B14: 4838 | C14: เด็กหญิงกุลฑีรา มังฉกรรจ์
A15: 10 | B15: 4845 | C15: เด็กหญิงสุชาวดี ไฮวัง
A16: 11 | B16: 4846 | C16: เด็กหญิงธนิดา แก้วมุงคุณ
A17: 12 | B17: 4840 | C17: เด็กหญิงธัญญารัตน์ ไชยเทพ
... A21: 16 | B21: 5013 | C21: เด็กชายนันทกร ปรางค์ทอง

Sheet เวลาเรียน (3)
BB1: 3
A2: เลขที่ | B2: เลขประจำตัว | C2: ชื่อ - สกุล | D2: เดือน | G2: ธ.ค. | N2: ธ.ค. | U2: ม.ค. | AB2: ม.ค. | AI2: ม.ค. | AP2: ม.ค. | AW2: ก.พ.
D3: สัปดาห์ที่ | G3: 8 | N3: 9 | U3: 10 | AB3: 11 | AI3: 12 | AP3: 13 | AW3: 14
D4: วันที่ | G4: 21 | H4: 22 | I4: 23 | J4: 24 | K4: 25 | L4: 26 | M4: 27 | N4: 28 | O4: 29 | P4: 30 | Q4: 31 | R4: 1 | S4: 2 | T4: 3 | U4: 4 | V4: 5 | W4: 6 | X4: 7 | Y4: 8 | Z4: 9 | AA4: 10 | AB4: 11 | AC4: 12 | AD4: 13 | AE4: 14 | AF4: 15 | AG4: 16 | AH4: 17 | AI4: 18 | AJ4: 19 | AK4: 20 | AL4: 21 | AM4: 22 | AN4: 23 | AO4: 24 | AP4: 25 | AQ4: 26 | AR4: 27 | AS4: 28 | AT4: 29 | AU4: 30 | AV4: 31 | AW4: 1 | AX4: 2 | AY4: 3 | AZ4: 4 | BA4: 5 | BB4: 6 | BC4: 7
D5: ชั่วโมงที่
A6: 1 | B6: 4833 | C6: เด็กชายพงษ์ศิริ พิมโยธา
A7: 2 | B7: 4832 | C7: เด็กชายพงศ์พิเชษฐ์ มาสีปา | AJ7: ข | AQ7: ข
A8: 3 | B8: 4836 | C8: เด็กชายรพีภัทร แสดคง
A9: 4 | B9: 4837 | C9: เด็กชายวัชรากร โพธิ์ศรี
A10: 5 | B10: 4897 | C10: เด็กชายธนกฤต ดกเอียร์ | AQ10: ข
A11: 6 | B11: 4927 | C11: เด็กชายขัตติยะ ไตรวงค์ย้อย | AJ11: ข | AQ11: ข
A12: 7 | B12: 4835 | C12: เด็กชายภูวนัตถ์ บุญมาก | AC12: ข | AQ12: ข
A13: 8 | B13: 4842 | C13: เด็กหญิงบงกช แสงนนท์ | AQ13: ข
A14: 9 | B14: 4838 | C14: เด็กหญิงกุลฑีรา มังฉกรรจ์
A15: 10 | B15: 4845 | C15: เด็กหญิงสุชาวดี ไฮวัง
A16: 11 | B16: 4846 | C16: เด็กหญิงธนิดา แก้วมุงคุณ
A17: 12 | B17: 4840 | C17: เด็กหญิงธัญญารัตน์ ไชยเทพ
A18: 13 | B18: 4841 | C18: เด็กหญิงนภัสสร ประฮาดไชย
A19: 14 | B19: 4843 | C19: เด็กหญิงมณีญานันท์ คำปัญโญ
A20: 15 | B20: 5012 | C20: เด็กหญิงธัญชนก อินทรภูมิ | AC20: ข
A21: 16 | B21: 5013 | C21: เด็กชายนันทกร ปรางค์ทอง

Sheet เวลาเรียน (4)
AX1: 4
A2: เลขที่ | B2: เลขประจำตัว | C2: ชื่อ - สกุล | E2: เดือน | H2: ก.พ. | O2: ก.พ. | V2: ก.พ. | AC2: มี.ค. | AJ2: มี.ค. | AQ2: มี.ค. | AX2: รวม
E3: สัปดาห์ที่ | H3: 15 | O3: 16 | V3: 17 | AC3: 18 | AJ3: 19 | AQ3: 20 | AX3: ปลาย
E4: วันที่ | H4: 8 | I4: 9 | J4: 10 | K4: 11 | L4: 12 | M4: 13 | N4: 14 | O4: 15 | P4: 16 | Q4: 17 | R4: 18 | S4: 19 | T4: 20 | U4: 21 | V4: 22 | W4: 23 | X4: 24 | Y4: 25 | Z4: 26 | AA4: 27 | AB4: 28 | AC4: 1 | AD4: 2 | AE4: 3 | AF4: 4 | AG4: 5 | AH4: 6 | AI4: 7 | AJ4: 8 | AK4: 9 | AL4: 10 | AM4: 11 | AN4: 12 | AO4: 13 | AP4: 14 | AQ4: 15 | AR4: 16 | AS4: 17 | AT4: 18 | AU4: 19 | AV4: 20 | AW4: 21 | AX4: ='ปก (1)'!N11*40 -> 40
E5: ชั่วโมงที่ | AX5: =AX4*80/100 -> 32
A6: 1 | B6: ='เวลาเรียน (2)'!B6 -> 4833 | C6: ='เวลาเรียน (2)'!C6 -> เด็กชายพงษ์ศิริ พิมโยธา | W6: ข | AX6: 38
A7: 2 | B7: ='เวลาเรียน (2)'!B7 -> 4832 | C7: ='เวลาเรียน (2)'!C7 -> เด็กชายพงศ์พิเชษฐ์ มาสีปา | P7: ข | W7: ข | AK7: ข | AX7: 30
A8: 3 | B8: ='เวลาเรียน (2)'!B8 -> 4836 | C8: ='เวลาเรียน (2)'!C8 -> เด็กชายรพีภัทร แสดคง | W8: ข | AX8: 38
A9: 4 | B9: ='เวลาเรียน (2)'!B9 -> 4837 | C9: ='เวลาเรียน (2)'!C9 -> เด็กชายวัชรากร โพธิ์ศรี | W9: ข | AX9: 38
A10: 5 | B10: ='เวลาเรียน (2)'!B10 -> 4897 | C10: ='เวลาเรียน (2)'!C10 -> เด็กชายธนกฤต ดกเอียร์ | P10: ข | W10: ข | AX10: 34
A11: 6 | B11: ='เวลาเรียน (2)'!B11 -> 4927 | C11: ='เวลาเรียน (2)'!C11 -> เด็กชายขัตติยะ ไตรวงค์ย้อย | P11: ข | W11: ข | AK11: ข | AX11: 30
A12: 7 | B12: ='เวลาเรียน (2)'!B12 -> 4835 | C12: ='เวลาเรียน (2)'!C12 -> เด็กชายภูวนัตถ์ บุญมาก | W12: ข | AK12: ข | AX12: 32
A13: 8 | B13: ='เวลาเรียน (2)'!B13 -> 4842 | C13: ='เวลาเรียน (2)'!C13 -> เด็กหญิงบงกช แสงนนท์ | W13: ข | AX13: 36
A14: 9 | B14: ='เวลาเรียน (2)'!B14 -> 4838 | C14: ='เวลาเรียน (2)'!C14 -> เด็กหญิงกุลฑีรา มังฉกรรจ์ | W14: ข | AX14: 38
A15: 10 | B15: ='เวลาเรียน (2)'!B15 -> 4845 | C15: ='เวลาเรียน (2)'!C15 -> เด็กหญิงสุชาวดี ไฮวัง | W15: ข | AX15: 38
A16: 11 | B16: ='เวลาเรียน (2)'!B16 -> 4846 | C16: ='เวลาเรียน (2)'!C16 -> เด็กหญิงธนิดา แก้วมุงคุณ | W16: ข | AX16: 38
A17: 12 | B17: ='เวลาเรียน (2)'!B17 -> 4840 | C17: ='เวลาเรียน (2)'!C17 -> เด็กหญิงธัญญารัตน์ ไชยเทพ | W17: ข | AX17: 38
A18: 13 | B18: ='เวลาเรียน (2)'!B18 -> 4841 | C18: ='เวลาเรียน (2)'!C18 -> เด็กหญิงนภัสสร ประฮาดไชย | W18: ข | AX18: 38
A19: 14 | B19: ='เวลาเรียน (2)'!B19 -> 4843 | C19: ='เวลาเรียน (2)'!C19 -> เด็กหญิงมณีญานันท์ คำปัญโญ | P19: ล | W19: ข | AX19: 36
A20: 15 | B20: ='เวลาเรียน (2)'!B20 -> 5012 | C20: ='เวลาเรียน (2)'!C20 -> เด็กหญิงธัญชนก อินทรภูมิ | W20: ข | AX20: 36
A21: 16 | B21: ='เวลาเรียน (2)'!B21 -> 5013 | C21: ='เวลาเรียน (2)'!C21 -> เด็กชายนันทกร ปรางค์ทอง | P21: ข | W21: ข | AK21: ข | AX21: 34

Sheet หน่วย 1,4 (5)
AD1: 5
A2: หน่วยการเรียนรู้ที่ | C2: 1 | J2: 2 | Q2: 3 | X2: 4
C3: ตัวชี้วัด/ผลการเรียนรู้ | H3: รวม | I3: ซ่อมเสริม | J3: ตัวชี้วัด/ผลการเรียนรู้ | O3: รวม | P3: ซ่อมเสริม | Q3: ตัวชี้วัด/ผลการเรียนรู้ | V3: รวม | W3: ซ่อมเสริม | X3: ตัวชี้วัด/ผลการเรียนรู้ | AC3: รวม | AD3: ซ่อมเสริม
B4: แผน / ข้อที่ | C4: 1 | D4: 2 | E4: 3 | F4: 4 | G4: 5 | J4: 1 | K4: 2 | L4: 3 | M4: 4 | N4: 5 | Q4: 1 | R4: 2 | S4: 3 | T4: 4 | U4: 5 | X4: 1 | Y4: 2 | Z4: 3 | AA4: 4 | AB4: 5
C5: 20 | J5: 20 | Q5: 20 | X5: 0
A6: 1 | B6: เด็กชายพงษ์ศิริ พิมโยธา | C6: 17 | H6: 17 | J6: 4 | K6: 4 | L6: 9 | O6: 17 | Q6: 18 | V6: 18 | AC6: 0
A7: 2 | B7: เด็กชายพงศ์พิเชษฐ์ มาสีปา | C7: 13 | H7: 13 | J7: 3 | K7: 3 | L7: 6 | O7: 12 | Q7: 13 | V7: 13 | AC7: 0
A8: 3 | B8: เด็กชายรพีภัทร แสดคง | C8: 16 | H8: 16 | J8: 5 | K8: 5 | L8: 10 | O8: 20 | Q8: 18 | V8: 18 | AC8: 0
A9: 4 | B9: เด็กชายวัชรากร โพธิ์ศรี | C9: 10 | H9: 10 | J9: 5 | K9: 5 | L9: 10 | O9: 20 | Q9: 18 | V9: 18 | AC9: 0
A10: 5 | B10: เด็กชายธนกฤต ดกเอียร์ | C10: 13 | H10: 13 | J10: 5 | K10: 5 | L10: 10 | O10: 20 | Q10: 16 | V10: 16 | AC10: 0
A11: 6 | B11: เด็กชายขัตติยะ ไตรวงค์ย้อย | C11: 13 | H11: 13 | J11: 3 | K11: 3 | L11: 7 | O11: 13 | Q11: 12 | V11: 12 | AC11: 0
A12: 7 | B12: เด็กชายภูวนัตถ์ บุญมาก | C12: 17 | H12: 17 | J12: 5 | K12: 5 | L12: 10 | O12: 20 | Q12: 13 | V12: 13 | AC12: 0
A13: 8 | B13: เด็กหญิงบงกช แสงนนท์ | C13: 18 | H13: 18 | J13: 5 | K13: 5 | L13: 10 | O13: 20 | Q13: 18 | V13: 18 | AC13: 0
A14: 9 | B14: เด็กหญิงกุลฑีรา มังฉกรรจ์ | C14: 18 | H14: 18 | J14: 5 | K14: 5 | L14: 10 | O14: 20 | Q14: 18 | V14: 18 | AC14: 0
A15: 10 | B15: เด็กหญิงสุชาวดี ไฮวัง | C15: 17 | H15: 17 | J15: 5 | K15: 5 | L15: 10 | O15: 20 | Q15: 18 | V15: 18 | AC15: 0
A16: 11 | B16: เด็กหญิงธนิดา แก้วมุงคุณ | C16: 17 | H16: 17 | J16: 5 | K16: 5 | L16: 10 | O16: 20 | Q16: 18 | V16: 18 | AC16: 0
A17: 12 | B17: เด็กหญิงธัญญารัตน์ ไชยเทพ | C17: 15 | H17: 15 | J17: 5 | K17: 5 | L17: 10 | O17: 20 | Q17: 10 | V17: 10 | AC17: 0
... A21: 16 | B21: เด็กชายนันทกร ปรางค์ทอง | C21: 14 | H21: 14 | J21: 5 | K21: 5 | L21: 10 | O21: 20 | Q21: 10 | V21: 10 | AC21: 0

Sheet หน่วย 5,8 (6)
AD1: 6
A2: หน่วยการเรียนรู้ที่ | C2: 5 | J2: 6 | Q2: 7 | X2: 8
C3: ตัวชี้วัด/ผลการเรียนรู้ | H3: รวม | I3: ซ่อมเสริม | J3: ตัวชี้วัด/ผลการเรียนรู้ | O3: รวม | P3: ซ่อมเสริม | Q3: ตัวชี้วัด/ผลการเรียนรู้ | V3: รวม | W3: ซ่อมเสริม | X3: ตัวชี้วัด/ผลการเรียนรู้ | AC3: รวม | AD3: ซ่อมเสริม
B4: แผน / ข้อที่ | C4: 1 | D4: 2 | E4: 3 | F4: 4 | G4: 5 | J4: 1 | K4: 2 | L4: 3 | M4: 4 | N4: 5 | Q4: 1 | R4: 2 | S4: 3 | T4: 4 | U4: 5 | X4: 1 | Y4: 2 | Z4: 3 | AA4: 4 | AB4: 5
C5: 0 | J5: 0 | Q5: 0 | X5: 0
A6: 1 | B6: เด็กชายพงษ์ศิริ พิมโยธา | H6: 0 | O6: 0 | V6: 0 | AC6: 0
A7: 2 | B7: เด็กชายพงศ์พิเชษฐ์ มาสีปา | H7: 0 | O7: 0 | V7: 0 | AC7: 0
A8: 3 | B8: เด็กชายรพีภัทร แสดคง | H8: 0 | O8: 0 | V8: 0 | AC8: 0
A9: 4 | B9: เด็กชายวัชรากร โพธิ์ศรี | H9: 0 | O9: 0 | V9: 0 | AC9: 0
A10: 5 | B10: เด็กชายธนกฤต ดกเอียร์ | H10: 0 | O10: 0 | V10: 0 | AC10: 0
A11: 6 | B11: เด็กชายขัตติยะ ไตรวงค์ย้อย | H11: 0 | O11: 0 | V11: 0 | AC11: 0
A12: 7 | B12: เด็กชายภูวนัตถ์ บุญมาก | H12: 0 | O12: 0 | V12: 0 | AC12: 0
A13: 8 | B13: เด็กหญิงบงกช แสงนนท์ | H13: 0 | O13: 0 | V13: 0 | AC13: 0
A14: 9 | B14: เด็กหญิงกุลฑีรา มังฉกรรจ์ | H14: 0 | O14: 0 | V14: 0 | AC14: 0
A15: 10 | B15: เด็กหญิงสุชาวดี ไฮวัง | H15: 0 | O15: 0 | V15: 0 | AC15: 0
A16: 11 | B16: เด็กหญิงธนิดา แก้วมุงคุณ | H16: 0 | O16: 0 | V16: 0 | AC16: 0
A17: 12 | B17: เด็กหญิงธัญญารัตน์ ไชยเทพ | H17: 0 | O17: 0 | V17: 0 | AC17: 0
... A21: 16 | B21: เด็กชายนันทกร ปรางค์ทอง | H21: 0 | O21: 0 | V21: 0 | AC21: 0

Sheet หน่วย 9,12 (7)
AD1: 7
A2: หน่วยการเรียนรู้ที่ | C2: 9 | J2: 10 | Q2: 11 | X2: 12
C3: ตัวชี้วัด/ผลการเรียนรู้ | H3: รวม | I3: ซ่อมเสริม | J3: ตัวชี้วัด/ผลการเรียนรู้ | O3: รวม | P3: ซ่อมเสริม | Q3: ตัวชี้วัด/ผลการเรียนรู้ | V3: รวม | W3: ซ่อมเสริม | X3: ตัวชี้วัด/ผลการเรียนรู้ | AC3: รวม | AD3: ซ่อมเสริม
B4: แผน / ข้อที่ | C4: 1 | D4: 2 | E4: 3 | F4: 4 | G4: 5 | J4: 1 | K4: 2 | L4: 3 | M4: 4 | N4: 5 | Q4: 1 | R4: 2 | S4: 3 | T4: 4 | U4: 5 | X4: 1 | Y4: 2 | Z4: 3 | AA4: 4 | AB4: 5
C5: 0 | J5: 0 | Q5: 0 | X5: 0
A6: 1 | B6: เด็กชายพงษ์ศิริ พิมโยธา | H6: 0 | O6: 0 | V6: 0 | AC6: 0
A7: 2 | B7: เด็กชายพงศ์พิเชษฐ์ มาสีปา | H7: 0 | O7: 0 | V7: 0 | AC7: 0
A8: 3 | B8: เด็กชายรพีภัทร แสดคง | H8: 0 | O8: 0 | V8: 0 | AC8: 0
A9: 4 | B9: เด็กชายวัชรากร โพธิ์ศรี | H9: 0 | O9: 0 | V9: 0 | AC9: 0
A10: 5 | B10: เด็กชายธนกฤต ดกเอียร์ | H10: 0 | O10: 0 | V10: 0 | AC10: 0
A11: 6 | B11: เด็กชายขัตติยะ ไตรวงค์ย้อย | H11: 0 | O11: 0 | V11: 0 | AC11: 0
A12: 7 | B12: เด็กชายภูวนัตถ์ บุญมาก | H12: 0 | O12: 0 | V12: 0 | AC12: 0
A13: 8 | B13: เด็กหญิงบงกช แสงนนท์ | H13: 0 | O13: 0 | V13: 0 | AC13: 0
A14: 9 | B14: เด็กหญิงกุลฑีรา มังฉกรรจ์ | H14: 0 | O14: 0 | V14: 0 | AC14: 0
A15: 10 | B15: เด็กหญิงสุชาวดี ไฮวัง | H15: 0 | O15: 0 | V15: 0 | AC15: 0
A16: 11 | B16: เด็กหญิงธนิดา แก้วมุงคุณ | H16: 0 | O16: 0 | V16: 0 | AC16: 0
A17: 12 | B17: เด็กหญิงธัญญารัตน์ ไชยเทพ | H17: 0 | O17: 0 | V17: 0 | AC17: 0
... A21: 16 | B21: เด็กชายนันทกร ปรางค์ทอง | H21: 0 | O21: 0 | V21: 0 | AC21: 0

Sheet สรุปผลรวม (8)
S1: 8
A2: สรุปผลการประเมินคุณภาพผู้เรียน
A3: คะแนนรวม | C3: คะแนนหน่วยที่ | O3: สอบ | P3: สอบ | Q3: ผลการประเมิน
O4: กลาง | P4: ปลาย | Q4: รวม | R4: ระดับ
A5: หน่วยการเรียนรู้ | C5: 1 | D5: 2 | E5: 3 | F5: 4 | G5: 5 | H5: 6 | I5: 7 | J5: 8 | K5: 9 | L5: 10 | M5: 11 | N5: 12 | O5: ภาค | P5: ภาค | R5: ผล
C6: 20 | D6: 20 | E6: 20 | F6: 0 | G6: 0 | H6: 0 | I6: 0 | J6: 0 | K6: 0 | L6: 0 | M6: 0 | N6: 0 | O6: 20 | P6: 20 | Q6: 100
A7: 1 | B7: เด็กชายพงษ์ศิริ พิมโยธา | C7: 17 | D7: 17 | E7: 18 | F7: 0 | G7: 0 | H7: 0 | I7: 0 | J7: 0 | K7: 0 | L7: 0 | M7: 0 | N7: 0 | O7: 17 | P7: 18 | Q7: 87 | R7: 4
A8: 2 | B8: เด็กชายพงศ์พิเชษฐ์ มาสีปา | C8: 13 | D8: 12 | E8: 13 | F8: 0 | G8: 0 | H8: 0 | I8: 0 | J8: 0 | K8: 0 | L8: 0 | M8: 0 | N8: 0 | O8: 13 | P8: 14 | Q8: 65 | R8: 2.5
A9: 3 | B9: เด็กชายรพีภัทร แสดคง | C9: 16 | D9: 20 | E9: 18 | F9: 0 | G9: 0 | H9: 0 | I9: 0 | J9: 0 | K9: 0 | L9: 0 | M9: 0 | N9: 0 | O9: 19 | P9: 18 | Q9: 91 | R9: 4
A10: 4 | B10: เด็กชายวัชรากร โพธิ์ศรี | C10: 10 | D10: 20 | E10: 18 | F10: 0 | G10: 0 | H10: 0 | I10: 0 | J10: 0 | K10: 0 | L10: 0 | M10: 0 | N10: 0 | O10: 19 | P10: 18 | Q10: 85 | R10: 4
A11: 5 | B11: เด็กชายธนกฤต ดกเอียร์ | C11: 13 | D11: 20 | E11: 16 | F11: 0 | G11: 0 | H11: 0 | I11: 0 | J11: 0 | K11: 0 | L11: 0 | M11: 0 | N11: 0 | O11: 17 | P11: 16 | Q11: 82 | R11: 4
A12: 6 | B12: เด็กชายขัตติยะ ไตรวงค์ย้อย | C12: 13 | D12: 13 | E12: 12 | F12: 0 | G12: 0 | H12: 0 | I12: 0 | J12: 0 | K12: 0 | L12: 0 | M12: 0 | N12: 0 | O12: 13 | P12: 14 | Q12: 65 | R12: 2.5
A13: 7 | B13: เด็กชายภูวนัตถ์ บุญมาก | C13: 17 | D13: 20 | E13: 13 | F13: 0 | G13: 0 | H13: 0 | I13: 0 | J13: 0 | K13: 0 | L13: 0 | M13: 0 | N13: 0 | O13: 16 | P13: 14 | Q13: 80 | R13: 4
A14: 8 | B14: เด็กหญิงบงกช แสงนนท์ | C14: 18 | D14: 20 | E14: 18 | F14: 0 | G14: 0 | H14: 0 | I14: 0 | J14: 0 | K14: 0 | L14: 0 | M14: 0 | N14: 0 | O14: 19 | P14: 18 | Q14: 93 | R14: 4
A15: 9 | B15: เด็กหญิงกุลฑีรา มังฉกรรจ์ | C15: 18 | D15: 20 | E15: 18 | F15: 0 | G15: 0 | H15: 0 | I15: 0 | J15: 0 | K15: 0 | L15: 0 | M15: 0 | N15: 0 | O15: 18 | P15: 19 | Q15: 93 | R15: 4
A16: 10 | B16: เด็กหญิงสุชาวดี ไฮวัง | C16: 17 | D16: 20 | E16: 18 | F16: 0 | G16: 0 | H16: 0 | I16: 0 | J16: 0 | K16: 0 | L16: 0 | M16: 0 | N16: 0 | O16: 18 | P16: 19 | Q16: 92 | R16: 4
A17: 11 | B17: เด็กหญิงธนิดา แก้วมุงคุณ | C17: 17 | D17: 20 | E17: 18 | F17: 0 | G17: 0 | H17: 0 | I17: 0 | J17: 0 | K17: 0 | L17: 0 | M17: 0 | N17: 0 | O17: 18 | P17: 19 | Q17: 92 | R17: 4
A18: 12 | B18: เด็กหญิงธัญญารัตน์ ไชยเทพ | C18: 15 | D18: 20 | E18: 10 | F18: 0 | G18: 0 | H18: 0 | I18: 0 | J18: 0 | K18: 0 | L18: 0 | M18: 0 | N18: 0 | O18: 15 | P18: 15 | Q18: 75 | R18: 3.5
... A22: 16 | B22: เด็กชายนันทกร ปรางค์ทอง | C22: 14 | D22: 20 | E22: 10 | F22: 0 | G22: 0 | H22: 0 | I22: 0 | J22: 0 | K22: 0 | L22: 0 | M22: 0 | N22: 0 | O22: 17 | P22: 16 | Q22: 77 | R22: 3.5

Sheet คุณลักษณะ อ่าน สมรรถนะ (9)
Z1: 9
A2: ผลการประเมินคุณภาพผู้เรียน | C2: คุณลักษณะอันพึงประสงค์ | M2: การอ่าน การคิดวิเคราะห์ และเขียนสื่อความ | T2: สมรรถนะสำคัญของผู้เรียน
A3: เลขที่ | B3: หน่วย | C3: 1. รักชาติศาสน์กษัตริย์ | D3: 2.ซื่อสัตย์สุจริต | E3: 3. วินัย | F3: 4.ใฝ่เรียนรู้ | G3: 5.อยู่อย่างพอเพียง | H3: 6.มุ่งมั่นทำงาน | I3: 7. รักความเป็นไทย | J3: 8.มีจิตสาธารณะ | K3: สรุปผลรวม | L3: หมายเหตุ | M3: 1. การคัดสรรสื่อ | N3: 2. จับประเด็นสำคัญ | O3: 3. วิเคราะห์ วิจารณ์ | P3: 4. สรุปคุณค่า แง่คิดที่ดี | Q3: 5. สรุปอภิปรายขยายความ | R3: สรุปผลรวม | S3: หมายเหตุ | T3: 1. การสื่อสาร | U3: 2. การคิด | V3: 3. การแก้ปัญหา | W3: 4. การใช้ทักษะชีวิต | X3: 5. การใช้เทคโนโลยี | Y3: สรุปผลรวม | Z3: หมายเหตุ
B4: ชื่อ-สกุล | C4: 3 | D4: 3 | E4: 3 | F4: 3 | G4: 3 | H4: 3 | I4: 3 | J4: 3 | K4: 3 | M4: 3 | N4: 3 | O4: 3 | P4: 3 | Q4: 3 | R4: 3 | T4: 3 | U4: 3 | V4: 3 | W4: 3 | X4: 3 | Y4: 3
A5: 1 | B5: เด็กชายพงษ์ศิริ พิมโยธา | C5: 3 | D5: 3 | E5: 3 | F5: 3 | G5: 3 | H5: 3 | I5: 3 | J5: 3 | K5: 3 | M5: 3 | N5: 3 | O5: 3 | P5: 3 | Q5: 3 | R5: 3 | T5: 3 | U5: 3 | V5: 3 | W5: 3 | X5: 3 | Y5: 3
A6: 2 | B6: เด็กชายพงศ์พิเชษฐ์ มาสีปา | C6: 3 | D6: 3 | E6: 3 | F6: 2 | G6: 3 | H6: 2 | I6: 3 | J6: 3 | K6: 3 | M6: 2 | N6: 2 | O6: 2 | P6: 2 | Q6: 2 | R6: 2 | T6: 2 | U6: 2 | V6: 2 | W6: 2 | X6: 2 | Y6: 2
A7: 3 | B7: เด็กชายรพีภัทร แสดคง | C7: 3 | D7: 3 | E7: 3 | F7: 3 | G7: 3 | H7: 3 | I7: 3 | J7: 3 | K7: 3 | M7: 3 | N7: 3 | O7: 3 | P7: 3 | Q7: 3 | R7: 3 | T7: 3 | U7: 3 | V7: 3 | W7: 3 | X7: 3 | Y7: 3
A8: 4 | B8: เด็กชายวัชรากร โพธิ์ศรี | C8: 3 | D8: 3 | E8: 3 | F8: 3 | G8: 3 | H8: 3 | I8: 3 | J8: 3 | K8: 3 | M8: 3 | N8: 3 | O8: 3 | P8: 3 | Q8: 3 | R8: 3 | T8: 3 | U8: 3 | V8: 3 | W8: 3 | X8: 3 | Y8: 3
A9: 5 | B9: เด็กชายธนกฤต ดกเอียร์ | C9: 3 | D9: 3 | E9: 3 | F9: 3 | G9: 3 | H9: 3 | I9: 3 | J9: 3 | K9: 3 | M9: 3 | N9: 3 | O9: 3 | P9: 3 | Q9: 3 | R9: 3 | T9: 3 | U9: 3 | V9: 3 | W9: 3 | X9: 3 | Y9: 3
A10: 6 | B10: เด็กชายขัตติยะ ไตรวงค์ย้อย | C10: 3 | D10: 3 | E10: 3 | F10: 2 | G10: 3 | H10: 2 | I10: 3 | J10: 3 | K10: 3 | M10: 2 | N10: 2 | O10: 2 | P10: 2 | Q10: 2 | R10: 2 | T10: 2 | U10: 2 | V10: 2 | W10: 2 | X10: 2 | Y10: 2
A11: 7 | B11: เด็กชายภูวนัตถ์ บุญมาก | C11: 3 | D11: 3 | E11: 3 | F11: 3 | G11: 3 | H11: 3 | I11: 3 | J11: 3 | K11: 3 | M11: 3 | N11: 3 | O11: 3 | P11: 3 | Q11: 3 | R11: 3 | T11: 3 | U11: 3 | V11: 3 | W11: 3 | X11: 3 | Y11: 3
A12: 8 | B12: เด็กหญิงบงกช แสงนนท์ | C12: 3 | D12: 3 | E12: 3 | F12: 3 | G12: 3 | H12: 3 | I12: 3 | J12: 3 | K12: 3 | M12: 3 | N12: 3 | O12: 3 | P12: 3 | Q12: 3 | R12: 3 | T12: 3 | U12: 3 | V12: 3 | W12: 3 | X12: 3 | Y12: 3
A13: 9 | B13: เด็กหญิงกุลฑีรา มังฉกรรจ์ | C13: 3 | D13: 3 | E13: 3 | F13: 3 | G13: 3 | H13: 3 | I13: 3 | J13: 3 | K13: 3 | M13: 3 | N13: 3 | O13: 3 | P13: 3 | Q13: 3 | R13: 3 | T13: 3 | U13: 3 | V13: 3 | W13: 3 | X13: 3 | Y13: 3
A14: 10 | B14: เด็กหญิงสุชาวดี ไฮวัง | C14: 3 | D14: 3 | E14: 3 | F14: 3 | G14: 3 | H14: 3 | I14: 3 | J14: 3 | K14: 3 | M14: 3 | N14: 3 | O14: 3 | P14: 3 | Q14: 3 | R14: 3 | T14: 3 | U14: 3 | V14: 3 | W14: 3 | X14: 3 | Y14: 3
A15: 11 | B15: เด็กหญิงธนิดา แก้วมุงคุณ | C15: 3 | D15: 3 | E15: 3 | F15: 3 | G15: 3 | H15: 3 | I15: 3 | J15: 3 | K15: 3 | M15: 3 | N15: 3 | O15: 3 | P15: 3 | Q15: 3 | R15: 3 | T15: 3 | U15: 3 | V15: 3 | W15: 3 | X15: 3 | Y15: 3
A16: 12 | B16: เด็กหญิงธัญญารัตน์ ไชยเทพ | C16: 3 | D16: 3 | E16: 3 | F16: 3 | G16: 3 | H16: 3 | I16: 3 | J16: 3 | K16: 3 | M16: 3 | N16: 3 | O16: 3 | P16: 3 | Q16: 3 | R16: 3 | T16: 3 | U16: 3 | V16: 3 | W16: 3 | X16: 3 | Y16: 3
... A20: 16 | B20: เด็กชายนันทกร ปรางค์ทอง | C20: 3 | D20: 3 | E20: 3 | F20: 3 | G20: 3 | H20: 3 | I20: 3 | J20: 3 | K20: 3 | M20: 3 | N20: 3 | O20: 3 | P20: 3 | Q20: 3 | R20: 3 | T20: 3 | U20: 3 | V20: 3 | W20: 3 | X20: 3 | Y20: 3
A27: 23
A28: 24
A29: 25
A30: 26
A31: 27
A32: 28
A33: 29
A34: 30
A35: 31
A36: 32
A37: 33
A38: 34
A39: 35

Sheet ผลการเรียนรู้ (10)
P1: 10
A2: ผลการเรียนรู้/ตัวชี้วัด (แยกหน่วย พร้อมระบุมาตรฐานการเรียนรู้)
C3: รายวิชา | F3: วิทยาการคำนวณ | N3: รหัสวิชา | O3: ว23201
A4: มาตรฐานการเรียนรู้ ว 4.2
A6: คำอธิบายมาตรฐาน: เข้าใจและใช้แนวคิดเชิงคำนวณในการแก้ปัญหาที่พบในชีวิตจริงอย่างเป็นขั้นตอนและเป็นระบบ
A7: ใช้เทคโนโลยีสารสนเทศและการสื่อสารในการเรียนรู้ การทำงาน และการแก้ปัญหาได้อย่างมีประสิทธิภาพ รู้เท่าทัน และมีจริยธรรม
A9: ตัวชี้วัดที่ 1: ออกแบบและพัฒนาแอปพลิเคชันที่มีการบูรณาการกับรายวิชาอื่นหรืองานในชีวิตจริง
A11: ตัวชี้วัดที่ 2: รวบรวมข้อมูล ประมวลผล ประเมินผล นำเสนอข้อมูลและสารสนเทศตามวัตถุประสงค์ โดยใช้ซอฟต์แวร์หรือบริการบนอินเทอร์เน็ต
A12: ที่หลากหลาย
A14: ตัวชี้วัดที่ 3: ประเมินความน่าเชื่อถือของข้อมูล วิเคราะห์สื่อและผลกระทบจากการให้ข่าวสารที่ผิด เพื่อการใช้งานอย่างรู้เท่าทัน
A16: ตัวชี้วัดที่ 4: ใช้เทคโนโลยีสารสนเทศอย่างปลอดภัย และปฏิบัติตามกฎหมายเกี่ยวกับคอมพิวเตอร์ ใช้ลิขสิทธิ์ของผู้อื่นโดยชอบธรรม

Sheet คำอธิบายการใช้ (11)
B1: คำอธิบายการใช้ ปพ.5 โรงเรียนบ้านขัวก่าย | K1: 11
A2: การบันทึกข้อมูลนักเรียน-เวลาเรียน
A3: 1 | B3: ชั่วโมงที่ ให้เขียนชั่วโมงที่สอนโดยนับต่อเนื่องกันไป จนสิ้นภาคเรียน เช่น 1,2,3,...,40 หรือ 1-2,3,4-5,6,...,60
A4: 2 | B4: การบันทึกเวลาเรียน ให้บันทึกรายละเอียดดังนี้
B5: 2.1 ผู้มาเรียน ให้เขียนเครื่องหมาย / ส่วนผู้ไม่มาเรียนให้ทำเครื่องหมาย O ด้วยหมึกสีแดง และระบุสาเหตุที่ไม่เข้า เช่น ลาป่วย "ป" ลากิจ "ล" ด้วยหมึกสีน้ำเงินหรือสีดำ
B6: ลงใน O แล้วแต่กรณี ถ้าขาดหรือไม่ทราบสาเหตุให้ทำเครื่องหมาย O
B7: 2.2 ถ้านักเรียนถูกพักการเรียนหรือย้ายหรือออกกลางคัน ให้ขีดเส้นแดงทับช่องตรงรายชื่อแล้วระบุสาเหตุไว้ที่ช่องหมายเหตุ ยกเว้นถูกสั่งพักการเรียนชั่วคราว
B8: (3,5,7 วัน โดยยังไม่ลาออก) ให้ปฏิบัติเหมือนกับการขาดเรียน
B9: 2.3 เมื่อสิ้นสุดสัปดาห์ที่ 5,10,15,18 และสิ้นสุดภาคเรียน ให้สรุปเวลามาเรียนไว้ในช่องรวมเวลารายภาค ถ้านักเรียนคนใดมีเวลาเรียนน้อยกว่าร้อยละ 80 ของรายวิชานั้นๆ
B10: ให้เขียนเวลาเรียนรวมด้วยหมึกสีแดง
A11: การบันทึกการพัฒนาคุณภาพผู้เรียน
A12: 1 | B12: ให้เขียนผลการเรียนรู้ไว้ในหน้าที่ 10 โดยแยกเป็นหน่วยและระบุมาตรฐานการเรียนรู้กลุ่มสาระหรือตัวชี้วัดให้ชัดเจน
A13: 2 | B13: ให้เขียนมาตรฐานการเรียนรู้กลุ่มสาระ ตัวชี้วัดหรือผลการเรียนรู้โดยแยกเป็นหน่วยให้ชัดเจน ไว้ในหน้า 10 และกำหนดรายละเอียดการประเมินผล เป็นคะแนนในช่องวิธีการวัดผล
B14: ในแต่ละข้อ ตามแผนการจัดการเรียนรู้
A15: 3 | B15: การบันทึกผลการประเมินคุณภาพผู้เรียนรายภาค มีรายละเอียดดังนี้
B16: 3.1 เขียนหมายเลขข้อผลการเรียนรู้หรือตัวชี้วัดและน้ำหนักคะแนนรวมในแต่ละข้อ (หน้า 5-7) และในช่องรวมให้เขียนคะแนนเต็ม สำหรับช่องซ่อมเสริมให้เขียนคะแนนตามเกณฑ์ผ่าน
B17: คือ ร้อยละ 60 ของคะแนนเต็ม
B18: 3.2 ให้กรอกคะแนนตามที่นักเรียนได้จริง ถ้าคะแนนไม่ผ่านเกณฑ์ (ต่ำกว่าร้อยละ 60) ให้ลงด้วยดินสอไว้ก่อนเมื่อซ่อมเสริมเสร็จ และผ่านเกณฑ์การประเมินจึงลงคะแนนด้วยปากกา
B19: 3.3 ถ้าผลการประเมินไม่ผ่านให้สอนซ่อมเสริม เพื่อให้นักเรียนมีความรู้ความสามารถตามเกณฑ์ของแต่ละผลการเรียนรู้ เมื่อสอบแก้ตัวเสร็จแล้วให้กรอกคะแนนตามเกณฑ์ที่สถานศึกษา
B20: กำหนด (ไม่น้อยกว่าร้อยละ 60)
A21: 4 | B21: การสรุปผลการประเมินคุณภาพผู้เรียนในหน้า 8 ให้นำคะแนนแต่ละหน่วยจากหน้า 5-7 บันทึกลงในช่องรายหน่วย แล้วรวมกับคะแนนสอบกลางภาคและคะแนนสอบปลายภาค
A22: 5 | B22: เปลี่ยนระดับคะแนนที่ได้เป็นผลการเรียน โดยใช้ช่วงระดับคะแนนดังนี้
D23: ช่วงคะแนนเป็นร้อยละ | F23: ระดับผลการเรียน
D24: 80 - 100 | F24: 4
D25: 75 - 79 | F25: 3.5
D26: 70 - 74 | F26: 3
D27: 65 - 69 | F27: 2.5
D28: 60 - 64 | F28: 2
D29: 55 - 59 | F29: 1.5
D30: 50 - 54 | F30: 1
D31: 0 - 49 | F31: 0
A32: 6 | B32: สรุปจำนวนนักเรียนที่ได้ผลการเรียน 4, 3.5, 3, 2.5, 2, 1.5, 1, 0 หรือ "ร" , "มส" ,"มก" ไว้ในช่องสรุปผลการเรียน (หน้าแรก)
A33: การบันทึกผลการประเมินคุณลักษณะอันพึงประสงค์
A34: 1 | B34: การประเมินคุณลักษณะอันพึงประสงค์ให้ประเมินควบคู่ไปกับการประเมินผลการเรียนในแต่ละกิจกรรมในหน่วยการเรียนรู้ประเมินตามคุณลักษณะอันพึงประสงค์ตามที่
B35: สำนักงานคณะกรรมการการศึกษาขั้นพื้นฐานกำหนดไว้ จำนวน 8 ข้อ (อยู่ในหน้า 9)
A36: 2 | B36: ให้เขียนระดับการประเมินในแต่ละข้อ ลงในหน้า 9 โดยยึดการประเมินตามหลักสูตรแกนกลางการศึกษาขั้นพื้นฐาน พุทธศักราช 2551 (หน้า12)
A37: 3 | B37: การสรุปผลการประเมิน ให้นำช่องสรุปของทุกข้อมาหาฐานนิยมและกรอกลงในช่องสรุปผล
A38: 4 | B38: ระดับของการประเมิน มีความหมายดังนี้
C39: ระดับ | D39: ความหมาย
C40: 3 | D40: ดีเยี่ยม | F40: มีพฤติกรรมสูงกว่าเกณฑ์ในระดับดีเยี่ยม
...

Sheet คำอธิบายการใช้ (12)
J1: 12
A2: การบันทึกผลการประเมินการอ่าน คิดวิเคราะห์ และเขียนสื่อความ
A3: 1 | B3: ให้ประเมินทักษะการอ่าน คิดวิเคราะห์ และเขียนสื่อความ ตามที่สำนักงานคณะกรรมการการศึกษาขั้นพื้นฐานกำหนดไว้ จำนวน 5 ข้อ (อยู่ในหน้า 9)
A4: 2 | B4: การประเมินการอ่าน คิดวิเคราะห์ และเขียนสื่อความ ให้ประเมินด้วยวิธีการที่หลากหลายที่สะท้อนถึงการอ่าน คิดวิเคราะห์ และเขียนสื่อความ โดยประเมินควบคู่ไปกับ
B5: การประเมินผลการเรียนในแต่ละกิจกรรมในหน่วยการเรียนรู้
A6: 3 | B6: ให้เขียนระดับการประเมินในแต่ละข้อ ลงในหน้า 9
A7: 4 | B7: การสรุปผลการประเมิน ให้นำช่องสรุปของทุกข้อมาหาฐานนิยมและกรอกลงในช่องสรุปผล
A8: 5 | B8: ระดับของการประเมิน มีความหมายดังนี้
C9: ระดับ | D9: ความหมาย
C10: 3 | D10: ดีเยี่ยม | F10: มีความสามารถในระดับดีเยี่ยม
C11: 2 | D11: ดี | F11: มีความสามารถในระดับดี
C12: 1 | D12: ผ่านเกณฑ์ | F12: มีความสามารถตามเกณฑ์ที่สถานศึกษากำหนด
C13: 0 | D13: ควรปรับปรุง | F13: ควรปรับปรุง
A14: 6 | B14: กรณีที่ผู้เรียนมีผลการประเมินย่อยเป็น 0 ให้ดำเนินการปรับปรุงพัฒนาทักษะการอ่าน คิดวิเคราะห์และเขียนสื่อความของผู้เรียนให้ผ่านเกณฑ์และแก้ไขได้ระดับไม่เกิน 1
A15: 7 | B15: สรุปจำนวนนักเรียนที่มีผลการประเมิน 3,2,1,0 ไว้ในช่องผลการประเมินการอ่าน คิดวิเคราะห์ และเขียนสื่อความ (หน้าแรก)
A16: 8 | B16: กรณีที่ผู้เรียนมีผลการประเมินรวมเป็น 0 ให้ดำเนินการปรับปรุงพัฒนาทักษะการอ่าน คิดวิเคราะห์และเขียนสื่อความของผู้เรียน ให้ผ่านเกณฑ์ในภาคเรียนถัดไป
A17: คุณลักษณะอันพึงประสงค์ ตามหลักสูตรแกนกลางการศึกษาขั้นพื้นฐาน พุทธศักราช 2551
B18: คุณลักษณะที่พึงประสงค์ | D18: ตัวชี้วัด
B19: 1. รักชาติ ศาสน์ กษัตริย์ | D19: 1.1 เป็นพลเมืองดีของชาติ
D20: 1.2 ธำรงไว้ซึ่งความเป็นชาติไทย
D21: 1.3 ศรัทธา ยึดมั่น และปฏิบัติตนตามหลักของศาสนา
D22: 1.4 เคารพเทิดทูนพระมหากษัตริย์
B23: 2. ซื่อสัตย์สุจริต | D23: 2.1 ประพฤติตนตามความเป็นจริงต่อตนเอง ทั้งกาย วาจา ใจ
D24: 2.2 ประพฤติตนตามความเป็นจริงต่อผู้อื่น ทั้งกาย วาจา ใจ
B25: 3. มีวินัย | D25: 3.1 ปฏิบัติตามข้อตกลง กฎเกณฑ์ ระเบียบ ข้อบังคับของครอบครัว โรงเรียนและสังคม
B26: 4. ใฝ่เรียนรู้ | D26: 4.1 ตั้งใจ เพียรพยายามในการเรียนและเข้าร่วมกิจกรรมการเรียนรู้
D27: 4.2 แสวงหาความรู้จากแหล่งเรียนรู้ต่างๆ ทั้งภายในและภายนอกโรงเรียน ด้วยการเลือกสื่ออย่างเหมาะสม บันทึกความรู้
D28: วิเคราะห์ สรุปเป็นองค์ความรู้ สามารถนำไปใช้นีวิตประจำวันได้
B29: 5. อยู่อย่างพอเพียง | D29: 5.1 ดำเนินชีวิตอย่างพอประมาณ มีเหตุผล รอบคอบ มีคุณธรรม
D30: 5.2 มีภูมิคุ้มกันในตัวที่ดี เพื่อปรับตัวอยู่ในสังคมได้อย่างมีความสุข
B31: 6. มุ่งมั่นในการทำงาน | D31: 6.1 ตั้งใจและรับผิดชอบในการปฏิบัติหน้าที่การงาน
D32: 6.2 ทำงานด้วยความเพียรพยายามและอดทนเพื่อให้งานสำเร็จตามเป้าหมาย
B33: 7. รักความเป็นไทย | D33: 7.1 ภาคภูมิใจในขนบธรรมเนียมประเพณี ศิลปะ วัฒนธรรมไทย มีความกตัญญูกตเวที
D34: 7.2 เห็นคุณค่าและใช้ภาษาไทยในการสื่อสารได้อย่างถูกต้อง เหมาะสม
D35: 7.3 อนุรักษ์และสืบทอดภูมิปัญญาไทย
B36: 8. มีจิตสาธารณะ | D36: 8.1 ช่วยเหลือผู้อื่นด้วยความเต็มใจและพึงพอใจ โดยไม่หวังผลตอบแทน
D37: 8.2 เข้าร่วมกิจกรรมที่เป็นประโยน์ต่อโรงเรียน ชุมชน และสังคม
B39: การอ่าน คิดวิเคราะห์และเขียนสื่อความ โรงเรียนบ้านขัวก่าย
B40: 1. สามารถคัดสรรสื่อที่ต้องการอ่านเพื่อหาข้อมูลสารสนเทศได้ตามวัตถุประสงค์
B41: 2. สามารถจับประเด็นสำคัญและประเด็นสนับสนุน โต้แย้ง
...

Sheet ผลการเรียน
A1: ผลการเรียนนักเรียน ชั้นมัธยมศึกษาปีที่ 3
A2: ภาคเรียนที่ 2 ปีการศึกษา 2568
A3: โรงเรียนบ้านขัวก่าย สำนักงานเขตพื้นที่การศึกษาประถมศึกษาสกลนคร เขต 3
B5: รายวิชา | C5: ='ปก (1)'!E10 -> คอมพิวเตอร์ | E5: รหัสวิชา | F5: ='ปก (1)'!L10 -> ว23201 | G5: ครูผู้สอน | I5: ='ปก (1)'!E12 -> นายวรวุฒิ มุงธิสาร
B7: เลขที่ | C7: เลขประจำตัว | D7: ชื่อ-นามสกุล | E7: คะแนน | F7: ผลการเรียน | G7: ผลการประเมิน | K7: จำนวนนักเรียน
E8: 100 | G8: ลักษณะอันพึงประสงค์ | H8: การอ่าน คิดวิเคราะห์ฯ | I8: สมรรถนะสำคัญฯ | K8: ชาย | L8: หญิง | M8: รวม
B9: 1 | C9: ='เวลาเรียน (2)'!B6 -> 4833 | D9: ='เวลาเรียน (2)'!C6 -> เด็กชายพงษ์ศิริ พิมโยธา | E9: ='สรุปผลรวม (8)'!Q7 -> 87 | F9: =IF(E9>79,4,IF(E9>74,3.5,IF(E9>69,3,IF(E9>64,2.5,IF(E9>59,2,IF(E9>54,1.5,IF(E9>49,1,IF(E9<50,0)))))))) -> 4 | G9: ='คุณลักษณะ อ่าน สมรรถนะ (9)'!K5 -> 3 | H9: ='คุณลักษณะ อ่าน สมรรถนะ (9)'!R5 -> 3 | I9: ='คุณลักษณะ อ่าน สมรรถนะ (9)'!Y5 -> 3 | K9: 8 | L9: 8 | M9: 16
B10: 2 | C10: ='เวลาเรียน (2)'!B7 -> 4832 | D10: ='เวลาเรียน (2)'!C7 -> เด็กชายพงศ์พิเชษฐ์ มาสีปา | E10: ='สรุปผลรวม (8)'!Q8 -> 65 | F10: =IF(E10>79,4,IF(E10>74,3.5,IF(E10>69,3,IF(E10>64,2.5,IF(E10>59,2,IF(E10>54,1.5,IF(E10>49,1,IF(E10<50,0)))))))) -> 2.5 | G10: ='คุณลักษณะ อ่าน สมรรถนะ (9)'!K6 -> 3 | H10: ='คุณลักษณะ อ่าน สมรรถนะ (9)'!R6 -> 2 | I10: ='คุณลักษณะ อ่าน สมรรถนะ (9)'!Y6 -> 2
B11: 3 | C11: ='เวลาเรียน (2)'!B8 -> 4836 | D11: ='เวลาเรียน (2)'!C8 -> เด็กชายรพีภัทร แสดคง | E11: ='สรุปผลรวม (8)'!Q9 -> 91 | F11: =IF(E11>79,4,IF(E11>74,3.5,IF(E11>69,3,IF(E11>64,2.5,IF(E11>59,2,IF(E11>54,1.5,IF(E11>49,1,IF(E11<50,0)))))))) -> 4 | G11: ='คุณลักษณะ อ่าน สมรรถนะ (9)'!K7 -> 3 | H11: ='คุณลักษณะ อ่าน สมรรถนะ (9)'!R7 -> 3 | I11: ='คุณลักษณะ อ่าน สมรรถนะ (9)'!Y7 -> 3 | K11: ผลการเรียน
B12: 4 | C12: ='เวลาเรียน (2)'!B9 -> 4837 | D12: ='เวลาเรียน (2)'!C9 -> เด็กชายวัชรากร โพธิ์ศรี | E12: ='สรุปผลรวม (8)'!Q10 -> 85 | F12: =IF(E12>79,4,IF(E12>74,3.5,IF(E12>69,3,IF(E12>64,2.5,IF(E12>59,2,IF(E12>54,1.5,IF(E12>49,1,IF(E12<50,0)))))))) -> 4 | G12: ='คุณลักษณะ อ่าน สมรรถนะ (9)'!K8 -> 3 | H12: ='คุณลักษณะ อ่าน สมรรถนะ (9)'!R8 -> 3 | I12: ='คุณลักษณะ อ่าน สมรรถนะ (9)'!Y8 -> 3 | K12: เกรด | L12: จำนวน | M12: ร้อยละ
B13: 5 | C13: ='เวลาเรียน (2)'!B10 -> 4897 | D13: ='เวลาเรียน (2)'!C10 -> เด็กชายธนกฤต ดกเอียร์ | E13: ='สรุปผลรวม (8)'!Q11 -> 82 | F13: =IF(E13>79,4,IF(E13>74,3.5,IF(E13>69,3,IF(E13>64,2.5,IF(E13>59,2,IF(E13>54,1.5,IF(E13>49,1,IF(E13<50,0)))))))) -> 4 | G13: ='คุณลักษณะ อ่าน สมรรถนะ (9)'!K9 -> 3 | H13: ='คุณลักษณะ อ่าน สมรรถนะ (9)'!R9 -> 3 | I13: ='คุณลักษณะ อ่าน สมรรถนะ (9)'!Y9 -> 3 | K13: 4 | L13: =COUNTIF($F$9:$F$25,K13) -> 11 | M13: =L13*100/16 -> 68.75
B14: 6 | C14: ='เวลาเรียน (2)'!B11 -> 4927 | D14: ='เวลาเรียน (2)'!C11 -> เด็กชายขัตติยะ ไตรวงค์ย้อย | E14: ='สรุปผลรวม (8)'!Q12 -> 65 | F14: =IF(E14>79,4,IF(E14>74,3.5,IF(E14>69,3,IF(E14>64,2.5,IF(E14>59,2,IF(E14>54,1.5,IF(E14>49,1,IF(E14<50,0)))))))) -> 2.5 | G14: ='คุณลักษณะ อ่าน สมรรถนะ (9)'!K10 -> 3 | H14: ='คุณลักษณะ อ่าน สมรรถนะ (9)'!R10 -> 2 | I14: ='คุณลักษณะ อ่าน สมรรถนะ (9)'!Y10 -> 2 | K14: 3.5 | L14: =COUNTIF($F$9:$F$25,K14) -> 2 | M14: =L14*100/16 -> 12.5
B15: 7 | C15: ='เวลาเรียน (2)'!B12 -> 4835 | D15: ='เวลาเรียน (2)'!C12 -> เด็กชายภูวนัตถ์ บุญมาก | E15: ='สรุปผลรวม (8)'!Q13 -> 80 | F15: =IF(E15>79,4,IF(E15>74,3.5,IF(E15>69,3,IF(E15>64,2.5,IF(E15>59,2,IF(E15>54,1.5,IF(E15>49,1,IF(E15<50,0)))))))) -> 4 | G15: ='คุณลักษณะ อ่าน สมรรถนะ (9)'!K11 -> 3 | H15: ='คุณลักษณะ อ่าน สมรรถนะ (9)'!R11 -> 3 | I15: ='คุณลักษณะ อ่าน สมรรถนะ (9)'!Y11 -> 3 | K15: 3 | L15: =COUNTIF($F$9:$F$25,K15) -> 1 | M15: =L15*100/16 -> 6.25
B16: 8 | C16: ='เวลาเรียน (2)'!B13 -> 4842 | D16: ='เวลาเรียน (2)'!C13 -> เด็กหญิงบงกช แสงนนท์ | E16: ='สรุปผลรวม (8)'!Q14 -> 93 | F16: =IF(E16>79,4,IF(E16>74,3.5,IF(E16>69,3,IF(E16>64,2.5,IF(E16>59,2,IF(E16>54,1.5,IF(E16>49,1,IF(E16<50,0)))))))) -> 4 | G16: ='คุณลักษณะ อ่าน สมรรถนะ (9)'!K12 -> 3 | H16: ='คุณลักษณะ อ่าน สมรรถนะ (9)'!R12 -> 3 | I16: ='คุณลักษณะ อ่าน สมรรถนะ (9)'!Y12 -> 3 | K16: 2.5 | L16: =COUNTIF($F$9:$F$25,K16) -> 2 | M16: =L16*100/16 -> 12.5
B17: 9 | C17: ='เวลาเรียน (2)'!B14 -> 4838 | D17: ='เวลาเรียน (2)'!C14 -> เด็กหญิงกุลฑีรา มังฉกรรจ์ | E17: ='สรุปผลรวม (8)'!Q15 -> 93 | F17: =IF(E17>79,4,IF(E17>74,3.5,IF(E17>69,3,IF(E17>64,2.5,IF(E17>59,2,IF(E17>54,1.5,IF(E17>49,1,IF(E17<50,0)))))))) -> 4 | G17: ='คุณลักษณะ อ่าน สมรรถนะ (9)'!K13 -> 3 | H17: ='คุณลักษณะ อ่าน สมรรถนะ (9)'!R13 -> 3 | I17: ='คุณลักษณะ อ่าน สมรรถนะ (9)'!Y13 -> 3 | K17: 2 | L17: =COUNTIF($F$9:$F$25,K17) -> 0 | M17: =L17*100/16 -> 0
B18: 10 | C18: ='เวลาเรียน (2)'!B15 -> 4845 | D18: ='เวลาเรียน (2)'!C15 -> เด็กหญิงสุชาวดี ไฮวัง | E18: ='สรุปผลรวม (8)'!Q16 -> 92 | F18: =IF(E18>79,4,IF(E18>74,3.5,IF(E18>69,3,IF(E18>64,2.5,IF(E18>59,2,IF(E18>54,1.5,IF(E18>49,1,IF(E18<50,0)))))))) -> 4 | G18: ='คุณลักษณะ อ่าน สมรรถนะ (9)'!K14 -> 3 | H18: ='คุณลักษณะ อ่าน สมรรถนะ (9)'!R14 -> 3 | I18: ='คุณลักษณะ อ่าน สมรรถนะ (9)'!Y14 -> 3 | K18: 1.5 | L18: =COUNTIF($F$9:$F$25,K18) -> 0 | M18: =L18*100/16 -> 0
B19: 11 | C19: ='เวลาเรียน (2)'!B16 -> 4846 | D19: ='เวลาเรียน (2)'!C16 -> เด็กหญิงธนิดา แก้วมุงคุณ | E19: ='สรุปผลรวม (8)'!Q17 -> 92 | F19: =IF(E19>79,4,IF(E19>74,3.5,IF(E19>69,3,IF(E19>64,2.5,IF(E19>59,2,IF(E19>54,1.5,IF(E19>49,1,IF(E19<50,0)))))))) -> 4 | G19: ='คุณลักษณะ อ่าน สมรรถนะ (9)'!K15 -> 3 | H19: ='คุณลักษณะ อ่าน สมรรถนะ (9)'!R15 -> 3 | I19: ='คุณลักษณะ อ่าน สมรรถนะ (9)'!Y15 -> 3 | K19: 1 | L19: =COUNTIF($F$9:$F$25,K19) -> 0 | M19: =L19*100/16 -> 0
B20: 12 | C20: ='เวลาเรียน (2)'!B17 -> 4840 | D20: ='เวลาเรียน (2)'!C17 -> เด็กหญิงธัญญารัตน์ ไชยเทพ | E20: ='สรุปผลรวม (8)'!Q18 -> 75 | F20: =IF(E20>79,4,IF(E20>74,3.5,IF(E20>69,3,IF(E20>64,2.5,IF(E20>59,2,IF(E20>54,1.5,IF(E20>49,1,IF(E20<50,0)))))))) -> 3.5 | G20: ='คุณลักษณะ อ่าน สมรรถนะ (9)'!K16 -> 3 | H20: ='คุณลักษณะ อ่าน สมรรถนะ (9)'!R16 -> 3 | I20: ='คุณลักษณะ อ่าน สมรรถนะ (9)'!Y16 -> 3 | K20: 0 | L20: =COUNTIF($F$9:$F$25,K20) -> 0 | M20: =L20*100/16 -> 0
B21: 13 | C21: ='เวลาเรียน (2)'!B18 -> 4841 | D21: ='เวลาเรียน (2)'!C18 -> เด็กหญิงนภัสสร ประฮาดไชย | E21: ='สรุปผลรวม (8)'!Q19 -> 87 | F21: =IF(E21>79,4,IF(E21>74,3.5,IF(E21>69,3,IF(E21>64,2.5,IF(E21>59,2,IF(E21>54,1.5,IF(E21>49,1,IF(E21<50,0)))))))) -> 4 | G21: ='คุณลักษณะ อ่าน สมรรถนะ (9)'!K17 -> 3 | H21: ='คุณลักษณะ อ่าน สมรรถนะ (9)'!R17 -> 3 | I21: ='คุณลักษณะ อ่าน สมรรถนะ (9)'!Y17 -> 3 | K21: ร | L21: =COUNTIF($F$9:$F$25,K21) -> 0 | M21: =L21*100/16 -> 0
B22: 14 | C22: ='เวลาเรียน (2)'!B19 -> 4843 | D22: ='เวลาเรียน (2)'!C19 -> เด็กหญิงมณีญานันท์ คำปัญโญ | E22: ='สรุปผลรวม (8)'!Q20 -> 90 | F22: =IF(E22>79,4,IF(E22>74,3.5,IF(E22>69,3,IF(E22>64,2.5,IF(E22>59,2,IF(E22>54,1.5,IF(E22>49,1,IF(E22<50,0)))))))) -> 4 | G22: ='คุณลักษณะ อ่าน สมรรถนะ (9)'!K18 -> 3 | H22: ='คุณลักษณะ อ่าน สมรรถนะ (9)'!R18 -> 3 | I22: ='คุณลักษณะ อ่าน สมรรถนะ (9)'!Y18 -> 3 | K22: มส | L22: =COUNTIF($F$9:$F$25,K22) -> 0 | M22: =L22*100/16 -> 0
B23: 15 | C23: ='เวลาเรียน (2)'!B20 -> 5012 | D23: ='เวลาเรียน (2)'!C20 -> เด็กหญิงธัญชนก อินทรภูมิ | E23: ='สรุปผลรวม (8)'!Q21 -> 73 | F23: =IF(E23>79,4,IF(E23>74,3.5,IF(E23>69,3,IF(E23>64,2.5,IF(E23>59,2,IF(E23>54,1.5,IF(E23>49,1,IF(E23<50,0)))))))) -> 3 | G23: ='คุณลักษณะ อ่าน สมรรถนะ (9)'!K19 -> 3 | H23: ='คุณลักษณะ อ่าน สมรรถนะ (9)'!R19 -> 3 | I23: ='คุณลักษณะ อ่าน สมรรถนะ (9)'!Y19 -> 2 | K23: รวม | L23: =SUM(L13:L22) -> 16 | M23: =L23*100/16 -> 100
B24: 16 | C24: ='เวลาเรียน (2)'!B21 -> 5013 | D24: ='เวลาเรียน (2)'!C21 -> เด็กชายนันทกร ปรางค์ทอง | E24: ='สรุปผลรวม (8)'!Q22 -> 77 | F24: =IF(E24>79,4,IF(E24>74,3.5,IF(E24>69,3,IF(E24>64,2.5,IF(E24>59,2,IF(E24>54,1.5,IF(E24>49,1,IF(E24<50,0)))))))) -> 3.5 | G24: ='คุณลักษณะ อ่าน สมรรถนะ (9)'!K20 -> 3 | H24: ='คุณลักษณะ อ่าน สมรรถนะ (9)'!R20 -> 3 | I24: ='คุณลักษณะ อ่าน สมรรถนะ (9)'!Y20 -> 3
K25: คุณลักษณะอันพึงประสงค์
B26: ผลการเรียนเฉลี่ย | E26: =SUM(E9:E25) -> 1327 | F26: =AVERAGE(F9:F25) -> 3.6875 | K26: 3 | L26: =COUNTIF($G$9:$G$25,K26) -> 16 | M26: =L26*100/16 -> 100
K27: 2 | L27: =COUNTIF($G$9:$G$25,K27) -> 0 | M27: =L27*100/16 -> 0
K28: 1 | L28: =COUNTIF($G$9:$G$25,K28) -> 0 | M28: =L28*100/16 -> 0
K29: 0 | L29: =COUNTIF($G$9:$G$25,K29) -> 0 | M29: =L29*100/16 -> 0
K30: รวม | L30: =SUM(L26:L29) -> 16 | M30: =L30*100/16 -> 100
D31: (ลงชื่อ).....................................................ครูผู้สอน
D32: ="("&I5&")" -> (นายวรวุฒิ มุงธิสาร) | K32: การอ่าน คิดวิเคราห์ฯ
D33: ...../............../....... | K33: 3 | L33: =COUNTIF($H$9:$H$25,K33) -> 14 | M33: =L33*100/16 -> 87.5
D34: (ลงชื่อ).....................................................งานวัดผล | K34: 2 | L34: =COUNTIF($H$9:$H$25,K34) -> 2 | M34: =L34*100/16 -> 12.5
D35: (นางขวัญจิต สุวรรณคุณ) | K35: 1 | L35: =COUNTIF($H$9:$H$25,K35) -> 0 | M35: =L35*100/16 -> 0
D36: ...../............../....... | K36: 0 | L36: =COUNTIF($H$9:$H$25,K36) -> 0 | M36: =L36*100/16 -> 0
D37: (ลงชื่อ).....................................................ผู้อำนวยการโรงเรียน | K37: รวม | L37: =SUM(L33:L36) -> 16 | M37: =L37*100/16 -> 100
D38: (นายอภัย ปังอุทา)
D39: ...../............../....... | K39: สมรรถนะสำคัญของผู้เรียน
K40: 3 | L40: =COUNTIF($I$9:$I$25,K40) -> 13 | M40: =L40*100/16 -> 81.25
K41: 2 | L41: =COUNTIF($I$9:$I$25,K41) -> 3 | M41: =L41*100/16 -> 18.75
K42: 1 | L42: =COUNTIF($I$9:$I$25,K42) -> 0 | M42: =L42*100/16 -> 0
...
