Workbook

Sheet ปก
A5: สมุดบันทึกผลการพัฒนาคุณภาพผู้เรียนรายวิชา (ปพ.5)
A6: โรงเรียนบ้านขัวก่าย ตำบลขัวก่าย อำเภอวานรนิวาส จังหวัดสกลนคร
A7: สังกัด สำนักงานเขตพื้นที่การศึกษาประถมศึกษา สกลนคร เขต 3
A8: สำนักงานคณะกรรมการการศึกษาขั้นพื้นฐาน กระทรวงศึกษาธิการ
A9: ชั้นประถมศึกษาปีที่ 6 ปีการศึกษา 2568
A10: สรุปผลการเรียน
A11: รายวิชา | D11: รหัสวิชา | E11: จำนวนนักเรียนที่ได้รับผลการเรียน | M11: ผลการเรียนเฉลี่ย
E12: 0 | F12: 1 | G12: 1.5 | H12: 2 | I12: 2.5 | J12: 3 | K12: 3.5 | L12: 4
A13: ภาษาไทย | D13: ท15101 | E13: =COUNTIF('เกรดรวม59-60'!$T$6:$T$34,E12) -> 0 | F13: =COUNTIF('เกรดรวม59-60'!$T$6:$T$34,F12) -> 0 | G13: =COUNTIF('เกรดรวม59-60'!$T$6:$T$34,G12) -> 0 | H13: =COUNTIF('เกรดรวม59-60'!$T$6:$T$34,H12) -> 0 | I13: =COUNTIF('เกรดรวม59-60'!$T$6:$T$34,I12) -> 0 | J13: =COUNTIF('เกรดรวม59-60'!$T$6:$T$34,J12) -> 3 | K13: =COUNTIF('เกรดรวม59-60'!$T$6:$T$34,K12) -> 3 | L13: =COUNTIF('เกรดรวม59-60'!$T$6:$T$34,L12) -> 7 | M13: =((E13*0)+(F13*1)+(G13*1.5)+(H13*2)+(I13*2.5)+(J13*3)+(K13*3.5)+(L13*4))/(E13+F13+G13+H13+I13+J13+K13+L13) -> 3.6538462
A14: คณิตศาสตร์ | D14: ค15101 | E14: =COUNTIF('เกรดรวม59-60'!$U$6:$U$34,E12) -> 0 | F14: =COUNTIF('เกรดรวม59-60'!$U$6:$U$34,F12) -> 0 | G14: =COUNTIF('เกรดรวม59-60'!$U$6:$U$34,G12) -> 0 | H14: =COUNTIF('เกรดรวม59-60'!$U$6:$U$34,H12) -> 0 | I14: =COUNTIF('เกรดรวม59-60'!$U$6:$U$34,I12) -> 0 | J14: =COUNTIF('เกรดรวม59-60'!$U$6:$U$34,J12) -> 3 | K14: =COUNTIF('เกรดรวม59-60'!$U$6:$U$34,K12) -> 2 | L14: =COUNTIF('เกรดรวม59-60'!$U$6:$U$34,L12) -> 8 | M14: =((E14*0)+(F14*1)+(G14*1.5)+(H14*2)+(I14*2.5)+(J14*3)+(K14*3.5)+(L14*4))/(E14+F14+G14+H14+I14+J14+K14+L14) -> 3.6923077
A15: วิทยาศาตร์และเทคโนโลยี | D15: ว15101 | E15: =COUNTIF('เกรดรวม59-60'!$V$6:$V$34,E12) -> 0 | F15: =COUNTIF('เกรดรวม59-60'!$V$6:$V$34,F12) -> 0 | G15: =COUNTIF('เกรดรวม59-60'!$V$6:$V$34,G12) -> 0 | H15: =COUNTIF('เกรดรวม59-60'!$V$6:$V$34,H12) -> 0 | I15: =COUNTIF('เกรดรวม59-60'!$V$6:$V$34,I12) -> 1 | J15: =COUNTIF('เกรดรวม59-60'!$V$6:$V$34,J12) -> 5 | K15: =COUNTIF('เกรดรวม59-60'!$V$6:$V$34,K12) -> 1 | L15: =COUNTIF('เกรดรวม59-60'!$V$6:$V$34,L12) -> 6 | M15: =((E15*0)+(F15*1)+(G15*1.5)+(H15*2)+(I15*2.5)+(J15*3)+(K15*3.5)+(L15*4))/(E15+F15+G15+H15+I15+J15+K15+L15) -> 3.4615385
A16: สังคมศึกษา ฯ | D16: ส15101 | E16: =COUNTIF('เกรดรวม59-60'!$W$6:$W$34,E12) -> 0 | F16: =COUNTIF('เกรดรวม59-60'!$W$6:$W$34,F12) -> 0 | G16: =COUNTIF('เกรดรวม59-60'!$W$6:$W$34,G12) -> 0 | H16: =COUNTIF('เกรดรวม59-60'!$W$6:$W$34,H12) -> 0 | I16: =COUNTIF('เกรดรวม59-60'!$W$6:$W$34,I12) -> 0 | J16: =COUNTIF('เกรดรวม59-60'!$W$6:$W$34,J12) -> 0 | K16: =COUNTIF('เกรดรวม59-60'!$W$6:$W$34,K12) -> 2 | L16: =COUNTIF('เกรดรวม59-60'!$W$6:$W$34,L12) -> 11 | M16: =((E16*0)+(F16*1)+(G16*1.5)+(H16*2)+(I16*2.5)+(J16*3)+(K16*3.5)+(L16*4))/(E16+F16+G16+H16+I16+J16+K16+L16) -> 3.9230769
A17: ประวัติศาสตร์ | D17: ส15102 | E17: =COUNTIF('เกรดรวม59-60'!$X$6:$X$34,E12) -> 0 | F17: =COUNTIF('เกรดรวม59-60'!$X$6:$X$34,F12) -> 0 | G17: =COUNTIF('เกรดรวม59-60'!$X$6:$X$34,G12) -> 0 | H17: =COUNTIF('เกรดรวม59-60'!$X$6:$X$34,H12) -> 0 | I17: =COUNTIF('เกรดรวม59-60'!$X$6:$X$34,I12) -> 0 | J17: =COUNTIF('เกรดรวม59-60'!$X$6:$X$34,J12) -> 0 | K17: =COUNTIF('เกรดรวม59-60'!$X$6:$X$34,K12) -> 1 | L17: =COUNTIF('เกรดรวม59-60'!$X$6:$X$34,L12) -> 12 | M17: =((E17*0)+(F17*1)+(G17*1.5)+(H17*2)+(I17*2.5)+(J17*3)+(K17*3.5)+(L17*4))/(E17+F17+G17+H17+I17+J17+K17+L17) -> 3.9615385
A18: สุขศึกษาและพลศึกษา | D18: พ15101 | E18: =COUNTIF('เกรดรวม59-60'!$Y$6:$Y$34,E12) -> 0 | F18: =COUNTIF('เกรดรวม59-60'!$Y$6:$Y$34,F12) -> 0 | G18: =COUNTIF('เกรดรวม59-60'!$Y$6:$Y$34,G12) -> 0 | H18: =COUNTIF('เกรดรวม59-60'!$Y$6:$Y$34,H12) -> 0 | I18: =COUNTIF('เกรดรวม59-60'!$Y$6:$Y$34,I12) -> 0 | J18: =COUNTIF('เกรดรวม59-60'!$Y$6:$Y$34,J12) -> 0 | K18: =COUNTIF('เกรดรวม59-60'!$Y$6:$Y$34,K12) -> 2 | L18: =COUNTIF('เกรดรวม59-60'!$Y$6:$Y$34,L12) -> 11 | M18: =((E18*0)+(F18*1)+(G18*1.5)+(H18*2)+(I18*2.5)+(J18*3)+(K18*3.5)+(L18*4))/(E18+F18+G18+H18+I18+J18+K18+L18) -> 3.9230769
A19: ศิลปะ | D19: ศ15101 | E19: =COUNTIF('เกรดรวม59-60'!$Z$6:$Z$34,E12) -> 0 | F19: =COUNTIF('เกรดรวม59-60'!$Z$6:$Z$34,F12) -> 0 | G19: =COUNTIF('เกรดรวม59-60'!$Z$6:$Z$34,G12) -> 0 | H19: =COUNTIF('เกรดรวม59-60'!$Z$6:$Z$34,H12) -> 0 | I19: =COUNTIF('เกรดรวม59-60'!$Z$6:$Z$34,I12) -> 0 | J19: =COUNTIF('เกรดรวม59-60'!$Z$6:$Z$34,J12) -> 0 | K19: =COUNTIF('เกรดรวม59-60'!$Z$6:$Z$34,K12) -> 0 | L19: =COUNTIF('เกรดรวม59-60'!$Z$6:$Z$34,L12) -> 13 | M19: =((E19*0)+(F19*1)+(G19*1.5)+(H19*2)+(I19*2.5)+(J19*3)+(K19*3.5)+(L19*4))/(E19+F19+G19+H19+I19+J19+K19+L19) -> 4
A20: การงานอาชีพ | D20: ง15101 | E20: =COUNTIF('เกรดรวม59-60'!$AA$6:$AA$34,E12) -> 0 | F20: =COUNTIF('เกรดรวม59-60'!$AA$6:$AA$34,F12) -> 0 | G20: =COUNTIF('เกรดรวม59-60'!$AA$6:$AA$34,G12) -> 0 | H20: =COUNTIF('เกรดรวม59-60'!$AA$6:$AA$34,H12) -> 0 | I20: =COUNTIF('เกรดรวม59-60'!$AA$6:$AA$34,I12) -> 0 | J20: =COUNTIF('เกรดรวม59-60'!$AA$6:$AA$34,J12) -> 0 | K20: =COUNTIF('เกรดรวม59-60'!$AA$6:$AA$34,K12) -> 0 | L20: =COUNTIF('เกรดรวม59-60'!$AA$6:$AA$34,L12) -> 13 | M20: =((E20*0)+(F20*1)+(G20*1.5)+(H20*2)+(I20*2.5)+(J20*3)+(K20*3.5)+(L20*4))/(E20+F20+G20+H20+I20+J20+K20+L20) -> 4
A21: ภาษาอังกฤษ | D21: อ15101 | E21: =COUNTIF('เกรดรวม59-60'!$AB$5:$AB$34,E12) -> 0 | F21: =COUNTIF('เกรดรวม59-60'!$AB$5:$AB$34,F12) -> 0 | G21: =COUNTIF('เกรดรวม59-60'!$AB$5:$AB$34,G12) -> 1 | H21: =COUNTIF('เกรดรวม59-60'!$AB$5:$AB$34,H12) -> 1 | I21: =COUNTIF('เกรดรวม59-60'!$AB$5:$AB$34,I12) -> 2 | J21: =COUNTIF('เกรดรวม59-60'!$AB$5:$AB$34,J12) -> 0 | K21: =COUNTIF('เกรดรวม59-60'!$AB$5:$AB$34,K12) -> 3 | L21: =COUNTIF('เกรดรวม59-60'!$AB$5:$AB$34,L12) -> 6 | M21: =((E21*0)+(F21*1)+(G21*1.5)+(H21*2)+(I21*2.5)+(J21*3)+(K21*3.5)+(L21*4))/(E21+F21+G21+H21+I21+J21+K21+L21) -> 3.3076923
A22: การป้องกันการทุจริต | D22: ส15201 | E22: =COUNTIF('เกรดรวม59-60'!$AC$5:$AC$34,E12) -> 0 | F22: =COUNTIF('เกรดรวม59-60'!$AC$5:$AC$34,F12) -> 0 | G22: =COUNTIF('เกรดรวม59-60'!$AC$5:$AC$34,G12) -> 0 | H22: =COUNTIF('เกรดรวม59-60'!$AC$5:$AC$34,H12) -> 0 | I22: =COUNTIF('เกรดรวม59-60'!$AC$5:$AC$34,I12) -> 0 | J22: =COUNTIF('เกรดรวม59-60'!$AC$5:$AC$34,J12) -> 1 | K22: =COUNTIF('เกรดรวม59-60'!$AC$5:$AC$34,K12) -> 1 | L22: =COUNTIF('เกรดรวม59-60'!$AC$5:$AC$34,L12) -> 11 | M22: =((E22*0)+(F22*1)+(G22*1.5)+(H22*2)+(I22*2.5)+(J22*3)+(K22*3.5)+(L22*4))/(E22+F22+G22+H22+I22+J22+K22+L22) -> 3.8846154
A24: ผลการประเมินคุณลักษณะอันพึงประสงค์ | F24: ผลการประเมินการอ่าน คิด และเขียน
A25: 0 | B25: 1 | C25: 2 | D25: 3 | F25: 0 | G25: 1 | H25: 2 | I25: 3
A26: =COUNTIF('คุณลักษณะ อ่านฯ57'!$K$5:$K$33,ปก!A25) -> 0 | B26: =COUNTIF('คุณลักษณะ อ่านฯ57'!$K$5:$K$33,ปก!B25) -> 0 | C26: =COUNTIF('คุณลักษณะ อ่านฯ57'!$K$5:$K$33,ปก!C25) -> 0 | D26: =COUNTIF('คุณลักษณะ อ่านฯ57'!$K$5:$K$33,ปก!D25) -> 13 | F26: =COUNTIF('คุณลักษณะ อ่านฯ57'!$R$5:$R$33,ปก!F25) -> 0 | G26: =COUNTIF('คุณลักษณะ อ่านฯ57'!$R$5:$R$33,ปก!G25) -> 0 | H26: =COUNTIF('คุณลักษณะ อ่านฯ57'!$R$5:$R$33,ปก!H25) -> 2 | I26: =COUNTIF('คุณลักษณะ อ่านฯ57'!$R$5:$R$33,ปก!I25) -> 11
A28: อนุมัติผลการเรียน
C29: ลงชื่อ…...……………………………….......….. | G29: ครูผู้สอน
D30: (นาอุราพร ธุระแพง )
C31: ลงชื่อ…………………………………......……… | G31: ผู้ทาน
D32: (นางเจษฎา คำปัญโญ)
C33: ลงชื่อ…………………………………………….. | G33: ผู้ตรวจ
D34: (นางขวัญจิต สุวรรณคุณ)
C35: ( ) | D35: อนุมัติ | G35: ( ) | H35: ไม่อนุมัติ
C36: ลงชื่อ…………………………………………….. | G36: ผู้อำนวยการโรงเรียนบ้านขัวก่าย
D37: (นายอภัย ปังอุทา)
C38: วันที่ 31 เดือน มีนาคม พ.ศ. 2568

Sheet ข้อมูลนร.2-3
G1: 2 | P1: 3
A2: เลขที่ | B2: เลขประจำตัว | C2: เลขประจำตัวประชาชน | D2: คำนำหน้าชื่อ ชื่อ - นามสกุล | E2: วัน เดือน ปี เกิด | F2: ชื่อ -นามสกุล บิดา | G2: ชื่อ - นามสกุล มารดา | H2: ชื่อ -นามสกุล ผู้ปกครอง | I2: เกี่ยวข้องเป็น | J2: อาขีพผู้ปกครอง | K2: ที่อยู่
K3: บ้านเลขที่ | L3: หมู่ที่ | M3: ตำบล | N3: อำเภอ | O3: จังหวัด | P3: เบอร์โทรศัพท์
A4: 1 | B4: 4874 | C4: 1470801474536 | D4: เด็กชายกฤษดา บัวศรี | E4: 01/10/2555
A5: 2 | B5: 4875 | C5: 1470801468064 | D5: เด็กชายจิรายุ ดอบุตร | E5: 22/01/2555
A6: 3 | B6: 4878 | C6: 1470801475991 | D6: เด็กชายจิรายุ เนตรสว่าง | E6: 20/11/2555
A7: 4 | B7: 4879 | C7: 1909803751611 | D7: เด็กชายจีรภัทร คันธมาตย์ | E7: 22/02/2555
A8: 5 | B8: 4880 | C8: 1470801474293 | D8: เด็กชายปรวัฒน์ โพธิ์ศรี | E8: 27/09/2555
A9: 6 | B9: 4881 | C9: 1470801470069 | D9: เด็กชายพีรภาพ วงคำใหญ่ | E9: 05/04/2555
A10: 7 | B10: 4926 | C10: 1479300152500 | D10: เด็กหญิงกมลรัตน์ แสดคง | E10: 20/07/2555
A11: 8 | B11: 4882 | C11: 1470801474064 | D11: เด็กหญิงกัลยรัตน์ ทึงสุข | E11: 17/09/2555
A12: 9 | B12: 4883 | C12: 1100704339339 | D12: เด็กหญิงนิตยา พละโท | E12: 24/03/2555
A13: 10 | B13: 4884 | C13: 1470801476431 | D13: เด็กหญิงบัณฑิตา เบ้าพงษ์ | E13: 09/12/2555
A14: 11 | B14: 4885 | C14: 1470801474111 | D14: เด็กหญิงพัชรกัญญ์ บาลนาคม | E14: 17/09/2555
A15: 12 | B15: 4886 | C15: 1749700193626 | D15: เด็กหญิงสุวิชาดา ชูจิตร | E15: 26/03/2555
A16: 13 | B16: 4887 | C16: 1470801468862 | D16: เด็กหญิงปุญญิศา อุปทุม | E16: 25/02/2555

Sheet เวลาเรียน4-16
AK1: 4 | BT1: 5 | DC1: 6 | EL1: 7 | FU1: 8 | HD1: 9 | IL1: 10 | JU1: 11 | LD1: 12 | MM1: 13 | NV1: 14 | PE1: 15 | PT1: 16
A2: เลขที่ | B2: ชื่อ | C2: เวลาเรียน ประจำเดือน พฤษภาคม พ.ศ. 2567 | AL2: เวลาเรียน ประจำเดือน มิถุนายน พ.ศ. 2567 | BU2: เวลาเรียน ประจำเดือน กรกฎาคม พ.ศ. 2567 | DD2: เวลาเรียน ประจำเดือน สิงหาคม พ.ศ. 2567 | EM2: เวลาเรียน ประจำเดือน กันยายน พ.ศ. 2567 | FV2: เวลาเรียน ประจำเดือน ตุลาคม พ.ศ. 2567 | HE2: เวลาเรียน ประจำเดือน พฤศจิกายน พ.ศ. 2567 | IN2: เวลาเรียน ประจำเดือน ธันวาคม พ.ศ. 2567 | JW2: เวลาเรียน ประจำเดือน มกราคม พ.ศ. 2568 | LF2: เวลาเรียน ประจำเดือน กุมภาพันธ์ พ.ศ. 2568 | MO2: เวลาเรียน ประจำเดือน มีนาคม พ.ศ. 2568 | NX2: เวลาเรียน ประจำเดือน เมษายน พ.ศ. 2568 | PG2: สรุปเวลาเรียน
C3: วันที่ | AH3: รวมเวลาเรียน | AL3: วันที่ | BQ3: รวมเวลาเรียน | BU3: วันที่ | CZ3: รวมเวลาเรียน | DD3: วันที่ | EI3: รวมเวลาเรียน | EM3: วันที่ | FR3: รวมเวลาเรียน | FV3: วันที่ | HA3: รวมเวลาเรียน | HE3: วันที่ | IJ3: รวมเวลาเรียน | IN3: วันที่ | JS3: รวมเวลาเรียน | JW3: วันที่ | LB3: รวมเวลาเรียน | LF3: วันที่ | MK3: รวมเวลาเรียน | MO3: วันที่ | NT3: รวมเวลาเรียน | NX3: วันที่ | PC3: รวมเวลาเรียน | PG3: พ.ค. | PH3: มิ.ย. | PI3: ก.ค. | PJ3: ส.ค. | PK3: ก.ย. | PL3: ต.ค. | PM3: พ.ย. | PN3: ธ.ค. | PO3: ม.ค. | PP3: ก.พ. | PQ3: มี.ค. | PR3: เม.ย. | PS3: รวม | PT3: คิดเป็นร้อยละ
C4: 1 | D4: 2 | E4: 3 | F4: 4 | G4: 5 | H4: 6 | I4: 7 | J4: 8 | K4: 9 | L4: 10 | M4: 11 | N4: 12 | O4: 13 | P4: 14 | Q4: 15 | R4: 16 | S4: 17 | T4: 18 | U4: 19 | V4: 20 | W4: 21 | X4: 22 | Y4: 23 | Z4: 24 | AA4: 25 | AB4: 26 | AC4: 27 | AD4: 28 | AE4: 29 | AF4: 30 | AG4: 31 | AH4: 11 | AK4: วัน | AL4: 1 | AM4: 2 | AN4: 3 | AO4: 4 | AP4: 5 | AQ4: 6 | AR4: 7 | AS4: 8 | AT4: 9 | AU4: 10 | AV4: 11 | AW4: 12 | AX4: 13 | AY4: 14 | AZ4: 15 | BA4: 16 | BB4: 17 | BC4: 18 | BD4: 19 | BE4: 20 | BF4: 21 | BG4: 22 | BH4: 23 | BI4: 24 | BJ4: 25 | BK4: 26 | BL4: 27 | BM4: 28 | BN4: 29 | BO4: 30 | BQ4: 19 | BT4: วัน | BU4: 1 | BV4: 2 | BW4: 3 | BX4: 4 | BY4: 5 | BZ4: 6 | CA4: 7 | CB4: 8 | CC4: 9 | CD4: 10 | CE4: 11 | CF4: 12 | CG4: 13 | CH4: 14 | CI4: 15 | CJ4: 16 | CK4: 17 | CL4: 18 | CM4: 19 | CN4: 20 | CO4: 21 | CP4: 22 | CQ4: 23 | CR4: 24 | CS4: 25 | CT4: 26 | CU4: 27 | CV4: 28 | CW4: 29 | CX4: 30 | CY4: 31 | CZ4: 21 | DC4: วัน | DD4: 1 | DE4: 2 | DF4: 3 | DG4: 4 | DH4: 5 | DI4: 6 | DJ4: 7 | DK4: 8 | DL4: 9 | DM4: 10 | DN4: 11 | DO4: 12 | DP4: 13 | DQ4: 14 | DR4: 15 | DS4: 16 | DT4: 17 | DU4: 18 | DV4: 19 | DW4: 20 | DX4: 21 | DY4: 22 | DZ4: 23 | EA4: 24 | EB4: 25 | EC4: 26 | ED4: 27 | EE4: 28 | EF4: 29 | EG4: 30 | EH4: 31 | EI4: 21 | EL4: วัน | EM4: 1 | EN4: 2 | EO4: 3 | EP4: 4 | EQ4: 5 | ER4: 6 | ES4: 7 | ET4: 8 | EU4: 9 | EV4: 10 | EW4: 11 | EX4: 12 | EY4: 13 | EZ4: 14 | FA4: 15 | FB4: 16 | FC4: 17 | FD4: 18 | FE4: 19 | FF4: 20 | FG4: 21 | FH4: 22 | FI4: 23 | FJ4: 24 | FK4: 25 | FL4: 26 | FM4: 27 | FN4: 28 | FO4: 29 | FP4: 30 | FR4: 21 | FU4: วัน | FV4: 1 | FW4: 2 | FX4: 3 | FY4: 4 | FZ4: 5 | GA4: 6 | GB4: 7 | GC4: 8 | GD4: 9 | GE4: 10 | GF4: 11 | GG4: 12 | GH4: 13 | GI4: 14 | GJ4: 15 | GK4: 16 | GL4: 17 | GM4: 18 | GN4: 19 | GO4: 20 | GP4: 21 | GQ4: 22 | GR4: 23 | GS4: 24 | GT4: 25 | GU4: 26 | GV4: 27 | GW4: 28 | GX4: 29 | GY4: 30 | GZ4: 31 | HA4: 6 | HD4: วัน | HE4: 1 | HF4: 2 | HG4: 3 | HH4: 4 | HI4: 5 | HJ4: 6 | HK4: 7 | HL4: 8 | HM4: 9 | HN4: 10 | HO4: 11 | HP4: 12 | HQ4: 13 | HR4: 14 | HS4: 15 | HT4: 16 | HU4: 17 | HV4: 18 | HW4: 19 | HX4: 20 | HY4: 21 | HZ4: 22 | IA4: 23 | IB4: 24 | IC4: 25 | ID4: 26 | IE4: 27 | IF4: 28 | IG4: 29 | IH4: 30 | IJ4: 21 | IM4: วัน | IN4: 1 | IO4: 2 | IP4: 3 | IQ4: 4 | IR4: 5 | IS4: 6 | IT4: 7 | IU4: 8 | IV4: 9 | IW4: 10 | IX4: 11 | IY4: 12 | IZ4: 13 | JA4: 14 | JB4: 15 | JC4: 16 | JD4: 17 | JE4: 18 | JF4: 19 | JG4: 20 | JH4: 21 | JI4: 22 | JJ4: 23 | JK4: 24 | JL4: 25 | JM4: 26 | JN4: 27 | JO4: 28 | JP4: 29 | JQ4: 30 | JR4: 31 | JS4: 18 | JV4: วัน | JW4: 1 | JX4: 2 | JY4: 3 | JZ4: 4 | KA4: 5 | KB4: 6 | KC4: 7 | KD4: 8 | KE4: 9 | KF4: 10 | KG4: 11 | KH4: 12 | KI4: 13 | KJ4: 14 | KK4: 15 | KL4: 16 | KM4: 17 | KN4: 18 | KO4: 19 | KP4: 20 | KQ4: 21 | KR4: 22 | KS4: 23 | KT4: 24 | KU4: 25 | KV4: 26 | KW4: 27 | KX4: 28 | KY4: 29 | KZ4: 30 | LA4: 31 | LB4: 22 | LE4: วัน | LF4: 1 | LG4: 2 | LH4: 3 | LI4: 4 | LJ4: 5 | LK4: 6 | LL4: 7 | LM4: 8 | LN4: 9 | LO4: 10 | LP4: 11 | LQ4: 12 | LR4: 13 | LS4: 14 | LT4: 15 | LU4: 16 | LV4: 17 | LW4: 18 | LX4: 19 | LY4: 20 | LZ4: 21 | MA4: 22 | MB4: 23 | MC4: 24 | MD4: 25 | ME4: 26 | MF4: 27 | MG4: 28 | MH4: 29 | MK4: 20 | MN4: วัน | MO4: 1 | MP4: 2 | MQ4: 3 | MR4: 4 | MS4: 5 | MT4: 6 | MU4: 7 | MV4: 8 | MW4: 9 | MX4: 10 | MY4: 11 | MZ4: 12 | NA4: 13 | NB4: 14 | NC4: 15 | ND4: 16 | NE4: 17 | NF4: 18 | NG4: 19 | NH4: 20 | NI4: 21 | NJ4: 22 | NK4: 23 | NL4: 24 | NM4: 25 | NN4: 26 | NO4: 27 | NP4: 28 | NQ4: 29 | NR4: 30 | NS4: 31 | NT4: 20 | NW4: วัน | NX4: 1 | NY4: 2 | NZ4: 3 | OA4: 4 | OB4: 5 | OC4: 6 | OD4: 7 | OE4: 8 | OF4: 9 | OG4: 10 | OH4: 11 | OI4: 12 | OJ4: 13 | OK4: 14 | OL4: 15 | OM4: 16 | ON4: 17 | OO4: 18 | OP4: 19 | OQ4: 20 | OR4: 21 | OS4: 22 | OT4: 23 | OU4: 24 | OV4: 25 | OW4: 26 | OX4: 27 | OY4: 28 | OZ4: 29 | PA4: 30 | PC4: 0 | PF4: วัน | PG4: =AH4 -> 11 | PH4: =BQ4 -> 19 | PI4: =CZ4 -> 21 | PJ4: =EI4 -> 21 | PK4: =FR4 -> 21 | PL4: =HA4 -> 6 | PM4: =IJ4 -> 21 | PN4: =JS4 -> 18 | PO4: =LB4 -> 22 | PP4: =MK4 -> 20 | PQ4: =NT4 -> 20 | PR4: =PC4 -> 0 | PS4: =SUM(PG4:PR5) -> 200
C5: พ | D5: พฤ | E5: ศ | F5: ส | G5: อา | H5: จ | I5: อ | J5: พ | K5: พฤ | L5: ศ | M5: ส | N5: อา | O5: จ | P5: อ | Q5: พ | R5: พฤ | S5: ศ | T5: ส | U5: อา | V5: จ | W5: อ | X5: พ | Y5: พฤ | Z5: ศ | AA5: ส | AB5: อา | AC5: จ | AD5: อ | AE5: พ | AF5: พฤ | AG5: ศ | AH5: มา | AI5: ป่วย | AJ5: ลา | AK5: ขาด | AL5: ส | AM5: อา | AN5: จ | AO5: อ | AP5: พ | AQ5: พฤ | AR5: ศ | AS5: ส | AT5: อา | AU5: จ | AV5: อ | AW5: พ | AX5: พฤ | AY5: ศ | AZ5: ส | BA5: อา | BB5: จ | BC5: อ | BD5: พ | BE5: พฤ | BF5: ศ | BG5: ส | BH5: อา | BI5: จ | BJ5: อ | BK5: พ | BL5: พฤ | BM5: ศ | BN5: ส | BO5: อา | BQ5: มา | BR5: ป่วย | BS5: ลา | BT5: ขาด | BU5: จ | BV5: อ | BW5: พ | BX5: พฤ | BY5: ศ | BZ5: ส | CA5: อา | CB5: จ | CC5: อ | CD5: พ | CE5: พฤ | CF5: ศ | CG5: ส | CH5: อา | CI5: จ | CJ5: อ | CK5: พ | CL5: พฤ | CM5: ศ | CN5: ส | CO5: อา | CP5: จ | CQ5: อ | CR5: พ | CS5: พฤ | CT5: ศ | CU5: ส | CV5: อา | CW5: จ | CX5: อ | CY5: พ | CZ5: มา | DA5: ป่วย | DB5: ลา | DC5: ขาด | DD5: พฤ | DE5: ศ | DF5: ส | DG5: อา | DH5: จ | DI5: อ | DJ5: พ | DK5: พฤ | DL5: ศ | DM5: ส | DN5: อา | DO5: จ | DP5: อ | DQ5: พ | DR5: พฤ | DS5: ศ | DT5: ส | DU5: อา | DV5: จ | DW5: อ | DX5: พ | DY5: พฤ | DZ5: ศ | EA5: ส | EB5: อา | EC5: จ | ED5: อ | EE5: พ | EF5: พฤ | EG5: ศ | EH5: ส | EI5: มา | EJ5: ป่วย | EK5: ลา | EL5: ขาด | EM5: อา | EN5: จ | EO5: อ | EP5: พ | EQ5: พฤ | ER5: ศ | ES5: ส | ET5: อา | EU5: จ | EV5: อ | EW5: พ | EX5: พฤ | EY5: ศ | EZ5: ส | FA5: อา | FB5: จ | FC5: อ | FD5: พ | FE5: พฤ | FF5: ศ | FG5: ส | FH5: อา | FI5: จ | FJ5: อ | FK5: พ | FL5: พฤ | FM5: ศ | FN5: ส | FO5: อา | FP5: จ | FR5: มา | FS5: ป่วย | FT5: ลา | FU5: ขาด | FV5: อ | FW5: พ | FX5: พฤ | FY5: ศ | FZ5: ส | GA5: อา | GB5: จ | GC5: อ | GD5: พ | GE5: พฤ | GF5: ศ | GG5: ส | GH5: อา | GI5: จ | GJ5: อ | GK5: พ | GL5: พฤ | GM5: ศ | GN5: ส | GO5: อา | GP5: จ | GQ5: อ | GR5: พ | GS5: พฤ | GT5: ศ | GU5: ส | GV5: อา | GW5: จ | GX5: อ | GY5: พ | GZ5: พฤ | HA5: มา | HB5: ป่วย | HC5: ลา | HD5: ขาด | HE5: ศ | HF5: ส | HG5: อา | HH5: จ | HI5: อ | HJ5: พ | HK5: พฤ | HL5: ศ | HM5: ส | HN5: อา | HO5: จ | HP5: อ | HQ5: พ | HR5: พฤ | HS5: ศ | HT5: ส | HU5: อา | HV5: จ | HW5: อ | HX5: พ | HY5: พฤ | HZ5: ศ | IA5: ส | IB5: อา | IC5: จ | ID5: อ | IE5: พ | IF5: พฤ | IG5: ศ | IH5: ส | IJ5: มา | IK5: ป่วย | IL5: ลา | IM5: ขาด | IN5: อา | IO5: จ | IP5: อ | IQ5: พ | IR5: พฤ | IS5: ศ | IT5: ส | IU5: อา | IV5: จ | IW5: อ | IX5: พ | IY5: พฤ | IZ5: ศ | JA5: ส | JB5: อา | JC5: จ | JD5: อ | JE5: พ | JF5: พฤ | JG5: ศ | JH5: ส | JI5: อา | JJ5: จ | JK5: อ | JL5: พ | JM5: พฤ | JN5: ศ | JO5: ส | JP5: อา | JQ5: จ | JR5: อ | JS5: มา | JT5: ป่วย | JU5: ลา | JV5: ขาด | JW5: พ | JX5: พฤ | JY5: ศ | JZ5: ส | KA5: อา | KB5: จ | KC5: อ | KD5: พ | KE5: พฤ | KF5: ศ | KG5: ส | KH5: ศ | KI5: อา | KJ5: จ | KK5: อ | KL5: พ | KM5: พฤ | KN5: ศ | KO5: ส | KP5: อา | KQ5: จ | KR5: อ | KS5: พ | KT5: พฤ | KU5: ศ | KV5: ส | KW5: อา | KX5: จ | KY5: อ | KZ5: พ | LA5: พฤ | LB5: มา | LC5: ป่วย | LD5: ลา | LE5: ขาด | LF5: พฤ | LG5: ศ | LH5: ส | LI5: อา | LJ5: จ | LK5: อ | LL5: พ | LM5: พฤ | LN5: ศ | LO5: ส | LP5: อา | LQ5: จ | LR5: อ | LS5: พ | LT5: พฤ | LU5: ศ | LV5: ส | LW5: อา | LX5: จ | LY5: อ | LZ5: พ | MA5: พฤ | MB5: ศ | MC5: ส | MD5: อา | ME5: จ | MF5: อ | MG5: พ | MH5: พฤ | MK5: มา | ML5: ป่วย | MM5: ลา | MN5: ขาด | MO5: ส | MP5: อา | MQ5: จ | MR5: อ | MS5: พ | MT5: พฤ | MU5: ศ | MV5: ส | MW5: อา | MX5: จ | MY5: อ | MZ5: พ | NA5: พฤ | NB5: ศ | NC5: ส | ND5: อา | NE5: จ | NF5: อ | NG5: พ | NH5: พฤ | NI5: ศ | NJ5: ส | NK5: ส | NL5: อา | NM5: จ | NN5: อ | NO5: พ | NP5: พฤ | NQ5: ศ | NR5: ส | NS5: อา | NT5: มา | NU5: ป่วย | NV5: ลา | NW5: ขาด | NX5: จ | NY5: อ | NZ5: พ | OA5: พฤ | OB5: ศ | OC5: ส | OD5: อา | OE5: จ | OF5: อ | OG5: พ | OH5: พฤ | OI5: ศ | OJ5: ส | OK5: อา | OL5: จ | OM5: อ | ON5: พ | OO5: พฤ | OP5: ศ | OQ5: ส | OR5: อา | OS5: จ | OT5: อ | OU5: พ | OV5: พฤ | OW5: ศ | OX5: ส | OY5: อา | OZ5: จ | PA5: อ | PC5: มา | PD5: ป่วย | PE5: ลา | PF5: ขาด
A6: 1 | B6: ='ข้อมูลนร.2-3'!D4 -> เด็กชายกฤษดา บัวศรี | AH6: =$AH$4-(AI6+AJ6+AK6) -> 11 | AI6: =COUNTIF(C6:AG6,"ป") -> 0 | AJ6: =COUNTIF(C6:AG6,"ล") -> 0 | AK6: =COUNTIF(C6:AG6,"ข") -> 0 | AQ6: ล | BC6: ล | BQ6: =$BQ$4-(BR6+BS6+BT6) -> 17 | BR6: =COUNTIF(AL6:BP6,"ป") -> 0 | BS6: =COUNTIF(AL6:BP6,"ล") -> 2 | BT6: =COUNTIF(AL6:BP6,"ข") -> 0 | CL6: ล | CZ6: =$CZ$4-(DA6+DB6+DC6) -> 20 | DA6: =COUNTIF(BU6:CY6,"ป") -> 0 | DB6: =COUNTIF(BU6:CY6,"ล") -> 1 | DC6: =COUNTIF(BU6:CY6,"ข") -> 0 | DJ6: ล | DK6: ล | DL6: ล | EI6: =$EI$4-(EJ6+EK6+EL6) -> 18 | EJ6: =COUNTIF(DD6:EH6,"ป") -> 0 | EK6: =COUNTIF(DD6:EH6,"ล") -> 3 | EL6: =COUNTIF(DD6:EH6,"ข") -> 0 | FR6: =$FR$4-(FS6+FT6+FU6) -> 21 | FS6: =COUNTIF(EM6:FQ6,"ป") -> 0 | FT6: =COUNTIF(EM6:FQ6,"ล") -> 0 | FU6: =COUNTIF(EM6:FQ6,"ข") -> 0 | HA6: =$HA$4-(HB6+HC6+HD6) -> 6 | HB6: =COUNTIF(FV6:GZ6,"ป") -> 0 | HC6: =COUNTIF(FV6:GZ6,"ล") -> 0 | HD6: =COUNTIF(FV6:GZ6,"ข") -> 0 | IJ6: =$IJ$4-(IK6+IL6+IM6) -> 21 | IK6: =COUNTIF(HE6:II6,"ป") -> 0 | IL6: =COUNTIF(HE6:II6,"ล") -> 0 | IM6: =COUNTIF(HE6:II6,"ข") -> 0 | JS6: =$JS$4-(JT6+JU6+JV6) -> 18 | JT6: =COUNTIF(IN6:JR6,"ป") -> 0 | JU6: =COUNTIF(IN6:JR6,"ล") -> 0 | JV6: =COUNTIF(IN6:JR6,"ข") -> 0 | LB6: =$LB$4-(LC6+LD6+LE6) -> 22 | LC6: =COUNTIF(JW6:LA6,"ป") -> 0 | LD6: =COUNTIF(JW6:LA6,"ล") -> 0 | LE6: =COUNTIF(JW6:LA6,"ข") -> 0 | MK6: =$MK$4-(ML6+MM6+MN6) -> 20 | ML6: =COUNTIF(LF6:MJ6,"ป") -> 0 | MM6: =COUNTIF(LF6:MJ6,"ล") -> 0 | MN6: =COUNTIF(LF6:MJ6,"ข") -> 0 | MY6: ล | NT6: =$NT$4-(NU6+NV6+NW6) -> 19 | NU6: =COUNTIF(MO6:NS6,"ป") -> 0 | NV6: =COUNTIF(MO6:NS6,"ล") -> 1 | NW6: =COUNTIF(MO6:NS6,"ข") -> 0 | PC6: =$PC$4-(PD6+PE6+PF6) -> 0 | PD6: =COUNTIF(NX6:PB6,"ป") -> 0 | PE6: =COUNTIF(NX6:PB6,"ล") -> 0 | PF6: =COUNTIF(NX6:PB6,"ข") -> 0 | PG6: =AH6 -> 11 | PH6: =BQ6 -> 17 | PI6: =CZ6 -> 20 | PJ6: =EI6 -> 18 | PK6: =FR6 -> 21 | PL6: =HA6 -> 6 | PM6: =IJ6 -> 21 | PN6: =JS6 -> 18 | PO6: =LB6 -> 22 | PP6: =MK6 -> 20 | PQ6: =NT6 -> 19 | PR6: =PC6 -> 0 | PS6: =SUM(PC6:PR6) -> 193 | PT6: =PS6*100/$PS$4 -> 96.5
A7: 2 | B7: ='ข้อมูลนร.2-3'!D5 -> เด็กชายจิรายุ ดอบุตร | AH7: =$AH$4-(AI7+AJ7+AK7) -> 11 | AI7: =COUNTIF(C7:AG7,"ป") -> 0 | AJ7: =COUNTIF(C7:AG7,"ล") -> 0 | AK7: =COUNTIF(C7:AG7,"ข") -> 0 | BQ7: =$BQ$4-(BR7+BS7+BT7) -> 19 | BR7: =COUNTIF(AL7:BP7,"ป") -> 0 | BS7: =COUNTIF(AL7:BP7,"ล") -> 0 | BT7: =COUNTIF(AL7:BP7,"ข") -> 0 | CE7: ล | CZ7: =$CZ$4-(DA7+DB7+DC7) -> 20 | DA7: =COUNTIF(BU7:CY7,"ป") -> 0 | DB7: =COUNTIF(BU7:CY7,"ล") -> 1 | DC7: =COUNTIF(BU7:CY7,"ข") -> 0 | DS7: ล | EI7: =$EI$4-(EJ7+EK7+EL7) -> 20 | EJ7: =COUNTIF(DD7:EH7,"ป") -> 0 | EK7: =COUNTIF(DD7:EH7,"ล") -> 1 | EL7: =COUNTIF(DD7:EH7,"ข") -> 0 | FR7: =$FR$4-(FS7+FT7+FU7) -> 21 | FS7: =COUNTIF(EM7:FQ7,"ป") -> 0 | FT7: =COUNTIF(EM7:FQ7,"ล") -> 0 | FU7: =COUNTIF(EM7:FQ7,"ข") -> 0 | HA7: =$HA$4-(HB7+HC7+HD7) -> 6 | HB7: =COUNTIF(FV7:GZ7,"ป") -> 0 | HC7: =COUNTIF(FV7:GZ7,"ล") -> 0 | HD7: =COUNTIF(FV7:GZ7,"ข") -> 0 | IJ7: =$IJ$4-(IK7+IL7+IM7) -> 21 | IK7: =COUNTIF(HE7:II7,"ป") -> 0 | IL7: =COUNTIF(HE7:II7,"ล") -> 0 | IM7: =COUNTIF(HE7:II7,"ข") -> 0 | JS7: =$JS$4-(JT7+JU7+JV7) -> 18 | JT7: =COUNTIF(IN7:JR7,"ป") -> 0 | JU7: =COUNTIF(IN7:JR7,"ล") -> 0 | JV7: =COUNTIF(IN7:JR7,"ข") -> 0 | JX7: ล | KJ7: ล | LB7: =$LB$4-(LC7+LD7+LE7) -> 20 | LC7: =COUNTIF(JW7:LA7,"ป") -> 0 | LD7: =COUNTIF(JW7:LA7,"ล") -> 2 | LE7: =COUNTIF(JW7:LA7,"ข") -> 0 | MK7: =$MK$4-(ML7+MM7+MN7) -> 20 | ML7: =COUNTIF(LF7:MJ7,"ป") -> 0 | MM7: =COUNTIF(LF7:MJ7,"ล") -> 0 | MN7: =COUNTIF(LF7:MJ7,"ข") -> 0 | NT7: =$NT$4-(NU7+NV7+NW7) -> 20 | NU7: =COUNTIF(MO7:NS7,"ป") -> 0 | NV7: =COUNTIF(MO7:NS7,"ล") -> 0 | NW7: =COUNTIF(MO7:NS7,"ข") -> 0 | PC7: =$PC$4-(PD7+PE7+PF7) -> 0 | PD7: =COUNTIF(NX7:PB7,"ป") -> 0 | PE7: =COUNTIF(NX7:PB7,"ล") -> 0 | PF7: =COUNTIF(NX7:PB7,"ข") -> 0 | PG7: =AH7 -> 11 | PH7: =BQ7 -> 19 | PI7: =CZ7 -> 20 | PJ7: =EI7 -> 20 | PK7: =FR7 -> 21 | PL7: =HA7 -> 6 | PM7: =IJ7 -> 21 | PN7: =JS7 -> 18 | PO7: =LB7 -> 20 | PP7: =MK7 -> 20 | PQ7: =NT7 -> 20 | PR7: =PC7 -> 0 | PS7: =SUM(PC7:PR7) -> 196 | PT7: =PS7*100/$PS$4 -> 98
A8: 3 | B8: ='ข้อมูลนร.2-3'!D6 -> เด็กชายจิรายุ เนตรสว่าง | AH8: =$AH$4-(AI8+AJ8+AK8) -> 11 | AI8: =COUNTIF(C8:AG8,"ป") -> 0 | AJ8: =COUNTIF(C8:AG8,"ล") -> 0 | AK8: =COUNTIF(C8:AG8,"ข") -> 0 | BQ8: =$BQ$4-(BR8+BS8+BT8) -> 19 | BR8: =COUNTIF(AL8:BP8,"ป") -> 0 | BS8: =COUNTIF(AL8:BP8,"ล") -> 0 | BT8: =COUNTIF(AL8:BP8,"ข") -> 0 | CM8: ล | CZ8: =$CZ$4-(DA8+DB8+DC8) -> 20 | DA8: =COUNTIF(BU8:CY8,"ป") -> 0 | DB8: =COUNTIF(BU8:CY8,"ล") -> 1 | DC8: =COUNTIF(BU8:CY8,"ข") -> 0 | EI8: =$EI$4-(EJ8+EK8+EL8) -> 21 | EJ8: =COUNTIF(DD8:EH8,"ป") -> 0 | EK8: =COUNTIF(DD8:EH8,"ล") -> 0 | EL8: =COUNTIF(DD8:EH8,"ข") -> 0 | FR8: =$FR$4-(FS8+FT8+FU8) -> 21 | FS8: =COUNTIF(EM8:FQ8,"ป") -> 0 | FT8: =COUNTIF(EM8:FQ8,"ล") -> 0 | FU8: =COUNTIF(EM8:FQ8,"ข") -> 0 | HA8: =$HA$4-(HB8+HC8+HD8) -> 6 | HB8: =COUNTIF(FV8:GZ8,"ป") -> 0 | HC8: =COUNTIF(FV8:GZ8,"ล") -> 0 | HD8: =COUNTIF(FV8:GZ8,"ข") -> 0 | IJ8: =$IJ$4-(IK8+IL8+IM8) -> 21 | IK8: =COUNTIF(HE8:II8,"ป") -> 0 | IL8: =COUNTIF(HE8:II8,"ล") -> 0 | IM8: =COUNTIF(HE8:II8,"ข") -> 0 | JS8: =$JS$4-(JT8+JU8+JV8) -> 18 | JT8: =COUNTIF(IN8:JR8,"ป") -> 0 | JU8: =COUNTIF(IN8:JR8,"ล") -> 0 | JV8: =COUNTIF(IN8:JR8,"ข") -> 0 | LB8: =$LB$4-(LC8+LD8+LE8) -> 22 | LC8: =COUNTIF(JW8:LA8,"ป") -> 0 | LD8: =COUNTIF(JW8:LA8,"ล") -> 0 | LE8: =COUNTIF(JW8:LA8,"ข") -> 0 | MK8: =$MK$4-(ML8+MM8+MN8) -> 20 | ML8: =COUNTIF(LF8:MJ8,"ป") -> 0 | MM8: =COUNTIF(LF8:MJ8,"ล") -> 0 | MN8: =COUNTIF(LF8:MJ8,"ข") -> 0 | NT8: =$NT$4-(NU8+NV8+NW8) -> 20 | NU8: =COUNTIF(MO8:NS8,"ป") -> 0 | NV8: =COUNTIF(MO8:NS8,"ล") -> 0 | NW8: =COUNTIF(MO8:NS8,"ข") -> 0 | PC8: =$PC$4-(PD8+PE8+PF8) -> 0 | PD8: =COUNTIF(NX8:PB8,"ป") -> 0 | PE8: =COUNTIF(NX8:PB8,"ล") -> 0 | PF8: =COUNTIF(NX8:PB8,"ข") -> 0 | PG8: =AH8 -> 11 | PH8: =BQ8 -> 19 | PI8: =CZ8 -> 20 | PJ8: =EI8 -> 21 | PK8: =FR8 -> 21 | PL8: =HA8 -> 6 | PM8: =IJ8 -> 21 | PN8: =JS8 -> 18 | PO8: =LB8 -> 22 | PP8: =MK8 -> 20 | PQ8: =NT8 -> 20 | PR8: =PC8 -> 0 | PS8: =SUM(PC8:PR8) -> 199 | PT8: =PS8*100/$PS$4 -> 99.5
A9: 4 | B9: ='ข้อมูลนร.2-3'!D7 -> เด็กชายจีรภัทร คันธมาตย์ | Y9: ป | AH9: =$AH$4-(AI9+AJ9+AK9) -> 10 | AI9: =COUNTIF(C9:AG9,"ป") -> 1 | AJ9: =COUNTIF(C9:AG9,"ล") -> 0 | AK9: =COUNTIF(C9:AG9,"ข") -> 0 | BQ9: =$BQ$4-(BR9+BS9+BT9) -> 19 | BR9: =COUNTIF(AL9:BP9,"ป") -> 0 | BS9: =COUNTIF(AL9:BP9,"ล") -> 0 | BT9: =COUNTIF(AL9:BP9,"ข") -> 0 | CR9: ล | CZ9: =$CZ$4-(DA9+DB9+DC9) -> 20 | DA9: =COUNTIF(BU9:CY9,"ป") -> 0 | DB9: =COUNTIF(BU9:CY9,"ล") -> 1 | DC9: =COUNTIF(BU9:CY9,"ข") -> 0 | EI9: =$EI$4-(EJ9+EK9+EL9) -> 21 | EJ9: =COUNTIF(DD9:EH9,"ป") -> 0 | EK9: =COUNTIF(DD9:EH9,"ล") -> 0 | EL9: =COUNTIF(DD9:EH9,"ข") -> 0 | FR9: =$FR$4-(FS9+FT9+FU9) -> 21 | FS9: =COUNTIF(EM9:FQ9,"ป") -> 0 | FT9: =COUNTIF(EM9:FQ9,"ล") -> 0 | FU9: =COUNTIF(EM9:FQ9,"ข") -> 0 | HA9: =$HA$4-(HB9+HC9+HD9) -> 6 | HB9: =COUNTIF(FV9:GZ9,"ป") -> 0 | HC9: =COUNTIF(FV9:GZ9,"ล") -> 0 | HD9: =COUNTIF(FV9:GZ9,"ข") -> 0 | HZ9: ล | IJ9: =$IJ$4-(IK9+IL9+IM9) -> 20 | IK9: =COUNTIF(HE9:II9,"ป") -> 0 | IL9: =COUNTIF(HE9:II9,"ล") -> 1 | IM9: =COUNTIF(HE9:II9,"ข") -> 0 | JS9: =$JS$4-(JT9+JU9+JV9) -> 18 | JT9: =COUNTIF(IN9:JR9,"ป") -> 0 | JU9: =COUNTIF(IN9:JR9,"ล") -> 0 | JV9: =COUNTIF(IN9:JR9,"ข") -> 0 | LB9: =$LB$4-(LC9+LD9+LE9) -> 22 | LC9: =COUNTIF(JW9:LA9,"ป") -> 0 | LD9: =COUNTIF(JW9:LA9,"ล") -> 0 | LE9: =COUNTIF(JW9:LA9,"ข") -> 0 | MK9: =$MK$4-(ML9+MM9+MN9) -> 20 | ML9: =COUNTIF(LF9:MJ9,"ป") -> 0 | MM9: =COUNTIF(LF9:MJ9,"ล") -> 0 | MN9: =COUNTIF(LF9:MJ9,"ข") -> 0 | NT9: =$NT$4-(NU9+NV9+NW9) -> 20 | NU9: =COUNTIF(MO9:NS9,"ป") -> 0 | NV9: =COUNTIF(MO9:NS9,"ล") -> 0 | NW9: =COUNTIF(MO9:NS9,"ข") -> 0 | PC9: =$PC$4-(PD9+PE9+PF9) -> 0 | PD9: =COUNTIF(NX9:PB9,"ป") -> 0 | PE9: =COUNTIF(NX9:PB9,"ล") -> 0 | PF9: =COUNTIF(NX9:PB9,"ข") -> 0 | PG9: =AH9 -> 10 | PH9: =BQ9 -> 19 | PI9: =CZ9 -> 20 | PJ9: =EI9 -> 21 | PK9: =FR9 -> 21 | PL9: =HA9 -> 6 | PM9: =IJ9 -> 20 | PN9: =JS9 -> 18 | PO9: =LB9 -> 22 | PP9: =MK9 -> 20 | PQ9: =NT9 -> 20 | PR9: =PC9 -> 0 | PS9: =SUM(PC9:PR9) -> 197 | PT9: =PS9*100/$PS$4 -> 98.5
A10: 5 | B10: ='ข้อมูลนร.2-3'!D8 -> เด็กชายปรวัฒน์ โพธิ์ศรี | AH10: =$AH$4-(AI10+AJ10+AK10) -> 11 | AI10: =COUNTIF(C10:AG10,"ป") -> 0 | AJ10: =COUNTIF(C10:AG10,"ล") -> 0 | AK10: =COUNTIF(C10:AG10,"ข") -> 0 | AU10: ล | BQ10: =$BQ$4-(BR10+BS10+BT10) -> 18 | BR10: =COUNTIF(AL10:BP10,"ป") -> 0 | BS10: =COUNTIF(AL10:BP10,"ล") -> 1 | BT10: =COUNTIF(AL10:BP10,"ข") -> 0 | CJ10: ล | CZ10: =$CZ$4-(DA10+DB10+DC10) -> 20 | DA10: =COUNTIF(BU10:CY10,"ป") -> 0 | DB10: =COUNTIF(BU10:CY10,"ล") -> 1 | DC10: =COUNTIF(BU10:CY10,"ข") -> 0 | DV10: ล | DW10: ล | EI10: =$EI$4-(EJ10+EK10+EL10) -> 19 | EJ10: =COUNTIF(DD10:EH10,"ป") -> 0 | EK10: =COUNTIF(DD10:EH10,"ล") -> 2 | EL10: =COUNTIF(DD10:EH10,"ข") -> 0 | FR10: =$FR$4-(FS10+FT10+FU10) -> 21 | FS10: =COUNTIF(EM10:FQ10,"ป") -> 0 | FT10: =COUNTIF(EM10:FQ10,"ล") -> 0 | FU10: =COUNTIF(EM10:FQ10,"ข") -> 0 | HA10: =$HA$4-(HB10+HC10+HD10) -> 6 | HB10: =COUNTIF(FV10:GZ10,"ป") -> 0 | HC10: =COUNTIF(FV10:GZ10,"ล") -> 0 | HD10: =COUNTIF(FV10:GZ10,"ข") -> 0 | IJ10: =$IJ$4-(IK10+IL10+IM10) -> 21 | IK10: =COUNTIF(HE10:II10,"ป") -> 0 | IL10: =COUNTIF(HE10:II10,"ล") -> 0 | IM10: =COUNTIF(HE10:II10,"ข") -> 0 | JS10: =$JS$4-(JT10+JU10+JV10) -> 18 | JT10: =COUNTIF(IN10:JR10,"ป") -> 0 | JU10: =COUNTIF(IN10:JR10,"ล") -> 0 | JV10: =COUNTIF(IN10:JR10,"ข") -> 0 | LB10: =$LB$4-(LC10+LD10+LE10) -> 22 | LC10: =COUNTIF(JW10:LA10,"ป") -> 0 | LD10: =COUNTIF(JW10:LA10,"ล") -> 0 | LE10: =COUNTIF(JW10:LA10,"ข") -> 0 | MK10: =$MK$4-(ML10+MM10+MN10) -> 20 | ML10: =COUNTIF(LF10:MJ10,"ป") -> 0 | MM10: =COUNTIF(LF10:MJ10,"ล") -> 0 | MN10: =COUNTIF(LF10:MJ10,"ข") -> 0 | NT10: =$NT$4-(NU10+NV10+NW10) -> 20 | NU10: =COUNTIF(MO10:NS10,"ป") -> 0 | NV10: =COUNTIF(MO10:NS10,"ล") -> 0 | NW10: =COUNTIF(MO10:NS10,"ข") -> 0 | PC10: =$PC$4-(PD10+PE10+PF10) -> 0 | PD10: =COUNTIF(NX10:PB10,"ป") -> 0 | PE10: =COUNTIF(NX10:PB10,"ล") -> 0 | PF10: =COUNTIF(NX10:PB10,"ข") -> 0 | PG10: =AH10 -> 11 | PH10: =BQ10 -> 18 | PI10: =CZ10 -> 20 | PJ10: =EI10 -> 19 | PK10: =FR10 -> 21 | PL10: =HA10 -> 6 | PM10: =IJ10 -> 21 | PN10: =JS10 -> 18 | PO10: =LB10 -> 22 | PP10: =MK10 -> 20 | PQ10: =NT10 -> 20 | PR10: =PC10 -> 0 | PS10: =SUM(PC10:PR10) -> 196 | PT10: =PS10*100/$PS$4 -> 98
A11: 6 | B11: ='ข้อมูลนร.2-3'!D9 -> เด็กชายพีรภาพ วงคำใหญ่ | AA11: ป | AH11: =$AH$4-(AI11+AJ11+AK11) -> 10 | AI11: =COUNTIF(C11:AG11,"ป") -> 1 | AJ11: =COUNTIF(C11:AG11,"ล") -> 0 | AK11: =COUNTIF(C11:AG11,"ข") -> 0 | BQ11: =$BQ$4-(BR11+BS11+BT11) -> 19 | BR11: =COUNTIF(AL11:BP11,"ป") -> 0 | BS11: =COUNTIF(AL11:BP11,"ล") -> 0 | CZ11: =$CZ$4-(DA11+DB11+DC11) -> 21 | DA11: =COUNTIF(BU11:CY11,"ป") -> 0 | DB11: =COUNTIF(BU11:CY11,"ล") -> 0 | DC11: =COUNTIF(BU11:CY11,"ข") -> 0 | EI11: =$EI$4-(EJ11+EK11+EL11) -> 21 | EJ11: =COUNTIF(DD11:EH11,"ป") -> 0 | EK11: =COUNTIF(DD11:EH11,"ล") -> 0 | EL11: =COUNTIF(DD11:EH11,"ข") -> 0 | FR11: =$FR$4-(FS11+FT11+FU11) -> 21 | FS11: =COUNTIF(EM11:FQ11,"ป") -> 0 | FT11: =COUNTIF(EM11:FQ11,"ล") -> 0 | FU11: =COUNTIF(EM11:FQ11,"ข") -> 0 | HA11: =$HA$4-(HB11+HC11+HD11) -> 6 | HB11: =COUNTIF(FV11:GZ11,"ป") -> 0 | HC11: =COUNTIF(FV11:GZ11,"ล") -> 0 | HD11: =COUNTIF(FV11:GZ11,"ข") -> 0 | IJ11: =$IJ$4-(IK11+IL11+IM11) -> 21 | IK11: =COUNTIF(HE11:II11,"ป") -> 0 | IL11: =COUNTIF(HE11:II11,"ล") -> 0 | IM11: =COUNTIF(HE11:II11,"ข") -> 0 | JS11: =$JS$4-(JT11+JU11+JV11) -> 18 | JT11: =COUNTIF(IN11:JR11,"ป") -> 0 | JU11: =COUNTIF(IN11:JR11,"ล") -> 0 | JV11: =COUNTIF(IN11:JR11,"ข") -> 0 | LB11: =$LB$4-(LC11+LD11+LE11) -> 22 | LC11: =COUNTIF(JW11:LA11,"ป") -> 0 | LD11: =COUNTIF(JW11:LA11,"ล") -> 0 | LE11: =COUNTIF(JW11:LA11,"ข") -> 0 | MK11: =$MK$4-(ML11+MM11+MN11) -> 20 | ML11: =COUNTIF(LF11:MJ11,"ป") -> 0 | MM11: =COUNTIF(LF11:MJ11,"ล") -> 0 | MN11: =COUNTIF(LF11:MJ11,"ข") -> 0 | NT11: =$NT$4-(NU11+NV11+NW11) -> 20 | NU11: =COUNTIF(MO11:NS11,"ป") -> 0 | NV11: =COUNTIF(MO11:NS11,"ล") -> 0 | NW11: =COUNTIF(MO11:NS11,"ข") -> 0 | PC11: =$PC$4-(PD11+PE11+PF11) -> 0 | PD11: =COUNTIF(NX11:PB11,"ป") -> 0 | PE11: =COUNTIF(NX11:PB11,"ล") -> 0 | PF11: =COUNTIF(NX11:PB11,"ข") -> 0 | PG11: =AH11 -> 10 | PH11: =BQ11 -> 19 | PI11: =CZ11 -> 21 | PJ11: =EI11 -> 21 | PK11: =FR11 -> 21 | PL11: =HA11 -> 6 | PM11: =IJ11 -> 21 | PN11: =JS11 -> 18 | PO11: =LB11 -> 22 | PP11: =MK11 -> 20 | PQ11: =NT11 -> 20 | PR11: =PC11 -> 0 | PS11: =SUM(PC11:PR11) -> 199 | PT11: =PS11*100/$PS$4 -> 99.5
A12: 7 | B12: ='ข้อมูลนร.2-3'!D10 -> เด็กหญิงกมลรัตน์ แสดคง | AH12: =$AH$4-(AI12+AJ12+AK12) -> 11 | AI12: =COUNTIF(C12:AG12,"ป") -> 0 | AJ12: =COUNTIF(C12:AG12,"ล") -> 0 | AK12: =COUNTIF(C12:AG12,"ข") -> 0 | AY12: ล | BQ12: =$BQ$4-(BR12+BS12+BT12) -> 18 | BR12: =COUNTIF(AL12:BP12,"ป") -> 0 | BS12: =COUNTIF(AL12:BP12,"ล") -> 1 | CZ12: =$CZ$4-(DA12+DB12+DC12) -> 21 | DA12: =COUNTIF(BU12:CY12,"ป") -> 0 | DB12: =COUNTIF(BU12:CY12,"ล") -> 0 | DC12: =COUNTIF(BU12:CY12,"ข") -> 0 | EI12: =$EI$4-(EJ12+EK12+EL12) -> 21 | EJ12: =COUNTIF(DD12:EH12,"ป") -> 0 | EK12: =COUNTIF(DD12:EH12,"ล") -> 0 | EL12: =COUNTIF(DD12:EH12,"ข") -> 0 | FR12: =$FR$4-(FS12+FT12+FU12) -> 21 | FS12: =COUNTIF(EM12:FQ12,"ป") -> 0 | FT12: =COUNTIF(EM12:FQ12,"ล") -> 0 | FU12: =COUNTIF(EM12:FQ12,"ข") -> 0 | HA12: =$HA$4-(HB12+HC12+HD12) -> 6 | HB12: =COUNTIF(FV12:GZ12,"ป") -> 0 | HC12: =COUNTIF(FV12:GZ12,"ล") -> 0 | HD12: =COUNTIF(FV12:GZ12,"ข") -> 0 | IJ12: =$IJ$4-(IK12+IL12+IM12) -> 21 | IK12: =COUNTIF(HE12:II12,"ป") -> 0 | IL12: =COUNTIF(HE12:II12,"ล") -> 0 | IM12: =COUNTIF(HE12:II12,"ข") -> 0 | JS12: =$JS$4-(JT12+JU12+JV12) -> 18 | JT12: =COUNTIF(IN12:JR12,"ป") -> 0 | JU12: =COUNTIF(IN12:JR12,"ล") -> 0 | JV12: =COUNTIF(IN12:JR12,"ข") -> 0 | LB12: =$LB$4-(LC12+LD12+LE12) -> 22 | LC12: =COUNTIF(JW12:LA12,"ป") -> 0 | LD12: =COUNTIF(JW12:LA12,"ล") -> 0 | LE12: =COUNTIF(JW12:LA12,"ข") -> 0 | MK12: =$MK$4-(ML12+MM12+MN12) -> 20 | ML12: =COUNTIF(LF12:MJ12,"ป") -> 0 | MM12: =COUNTIF(LF12:MJ12,"ล") -> 0 | MN12: =COUNTIF(LF12:MJ12,"ข") -> 0 | NT12: =$NT$4-(NU12+NV12+NW12) -> 20 | NU12: =COUNTIF(MO12:NS12,"ป") -> 0 | NV12: =COUNTIF(MO12:NS12,"ล") -> 0 | NW12: =COUNTIF(MO12:NS12,"ข") -> 0 | PC12: =$PC$4-(PD12+PE12+PF12) -> 0 | PD12: =COUNTIF(NX12:PB12,"ป") -> 0 | PE12: =COUNTIF(NX12:PB12,"ล") -> 0 | PF12: =COUNTIF(NX12:PB12,"ข") -> 0 | PG12: =AH12 -> 11 | PH12: =BQ12 -> 18 | PI12: =CZ12 -> 21 | PJ12: =EI12 -> 21 | PK12: =FR12 -> 21 | PL12: =HA12 -> 6 | PM12: =IJ12 -> 21 | PN12: =JS12 -> 18 | PO12: =LB12 -> 22 | PP12: =MK12 -> 20 | PQ12: =NT12 -> 20 | PR12: =PC12 -> 0 | PS12: =SUM(PC12:PR12) -> 199 | PT12: =PS12*100/$PS$4 -> 99.5
A13: 8 | B13: ='ข้อมูลนร.2-3'!D11 -> เด็กหญิงกัลยรัตน์ ทึงสุข | AB13: ล | AH13: =$AH$4-(AI13+AJ13+AK13) -> 10 | AI13: =COUNTIF(C13:AG13,"ป") -> 0 | AJ13: =COUNTIF(C13:AG13,"ล") -> 1 | AK13: =COUNTIF(C13:AG13,"ข") -> 0 | BQ13: =$BQ$4-(BR13+BS13+BT13) -> 19 | BR13: =COUNTIF(AL13:BP13,"ป") -> 0 | BS13: =COUNTIF(AL13:BP13,"ล") -> 0 | CZ13: =$CZ$4-(DA13+DB13+DC13) -> 21 | DA13: =COUNTIF(BU13:CY13,"ป") -> 0 | DB13: =COUNTIF(BU13:CY13,"ล") -> 0 | DC13: =COUNTIF(BU13:CY13,"ข") -> 0 | EI13: =$EI$4-(EJ13+EK13+EL13) -> 21 | EJ13: =COUNTIF(DD13:EH13,"ป") -> 0 | EK13: =COUNTIF(DD13:EH13,"ล") -> 0 | EL13: =COUNTIF(DD13:EH13,"ข") -> 0 | FR13: =$FR$4-(FS13+FT13+FU13) -> 21 | FS13: =COUNTIF(EM13:FQ13,"ป") -> 0 | FT13: =COUNTIF(EM13:FQ13,"ล") -> 0 | FU13: =COUNTIF(EM13:FQ13,"ข") -> 0 | HA13: =$HA$4-(HB13+HC13+HD13) -> 6 | HB13: =COUNTIF(FV13:GZ13,"ป") -> 0 | HC13: =COUNTIF(FV13:GZ13,"ล") -> 0 | HD13: =COUNTIF(FV13:GZ13,"ข") -> 0 | IJ13: =$IJ$4-(IK13+IL13+IM13) -> 21 | IK13: =COUNTIF(HE13:II13,"ป") -> 0 | IL13: =COUNTIF(HE13:II13,"ล") -> 0 | IM13: =COUNTIF(HE13:II13,"ข") -> 0 | JS13: =$JS$4-(JT13+JU13+JV13) -> 18 | JT13: =COUNTIF(IN13:JR13,"ป") -> 0 | JU13: =COUNTIF(IN13:JR13,"ล") -> 0 | JV13: =COUNTIF(IN13:JR13,"ข") -> 0 | LB13: =$LB$4-(LC13+LD13+LE13) -> 22 | LC13: =COUNTIF(JW13:LA13,"ป") -> 0 | LD13: =COUNTIF(JW13:LA13,"ล") -> 0 | LE13: =COUNTIF(JW13:LA13,"ข") -> 0 | MK13: =$MK$4-(ML13+MM13+MN13) -> 20 | ML13: =COUNTIF(LF13:MJ13,"ป") -> 0 | MM13: =COUNTIF(LF13:MJ13,"ล") -> 0 | MN13: =COUNTIF(LF13:MJ13,"ข") -> 0 | NT13: =$NT$4-(NU13+NV13+NW13) -> 20 | NU13: =COUNTIF(MO13:NS13,"ป") -> 0 | NV13: =COUNTIF(MO13:NS13,"ล") -> 0 | NW13: =COUNTIF(MO13:NS13,"ข") -> 0 | PC13: =$PC$4-(PD13+PE13+PF13) -> 0 | PD13: =COUNTIF(NX13:PB13,"ป") -> 0 | PE13: =COUNTIF(NX13:PB13,"ล") -> 0 | PF13: =COUNTIF(NX13:PB13,"ข") -> 0 | PG13: =AH13 -> 10 | PH13: =BQ13 -> 19 | PI13: =CZ13 -> 21 | PJ13: =EI13 -> 21 | PK13: =FR13 -> 21 | PL13: =HA13 -> 6 | PM13: =IJ13 -> 21 | PN13: =JS13 -> 18 | PO13: =LB13 -> 22 | PP13: =MK13 -> 20 | PQ13: =NT13 -> 20 | PR13: =PC13 -> 0 | PS13: =SUM(PC13:PR13) -> 199 | PT13: =PS13*100/$PS$4 -> 99.5
A14: 9 | B14: ='ข้อมูลนร.2-3'!D12 -> เด็กหญิงนิตยา พละโท | AH14: =$AH$4-(AI14+AJ14+AK14) -> 11 | AI14: =COUNTIF(C14:AG14,"ป") -> 0 | AJ14: =COUNTIF(C14:AG14,"ล") -> 0 | AK14: =COUNTIF(C14:AG14,"ข") -> 0 | BK14: ล | BQ14: =$BQ$4-(BR14+BS14+BT14) -> 18 | BR14: =COUNTIF(AL14:BP14,"ป") -> 0 | BS14: =COUNTIF(AL14:BP14,"ล") -> 1 | CZ14: =$CZ$4-(DA14+DB14+DC14) -> 21 | DA14: =COUNTIF(BU14:CY14,"ป") -> 0 | DB14: =COUNTIF(BU14:CY14,"ล") -> 0 | DC14: =COUNTIF(BU14:CY14,"ข") -> 0 | EI14: =$EI$4-(EJ14+EK14+EL14) -> 21 | EJ14: =COUNTIF(DD14:EH14,"ป") -> 0 | EK14: =COUNTIF(DD14:EH14,"ล") -> 0 | EL14: =COUNTIF(DD14:EH14,"ข") -> 0 | FR14: =$FR$4-(FS14+FT14+FU14) -> 21 | FS14: =COUNTIF(EM14:FQ14,"ป") -> 0 | FT14: =COUNTIF(EM14:FQ14,"ล") -> 0 | FU14: =COUNTIF(EM14:FQ14,"ข") -> 0 | HA14: =$HA$4-(HB14+HC14+HD14) -> 6 | HB14: =COUNTIF(FV14:GZ14,"ป") -> 0 | HC14: =COUNTIF(FV14:GZ14,"ล") -> 0 | HD14: =COUNTIF(FV14:GZ14,"ข") -> 0 | IJ14: =$IJ$4-(IK14+IL14+IM14) -> 21 | IK14: =COUNTIF(HE14:II14,"ป") -> 0 | IL14: =COUNTIF(HE14:II14,"ล") -> 0 | IM14: =COUNTIF(HE14:II14,"ข") -> 0 | JS14: =$JS$4-(JT14+JU14+JV14) -> 18 | JT14: =COUNTIF(IN14:JR14,"ป") -> 0 | JU14: =COUNTIF(IN14:JR14,"ล") -> 0 | JV14: =COUNTIF(IN14:JR14,"ข") -> 0 | LB14: =$LB$4-(LC14+LD14+LE14) -> 22 | LC14: =COUNTIF(JW14:LA14,"ป") -> 0 | LD14: =COUNTIF(JW14:LA14,"ล") -> 0 | LE14: =COUNTIF(JW14:LA14,"ข") -> 0 | MK14: =$MK$4-(ML14+MM14+MN14) -> 20 | ML14: =COUNTIF(LF14:MJ14,"ป") -> 0 | MM14: =COUNTIF(LF14:MJ14,"ล") -> 0 | MN14: =COUNTIF(LF14:MJ14,"ข") -> 0 | NT14: =$NT$4-(NU14+NV14+NW14) -> 20 | NU14: =COUNTIF(MO14:NS14,"ป") -> 0 | NV14: =COUNTIF(MO14:NS14,"ล") -> 0 | NW14: =COUNTIF(MO14:NS14,"ข") -> 0 | PC14: =$PC$4-(PD14+PE14+PF14) -> 0 | PD14: =COUNTIF(NX14:PB14,"ป") -> 0 | PE14: =COUNTIF(NX14:PB14,"ล") -> 0 | PF14: =COUNTIF(NX14:PB14,"ข") -> 0 | PG14: =AH14 -> 11 | PH14: =BQ14 -> 18 | PI14: =CZ14 -> 21 | PJ14: =EI14 -> 21 | PK14: =FR14 -> 21 | PL14: =HA14 -> 6 | PM14: =IJ14 -> 21 | PN14: =JS14 -> 18 | PO14: =LB14 -> 22 | PP14: =MK14 -> 20 | PQ14: =NT14 -> 20 | PR14: =PC14 -> 0 | PS14: =SUM(PC14:PR14) -> 199 | PT14: =PS14*100/$PS$4 -> 99.5
A15: 10 | B15: ='ข้อมูลนร.2-3'!D13 -> เด็กหญิงบัณฑิตา เบ้าพงษ์ | AH15: =$AH$4-(AI15+AJ15+AK15) -> 11 | AI15: =COUNTIF(C15:AG15,"ป") -> 0 | AJ15: =COUNTIF(C15:AG15,"ล") -> 0 | AK15: =COUNTIF(C15:AG15,"ข") -> 0 | BQ15: =$BQ$4-(BR15+BS15+BT15) -> 19 | BR15: =COUNTIF(AL15:BP15,"ป") -> 0 | BS15: =COUNTIF(AL15:BP15,"ล") -> 0 | CZ15: =$CZ$4-(DA15+DB15+DC15) -> 21 | DA15: =COUNTIF(BU15:CY15,"ป") -> 0 | DB15: =COUNTIF(BU15:CY15,"ล") -> 0 | DC15: =COUNTIF(BU15:CY15,"ข") -> 0 | EI15: =$EI$4-(EJ15+EK15+EL15) -> 21 | EJ15: =COUNTIF(DD15:EH15,"ป") -> 0 | EK15: =COUNTIF(DD15:EH15,"ล") -> 0 | EL15: =COUNTIF(DD15:EH15,"ข") -> 0 | FR15: =$FR$4-(FS15+FT15+FU15) -> 21 | FS15: =COUNTIF(EM15:FQ15,"ป") -> 0 | FT15: =COUNTIF(EM15:FQ15,"ล") -> 0 | FU15: =COUNTIF(EM15:FQ15,"ข") -> 0 | HA15: =$HA$4-(HB15+HC15+HD15) -> 6 | HB15: =COUNTIF(FV15:GZ15,"ป") -> 0 | HC15: =COUNTIF(FV15:GZ15,"ล") -> 0 | HD15: =COUNTIF(FV15:GZ15,"ข") -> 0 | IJ15: =$IJ$4-(IK15+IL15+IM15) -> 21 | IK15: =COUNTIF(HE15:II15,"ป") -> 0 | IL15: =COUNTIF(HE15:II15,"ล") -> 0 | IM15: =COUNTIF(HE15:II15,"ข") -> 0 | JS15: =$JS$4-(JT15+JU15+JV15) -> 18 | JT15: =COUNTIF(IN15:JR15,"ป") -> 0 | JU15: =COUNTIF(IN15:JR15,"ล") -> 0 | JV15: =COUNTIF(IN15:JR15,"ข") -> 0 | LB15: =$LB$4-(LC15+LD15+LE15) -> 22 | LC15: =COUNTIF(JW15:LA15,"ป") -> 0 | LD15: =COUNTIF(JW15:LA15,"ล") -> 0 | LE15: =COUNTIF(JW15:LA15,"ข") -> 0 | MK15: =$MK$4-(ML15+MM15+MN15) -> 20 | ML15: =COUNTIF(LF15:MJ15,"ป") -> 0 | MM15: =COUNTIF(LF15:MJ15,"ล") -> 0 | MN15: =COUNTIF(LF15:MJ15,"ข") -> 0 | NT15: =$NT$4-(NU15+NV15+NW15) -> 20 | NU15: =COUNTIF(MO15:NS15,"ป") -> 0 | NV15: =COUNTIF(MO15:NS15,"ล") -> 0 | NW15: =COUNTIF(MO15:NS15,"ข") -> 0 | PC15: =$PC$4-(PD15+PE15+PF15) -> 0 | PD15: =COUNTIF(NX15:PB15,"ป") -> 0 | PE15: =COUNTIF(NX15:PB15,"ล") -> 0 | PF15: =COUNTIF(NX15:PB15,"ข") -> 0 | PG15: =AH15 -> 11 | PH15: =BQ15 -> 19 | PI15: =CZ15 -> 21 | PJ15: =EI15 -> 21 | PK15: =FR15 -> 21 | PL15: =HA15 -> 6 | PM15: =IJ15 -> 21 | PN15: =JS15 -> 18 | PO15: =LB15 -> 22 | PP15: =MK15 -> 20 | PQ15: =NT15 -> 20 | PR15: =PC15 -> 0 | PS15: =SUM(PC15:PR15) -> 200 | PT15: =PS15*100/$PS$4 -> 100
A16: 11 | B16: ='ข้อมูลนร.2-3'!D14 -> เด็กหญิงพัชรกัญญ์ บาลนาคม | AH16: =$AH$4-(AI16+AJ16+AK16) -> 11 | AI16: =COUNTIF(C16:AG16,"ป") -> 0 | AJ16: =COUNTIF(C16:AG16,"ล") -> 0 | AK16: =COUNTIF(C16:AG16,"ข") -> 0 | BQ16: =$BQ$4-(BR16+BS16+BT16) -> 19 | BR16: =COUNTIF(AL16:BP16,"ป") -> 0 | BS16: =COUNTIF(AL16:BP16,"ล") -> 0 | CZ16: =$CZ$4-(DA16+DB16+DC16) -> 21 | DA16: =COUNTIF(BU16:CY16,"ป") -> 0 | DB16: =COUNTIF(BU16:CY16,"ล") -> 0 | DC16: =COUNTIF(BU16:CY16,"ข") -> 0 | EI16: =$EI$4-(EJ16+EK16+EL16) -> 21 | EJ16: =COUNTIF(DD16:EH16,"ป") -> 0 | EK16: =COUNTIF(DD16:EH16,"ล") -> 0 | EL16: =COUNTIF(DD16:EH16,"ข") -> 0 | FR16: =$FR$4-(FS16+FT16+FU16) -> 21 | FS16: =COUNTIF(EM16:FQ16,"ป") -> 0 | FT16: =COUNTIF(EM16:FQ16,"ล") -> 0 | FU16: =COUNTIF(EM16:FQ16,"ข") -> 0 | HA16: =$HA$4-(HB16+HC16+HD16) -> 6 | HB16: =COUNTIF(FV16:GZ16,"ป") -> 0 | HC16: =COUNTIF(FV16:GZ16,"ล") -> 0 | HD16: =COUNTIF(FV16:GZ16,"ข") -> 0 | IJ16: =$IJ$4-(IK16+IL16+IM16) -> 21 | IK16: =COUNTIF(HE16:II16,"ป") -> 0 | IL16: =COUNTIF(HE16:II16,"ล") -> 0 | IM16: =COUNTIF(HE16:II16,"ข") -> 0 | JS16: =$JS$4-(JT16+JU16+JV16) -> 18 | JT16: =COUNTIF(IN16:JR16,"ป") -> 0 | JU16: =COUNTIF(IN16:JR16,"ล") -> 0 | JV16: =COUNTIF(IN16:JR16,"ข") -> 0 | LB16: =$LB$4-(LC16+LD16+LE16) -> 22 | LC16: =COUNTIF(JW16:LA16,"ป") -> 0 | LD16: =COUNTIF(JW16:LA16,"ล") -> 0 | LE16: =COUNTIF(JW16:LA16,"ข") -> 0 | MK16: =$MK$4-(ML16+MM16+MN16) -> 20 | ML16: =COUNTIF(LF16:MJ16,"ป") -> 0 | MM16: =COUNTIF(LF16:MJ16,"ล") -> 0 | MN16: =COUNTIF(LF16:MJ16,"ข") -> 0 | NT16: =$NT$4-(NU16+NV16+NW16) -> 20 | NU16: =COUNTIF(MO16:NS16,"ป") -> 0 | NV16: =COUNTIF(MO16:NS16,"ล") -> 0 | NW16: =COUNTIF(MO16:NS16,"ข") -> 0 | PC16: =$PC$4-(PD16+PE16+PF16) -> 0 | PD16: =COUNTIF(NX16:PB16,"ป") -> 0 | PE16: =COUNTIF(NX16:PB16,"ล") -> 0 | PF16: =COUNTIF(NX16:PB16,"ข") -> 0 | PG16: =AH16 -> 11 | PH16: =BQ16 -> 19 | PI16: =CZ16 -> 21 | PJ16: =EI16 -> 21 | PK16: =FR16 -> 21 | PL16: =HA16 -> 6 | PM16: =IJ16 -> 21 | PN16: =JS16 -> 18 | PO16: =LB16 -> 22 | PP16: =MK16 -> 20 | PQ16: =NT16 -> 20 | PR16: =PC16 -> 0 | PS16: =SUM(PC16:PR16) -> 200 | PT16: =PS16*100/$PS$4 -> 100
A17: 12 | B17: ='ข้อมูลนร.2-3'!D15 -> เด็กหญิงสุวิชาดา ชูจิตร | AH17: =$AH$4-(AI17+AJ17+AK17) -> 11 | AI17: =COUNTIF(C17:AG17,"ป") -> 0 | AJ17: =COUNTIF(C17:AG17,"ล") -> 0 | AK17: =COUNTIF(C17:AG17,"ข") -> 0 | BQ17: =$BQ$4-(BR17+BS17+BT17) -> 19 | BR17: =COUNTIF(AL17:BP17,"ป") -> 0 | BS17: =COUNTIF(AL17:BP17,"ล") -> 0 | CZ17: =$CZ$4-(DA17+DB17+DC17) -> 21 | DA17: =COUNTIF(BU17:CY17,"ป") -> 0 | DB17: =COUNTIF(BU17:CY17,"ล") -> 0 | DC17: =COUNTIF(BU17:CY17,"ข") -> 0 | EI17: =$EI$4-(EJ17+EK17+EL17) -> 21 | EJ17: =COUNTIF(DD17:EH17,"ป") -> 0 | EK17: =COUNTIF(DD17:EH17,"ล") -> 0 | EL17: =COUNTIF(DD17:EH17,"ข") -> 0 | FR17: =$FR$4-(FS17+FT17+FU17) -> 21 | FS17: =COUNTIF(EM17:FQ17,"ป") -> 0 | FT17: =COUNTIF(EM17:FQ17,"ล") -> 0 | FU17: =COUNTIF(EM17:FQ17,"ข") -> 0 | HA17: =$HA$4-(HB17+HC17+HD17) -> 6 | HB17: =COUNTIF(FV17:GZ17,"ป") -> 0 | HC17: =COUNTIF(FV17:GZ17,"ล") -> 0 | HD17: =COUNTIF(FV17:GZ17,"ข") -> 0 | IJ17: =$IJ$4-(IK17+IL17+IM17) -> 21 | IK17: =COUNTIF(HE17:II17,"ป") -> 0 | IL17: =COUNTIF(HE17:II17,"ล") -> 0 | IM17: =COUNTIF(HE17:II17,"ข") -> 0 | JS17: =$JS$4-(JT17+JU17+JV17) -> 18 | JT17: =COUNTIF(IN17:JR17,"ป") -> 0 | JU17: =COUNTIF(IN17:JR17,"ล") -> 0 | JV17: =COUNTIF(IN17:JR17,"ข") -> 0 | LB17: =$LB$4-(LC17+LD17+LE17) -> 22 | LC17: =COUNTIF(JW17:LA17,"ป") -> 0 | LD17: =COUNTIF(JW17:LA17,"ล") -> 0 | LE17: =COUNTIF(JW17:LA17,"ข") -> 0 | MK17: =$MK$4-(ML17+MM17+MN17) -> 20 | ML17: =COUNTIF(LF17:MJ17,"ป") -> 0 | MM17: =COUNTIF(LF17:MJ17,"ล") -> 0 | MN17: =COUNTIF(LF17:MJ17,"ข") -> 0 | NT17: =$NT$4-(NU17+NV17+NW17) -> 20 | NU17: =COUNTIF(MO17:NS17,"ป") -> 0 | NV17: =COUNTIF(MO17:NS17,"ล") -> 0 | NW17: =COUNTIF(MO17:NS17,"ข") -> 0 | PC17: =$PC$4-(PD17+PE17+PF17) -> 0 | PD17: =COUNTIF(NX17:PB17,"ป") -> 0 | PE17: =COUNTIF(NX17:PB17,"ล") -> 0 | PF17: =COUNTIF(NX17:PB17,"ข") -> 0 | PG17: =AH17 -> 11 | PH17: =BQ17 -> 19 | PI17: =CZ17 -> 21 | PJ17: =EI17 -> 21 | PK17: =FR17 -> 21 | PL17: =HA17 -> 6 | PM17: =IJ17 -> 21 | PN17: =JS17 -> 18 | PO17: =LB17 -> 22 | PP17: =MK17 -> 20 | PQ17: =NT17 -> 20 | PR17: =PC17 -> 0 | PS17: =SUM(PC17:PR17) -> 200 | PT17: =PS17*100/$PS$4 -> 100
A18: 13 | B18: ='ข้อมูลนร.2-3'!D16 -> เด็กหญิงปุญญิศา อุปทุม | W18: ล | AH18: =$AH$4-(AI18+AJ18+AK18) -> 10 | AI18: =COUNTIF(C18:AG18,"ป") -> 0 | AJ18: =COUNTIF(C18:AG18,"ล") -> 1 | AK18: =COUNTIF(C18:AG18,"ข") -> 0 | BQ18: =$BQ$4-(BR18+BS18+BT18) -> 19 | BR18: =COUNTIF(AL18:BP18,"ป") -> 0 | BS18: =COUNTIF(AL18:BP18,"ล") -> 0 | CZ18: =$CZ$4-(DA18+DB18+DC18) -> 21 | DA18: =COUNTIF(BU18:CY18,"ป") -> 0 | DB18: =COUNTIF(BU18:CY18,"ล") -> 0 | DC18: =COUNTIF(BU18:CY18,"ข") -> 0 | EI18: =$EI$4-(EJ18+EK18+EL18) -> 21 | EJ18: =COUNTIF(DD18:EH18,"ป") -> 0 | EK18: =COUNTIF(DD18:EH18,"ล") -> 0 | EL18: =COUNTIF(DD18:EH18,"ข") -> 0 | FR18: =$FR$4-(FS18+FT18+FU18) -> 21 | FS18: =COUNTIF(EM18:FQ18,"ป") -> 0 | FT18: =COUNTIF(EM18:FQ18,"ล") -> 0 | FU18: =COUNTIF(EM18:FQ18,"ข") -> 0 | HA18: =$HA$4-(HB18+HC18+HD18) -> 6 | HB18: =COUNTIF(FV18:GZ18,"ป") -> 0 | HC18: =COUNTIF(FV18:GZ18,"ล") -> 0 | HD18: =COUNTIF(FV18:GZ18,"ข") -> 0 | IJ18: =$IJ$4-(IK18+IL18+IM18) -> 21 | IK18: =COUNTIF(HE18:II18,"ป") -> 0 | IL18: =COUNTIF(HE18:II18,"ล") -> 0 | IM18: =COUNTIF(HE18:II18,"ข") -> 0 | JS18: =$JS$4-(JT18+JU18+JV18) -> 18 | JT18: =COUNTIF(IN18:JR18,"ป") -> 0 | JU18: =COUNTIF(IN18:JR18,"ล") -> 0 | JV18: =COUNTIF(IN18:JR18,"ข") -> 0 | LB18: =$LB$4-(LC18+LD18+LE18) -> 22 | LC18: =COUNTIF(JW18:LA18,"ป") -> 0 | LD18: =COUNTIF(JW18:LA18,"ล") -> 0 | LE18: =COUNTIF(JW18:LA18,"ข") -> 0 | MK18: =$MK$4-(ML18+MM18+MN18) -> 20 | ML18: =COUNTIF(LF18:MJ18,"ป") -> 0 | MM18: =COUNTIF(LF18:MJ18,"ล") -> 0 | MN18: =COUNTIF(LF18:MJ18,"ข") -> 0 | NT18: =$NT$4-(NU18+NV18+NW18) -> 20 | NU18: =COUNTIF(MO18:NS18,"ป") -> 0 | NV18: =COUNTIF(MO18:NS18,"ล") -> 0 | NW18: =COUNTIF(MO18:NS18,"ข") -> 0 | PC18: =$PC$4-(PD18+PE18+PF18) -> 0 | PD18: =COUNTIF(NX18:PB18,"ป") -> 0 | PE18: =COUNTIF(NX18:PB18,"ล") -> 0 | PF18: =COUNTIF(NX18:PB18,"ข") -> 0 | PG18: =AH18 -> 10 | PH18: =BQ18 -> 19 | PI18: =CZ18 -> 21 | PJ18: =EI18 -> 21 | PK18: =FR18 -> 21 | PL18: =HA18 -> 6 | PM18: =IJ18 -> 21 | PN18: =JS18 -> 18 | PO18: =LB18 -> 22 | PP18: =MK18 -> 20 | PQ18: =NT18 -> 20 | PR18: =PC18 -> 0 | PS18: =SUM(PC18:PR18) -> 199 | PT18: =PS18*100/$PS$4 -> 99.5
A19: 15
A20: 16
A21: 17
A22: 18
A23: 19
A24: 20
A25: 21
A26: 22
A27: 23
A28: 24 | CZ28: =$CZ$4-(DA28+DB28+DC28) -> 21 | DA28: =COUNTIF(BU28:CY28,"ป") -> 0 | DB28: =COUNTIF(BU28:CY28,"ล") -> 0 | DC28: =COUNTIF(BU28:CY28,"ข") -> 0 | EI28: =$EI$4-(EJ28+EK28+EL28) -> 21 | EJ28: =COUNTIF(DD28:EH28,"ป") -> 0 | EK28: =COUNTIF(DD28:EH28,"ล") -> 0 | EL28: =COUNTIF(DD28:EH28,"ข") -> 0
A29: 25 | CZ29: =$CZ$4-(DA29+DB29+DC29) -> 21 | DA29: =COUNTIF(BU29:CY29,"ป") -> 0 | DB29: =COUNTIF(BU29:CY29,"ล") -> 0 | DC29: =COUNTIF(BU29:CY29,"ข") -> 0 | EI29: =$EI$4-(EJ29+EK29+EL29) -> 21 | EJ29: =COUNTIF(DD29:EH29,"ป") -> 0 | EK29: =COUNTIF(DD29:EH29,"ล") -> 0 | EL29: =COUNTIF(DD29:EH29,"ข") -> 0
A30: 26 | CZ30: =$CZ$4-(DA30+DB30+DC30) -> 21 | DA30: =COUNTIF(BU30:CY30,"ป") -> 0 | DB30: =COUNTIF(BU30:CY30,"ล") -> 0 | DC30: =COUNTIF(BU30:CY30,"ข") -> 0 | EI30: =$EI$4-(EJ30+EK30+EL30) -> 21 | EJ30: =COUNTIF(DD30:EH30,"ป") -> 0 | EK30: =COUNTIF(DD30:EH30,"ล") -> 0 | EL30: =COUNTIF(DD30:EH30,"ข") -> 0
A31: 27 | CZ31: =$CZ$4-(DA31+DB31+DC31) -> 21 | DA31: =COUNTIF(BU31:CY31,"ป") -> 0 | DB31: =COUNTIF(BU31:CY31,"ล") -> 0 | DC31: =COUNTIF(BU31:CY31,"ข") -> 0 | EI31: =$EI$4-(EJ31+EK31+EL31) -> 21 | EJ31: =COUNTIF(DD31:EH31,"ป") -> 0 | EK31: =COUNTIF(DD31:EH31,"ล") -> 0 | EL31: =COUNTIF(DD31:EH31,"ข") -> 0
A32: 28 | CZ32: =$CZ$4-(DA32+DB32+DC32) -> 21 | DA32: =COUNTIF(BU32:CY32,"ป") -> 0 | DB32: =COUNTIF(BU32:CY32,"ล") -> 0 | DC32: =COUNTIF(BU32:CY32,"ข") -> 0 | EI32: =$EI$4-(EJ32+EK32+EL32) -> 21 | EJ32: =COUNTIF(DD32:EH32,"ป") -> 0 | EK32: =COUNTIF(DD32:EH32,"ล") -> 0 | EL32: =COUNTIF(DD32:EH32,"ข") -> 0
A33: 29 | CZ33: =$CZ$4-(DA33+DB33+DC33) -> 21 | DA33: =COUNTIF(BU33:CY33,"ป") -> 0 | DB33: =COUNTIF(BU33:CY33,"ล") -> 0 | DC33: =COUNTIF(BU33:CY33,"ข") -> 0 | EI33: =$EI$4-(EJ33+EK33+EL33) -> 21 | EJ33: =COUNTIF(DD33:EH33,"ป") -> 0 | EK33: =COUNTIF(DD33:EH33,"ล") -> 0 | EL33: =COUNTIF(DD33:EH33,"ข") -> 0
A34: 30 | CZ34: =$CZ$4-(DA34+DB34+DC34) -> 21 | DA34: =COUNTIF(BU34:CY34,"ป") -> 0 | DB34: =COUNTIF(BU34:CY34,"ล") -> 0 | DC34: =COUNTIF(BU34:CY34,"ข") -> 0 | EI34: =$EI$4-(EJ34+EK34+EL34) -> 21 | EJ34: =COUNTIF(DD34:EH34,"ป") -> 0 | EK34: =COUNTIF(DD34:EH34,"ล") -> 0 | EL34: =COUNTIF(DD34:EH34,"ข") -> 0

Sheet ไทย17-20
O1: 21 | AD1: 22 | AL1: 23 | AU1: 24
A2: การวัดผลกลางปี | P2: การวัดผลปลายปี | AE2: ผลการประเมินการเรียนรู้ ปีการศึกษา 2567 | AM2: มาตรฐานและตัวชี้วัด /ผลการเรียนรู้
A3: รายวิชา ภาษาไทย (ท15101) | P3: =A3 -> รายวิชา ภาษาไทย (ท15101) | AE3: =A3 -> รายวิชา ภาษาไทย (ท15101) | AM3: รายวิชา คณิตศาสตร์ ค16101
A4: เลขที่ | B4: ชื่อ | C4: คะแนนผลการเรียนรู้ ภาคเรียนที่ 1 | N4: ปลายภาค 1 | O4: รวมคะแนน | P4: เลขที่ | Q4: ชื่อ | R4: คะแนนผลการเรียนรู้ ภาคเรียนที่ 2 | AC4: ปลายภาค2 | AD4: รวมคะแนน | AE4: เลขที่ | AF4: ชื่อ | AG4: คะแนนภาคเรียนที่ 1 | AH4: คะแนนภาคเรียนที่ 2 | AI4: รวมคะแนนทั้งปี | AJ4: ผลการเรียน | AK4: ผลการแก้ไข | AL4: หมายเหตุ
B5: หน่วยที่ | C5: 1 | D5: 2 | E5: 3 | F5: 4 | G5: 5 | M5: รวม | Q5: หน่วยที่ | R5: 6 | S5: 7 | T5: 8 | U5: 9 | V5: 10 | AB5: รวม | AM5: 1 | AN5: เปรียบเทียบ เรียงลำดับเศษส่วนและจำนวนคละ จากสถานการณ์ต่าง ๆ | AU5: ค 1.1 ป.6/1
B6: คะแนนเต็ม | C6: 30 | M6: =SUM(C6:L6) -> 30 | N6: 20 | O6: =SUM(M6:N6) -> 50 | Q6: คะแนนเต็ม | R6: 30 | AB6: 30 | AC6: 20 | AD6: =SUM(AB6:AC6) -> 50 | AF6: คะแนนเต็ม | AG6: 50 | AH6: 50 | AI6: 100 | AM6: 2 | AN6: เขียนอัตราส่วนแสดงการเปรียบเทียบปริมาณ 2 ปริมาณ จากข้อความหรือสถานการณ์ โดยที่ปริมาณแต่ละ | AU6: ค 1.1 ป.6/2
A7: 1 | B7: ='เวลาเรียน4-16'!B6 -> เด็กชายกฤษดา บัวศรี | C7: 25 | M7: =SUM(C7:L7) -> 25 | N7: 14 | O7: =SUM(M7:N7) -> 39 | P7: 1 | Q7: =B7 -> เด็กชายกฤษดา บัวศรี | R7: 25 | AB7: =SUM(R7:AA7) -> 25 | AC7: 16 | AD7: =SUM(AB7:AC7) -> 41 | AE7: 1 | AF7: ='เวลาเรียน4-16'!B6 -> เด็กชายกฤษดา บัวศรี | AG7: =O7 -> 39 | AH7: =AD7 -> 41 | AI7: =SUM(AG7:AH7) -> 80 | AJ7: =IF(AI7>79,4,IF(AI7>74,3.5,IF(AI7>69,3,IF(AI7>64,2.5,IF(AI7>59,2,IF(AI7>54,1.5,IF(AI7>49,1,IF(AI7<50,0)))))))) -> 4 | AN7: ปริมาณเป็นจำนวนนับ
A8: 2 | B8: ='เวลาเรียน4-16'!B7 -> เด็กชายจิรายุ ดอบุตร | C8: 22 | M8: =SUM(C8:L8) -> 22 | N8: 13 | O8: =SUM(M8:N8) -> 35 | P8: 2 | Q8: =B8 -> เด็กชายจิรายุ ดอบุตร | R8: 24 | AB8: =SUM(R8:AA8) -> 24 | AC8: 11 | AD8: =SUM(AB8:AC8) -> 35 | AE8: 2 | AF8: ='เวลาเรียน4-16'!B7 -> เด็กชายจิรายุ ดอบุตร | AG8: =O8 -> 35 | AH8: =AD8 -> 35 | AI8: =SUM(AG8:AH8) -> 70 | AJ8: =IF(AI8>79,4,IF(AI8>74,3.5,IF(AI8>69,3,IF(AI8>64,2.5,IF(AI8>59,2,IF(AI8>54,1.5,IF(AI8>49,1,IF(AI8<50,0)))))))) -> 3 | AM8: 3 | AN8: หาอัตราส่วนที่เท่ากับอัตราส่วนที่กำหนดให้ | AU8: ค 1.1 ป.6/3
A9: 3 | B9: ='เวลาเรียน4-16'!B8 -> เด็กชายจิรายุ เนตรสว่าง | C9: 24 | M9: =SUM(C9:L9) -> 24 | N9: 12 | O9: =SUM(M9:N9) -> 36 | P9: 3 | Q9: =B9 -> เด็กชายจิรายุ เนตรสว่าง | R9: 27 | AB9: =SUM(R9:AA9) -> 27 | AC9: 13 | AD9: =SUM(AB9:AC9) -> 40 | AE9: 3 | AF9: ='เวลาเรียน4-16'!B8 -> เด็กชายจิรายุ เนตรสว่าง | AG9: =O9 -> 36 | AH9: =AD9 -> 40 | AI9: =SUM(AG9:AH9) -> 76 | AJ9: =IF(AI9>79,4,IF(AI9>74,3.5,IF(AI9>69,3,IF(AI9>64,2.5,IF(AI9>59,2,IF(AI9>54,1.5,IF(AI9>49,1,IF(AI9<50,0)))))))) -> 3.5 | AM9: 4 | AN9: หา ห.ร.ม. ของจำนวนนับไม่เกิน 3 จำนวน | AU9: ค 1.1 ป.6/4
A10: 4 | B10: ='เวลาเรียน4-16'!B9 -> เด็กชายจีรภัทร คันธมาตย์ | C10: 24 | M10: =SUM(C10:L10) -> 24 | N10: 13 | O10: =SUM(M10:N10) -> 37 | P10: 4 | Q10: =B10 -> เด็กชายจีรภัทร คันธมาตย์ | R10: 25 | AB10: =SUM(R10:AA10) -> 25 | AC10: 13 | AD10: =SUM(AB10:AC10) -> 38 | AE10: 4 | AF10: ='เวลาเรียน4-16'!B9 -> เด็กชายจีรภัทร คันธมาตย์ | AG10: =O10 -> 37 | AH10: =AD10 -> 38 | AI10: =SUM(AG10:AH10) -> 75 | AJ10: =IF(AI10>79,4,IF(AI10>74,3.5,IF(AI10>69,3,IF(AI10>64,2.5,IF(AI10>59,2,IF(AI10>54,1.5,IF(AI10>49,1,IF(AI10<50,0)))))))) -> 3.5 | AM10: 5 | AN10: หา ค.ร.น. ของจำนวนนับไม่เกิน 3 จำนวน | AU10: ค 1.1 ป.6/5
A11: 5 | B11: ='เวลาเรียน4-16'!B10 -> เด็กชายปรวัฒน์ โพธิ์ศรี | C11: 23 | M11: =SUM(C11:L11) -> 23 | N11: 11 | O11: =SUM(M11:N11) -> 34 | P11: 5 | Q11: =B11 -> เด็กชายปรวัฒน์ โพธิ์ศรี | R11: 24 | AB11: =SUM(R11:AA11) -> 24 | AC11: 12 | AD11: =SUM(AB11:AC11) -> 36 | AE11: 5 | AF11: ='เวลาเรียน4-16'!B10 -> เด็กชายปรวัฒน์ โพธิ์ศรี | AG11: =O11 -> 34 | AH11: =AD11 -> 36 | AI11: =SUM(AG11:AH11) -> 70 | AJ11: =IF(AI11>79,4,IF(AI11>74,3.5,IF(AI11>69,3,IF(AI11>64,2.5,IF(AI11>59,2,IF(AI11>54,1.5,IF(AI11>49,1,IF(AI11<50,0)))))))) -> 3 | AM11: 6 | AN11: แสดงวิธีหาคำตอบของโจทย์ปัญหาโดยใช้ความรู้เกี่ยวกับ ห.ร.ม. และ ค.ร.น. | AU11: ค 1.1 ป.6/6
A12: 6 | B12: ='เวลาเรียน4-16'!B11 -> เด็กชายพีรภาพ วงคำใหญ่ | C12: 25 | M12: =SUM(C12:L12) -> 25 | N12: 14 | O12: =SUM(M12:N12) -> 39 | P12: 6 | Q12: =B12 -> เด็กชายพีรภาพ วงคำใหญ่ | R12: 27 | AB12: =SUM(R12:AA12) -> 27 | AC12: 18 | AD12: =SUM(AB12:AC12) -> 45 | AE12: 6 | AF12: ='เวลาเรียน4-16'!B11 -> เด็กชายพีรภาพ วงคำใหญ่ | AG12: =O12 -> 39 | AH12: =AD12 -> 45 | AI12: =SUM(AG12:AH12) -> 84 | AJ12: =IF(AI12>79,4,IF(AI12>74,3.5,IF(AI12>69,3,IF(AI12>64,2.5,IF(AI12>59,2,IF(AI12>54,1.5,IF(AI12>49,1,IF(AI12<50,0)))))))) -> 4 | AM12: 7 | AN12: หาผลลัพธ์ของการบวก ลบ คูณ หารระคนของเศษส่วนและจำนวนคละ | AU12: ค 1.1 ป.6/7
A13: 7 | B13: ='เวลาเรียน4-16'!B12 -> เด็กหญิงกมลรัตน์ แสดคง | C13: 26 | M13: =SUM(C13:L13) -> 26 | N13: 14 | O13: =SUM(M13:N13) -> 40 | P13: 7 | Q13: =B13 -> เด็กหญิงกมลรัตน์ แสดคง | R13: 27 | AB13: =SUM(R13:AA13) -> 27 | AC13: 15 | AD13: =SUM(AB13:AC13) -> 42 | AE13: 7 | AF13: ='เวลาเรียน4-16'!B12 -> เด็กหญิงกมลรัตน์ แสดคง | AG13: =O13 -> 40 | AH13: =AD13 -> 42 | AI13: =SUM(AG13:AH13) -> 82 | AJ13: =IF(AI13>79,4,IF(AI13>74,3.5,IF(AI13>69,3,IF(AI13>64,2.5,IF(AI13>59,2,IF(AI13>54,1.5,IF(AI13>49,1,IF(AI13<50,0)))))))) -> 4 | AM13: 8 | AN13: แสดงวิธีหาคำตอบของโจทย์ปัญหาเศษส่วนและจำนวนคละ 2 - 3 ขั้นตอน | AU13: ค 1.1 ป.6/8
A14: 8 | B14: ='เวลาเรียน4-16'!B13 -> เด็กหญิงกัลยรัตน์ ทึงสุข | C14: 27 | M14: =SUM(C14:L14) -> 27 | N14: 15 | O14: =SUM(M14:N14) -> 42 | P14: 8 | Q14: =B14 -> เด็กหญิงกัลยรัตน์ ทึงสุข | R14: 28 | AB14: =SUM(R14:AA14) -> 28 | AC14: 18 | AD14: =SUM(AB14:AC14) -> 46 | AE14: 8 | AF14: ='เวลาเรียน4-16'!B13 -> เด็กหญิงกัลยรัตน์ ทึงสุข | AG14: =O14 -> 42 | AH14: =AD14 -> 46 | AI14: =SUM(AG14:AH14) -> 88 | AJ14: =IF(AI14>79,4,IF(AI14>74,3.5,IF(AI14>69,3,IF(AI14>64,2.5,IF(AI14>59,2,IF(AI14>54,1.5,IF(AI14>49,1,IF(AI14<50,0)))))))) -> 4 | AM14: 9 | AN14: หาผลหารของทศนิยมที่ตัวหารและผลหารเป็นทศนิยมไม่เกิน 3 ตำแหน่ง | AU14: ค 1.1 ป.6/9
A15: 9 | B15: ='เวลาเรียน4-16'!B14 -> เด็กหญิงนิตยา พละโท | C15: 27 | M15: =SUM(C15:L15) -> 27 | N15: 15 | O15: =SUM(M15:N15) -> 42 | P15: 9 | Q15: =B15 -> เด็กหญิงนิตยา พละโท | R15: 27 | AB15: =SUM(R15:AA15) -> 27 | AC15: 14 | AD15: =SUM(AB15:AC15) -> 41 | AE15: 9 | AF15: ='เวลาเรียน4-16'!B14 -> เด็กหญิงนิตยา พละโท | AG15: =O15 -> 42 | AH15: =AD15 -> 41 | AI15: =SUM(AG15:AH15) -> 83 | AJ15: =IF(AI15>79,4,IF(AI15>74,3.5,IF(AI15>69,3,IF(AI15>64,2.5,IF(AI15>59,2,IF(AI15>54,1.5,IF(AI15>49,1,IF(AI15<50,0)))))))) -> 4 | AM15: 10 | AN15: แสดงวิธีหาคำตอบของโจทย์ปัญหาการบวก การลบ การคูณ การหารทศนิยม 3 ขั้นตอน | AU15: ค 1.1 ป.6/10
A16: 10 | B16: ='เวลาเรียน4-16'!B15 -> เด็กหญิงบัณฑิตา เบ้าพงษ์ | C16: 25 | M16: =SUM(C16:L16) -> 25 | N16: 13 | O16: =SUM(M16:N16) -> 38 | P16: 10 | Q16: =B16 -> เด็กหญิงบัณฑิตา เบ้าพงษ์ | R16: 25 | AB16: =SUM(R16:AA16) -> 25 | AC16: 14 | AD16: =SUM(AB16:AC16) -> 39 | AE16: 10 | AF16: ='เวลาเรียน4-16'!B15 -> เด็กหญิงบัณฑิตา เบ้าพงษ์ | AG16: =O16 -> 38 | AH16: =AD16 -> 39 | AI16: =SUM(AG16:AH16) -> 77 | AJ16: =IF(AI16>79,4,IF(AI16>74,3.5,IF(AI16>69,3,IF(AI16>64,2.5,IF(AI16>59,2,IF(AI16>54,1.5,IF(AI16>49,1,IF(AI16<50,0)))))))) -> 3.5 | AM16: 11 | AN16: แสดงวิธีหาคำตอบของโจทย์ปัญหาอัตราส่วน | AU16: ค 1.1 ป.6/11
A17: 11 | B17: ='เวลาเรียน4-16'!B16 -> เด็กหญิงพัชรกัญญ์ บาลนาคม | C17: 26 | M17: =SUM(C17:L17) -> 26 | N17: 13 | O17: =SUM(M17:N17) -> 39 | P17: 11 | Q17: =B17 -> เด็กหญิงพัชรกัญญ์ บาลนาคม | R17: 28 | AB17: =SUM(R17:AA17) -> 28 | AC17: 18 | AD17: =SUM(AB17:AC17) -> 46 | AE17: 11 | AF17: ='เวลาเรียน4-16'!B16 -> เด็กหญิงพัชรกัญญ์ บาลนาคม | AG17: =O17 -> 39 | AH17: =AD17 -> 46 | AI17: =SUM(AG17:AH17) -> 85 | AJ17: =IF(AI17>79,4,IF(AI17>74,3.5,IF(AI17>69,3,IF(AI17>64,2.5,IF(AI17>59,2,IF(AI17>54,1.5,IF(AI17>49,1,IF(AI17<50,0)))))))) -> 4 | AM17: 12 | AN17: แสดงวิธีหาคำตอบของโจทย์ปัญหาร้อยละ 2 - 3 ขั้นตอน | AU17: ค 1.1 ป.6/12
A18: 12 | B18: ='เวลาเรียน4-16'!B17 -> เด็กหญิงสุวิชาดา ชูจิตร | C18: 21 | M18: =SUM(C18:L18) -> 21 | N18: 13 | O18: =SUM(M18:N18) -> 34 | P18: 12 | Q18: =B18 -> เด็กหญิงสุวิชาดา ชูจิตร | R18: 25 | AB18: =SUM(R18:AA18) -> 25 | AC18: 11 | AD18: =SUM(AB18:AC18) -> 36 | AE18: 12 | AF18: ='เวลาเรียน4-16'!B17 -> เด็กหญิงสุวิชาดา ชูจิตร | AG18: =O18 -> 34 | AH18: =AD18 -> 36 | AI18: =SUM(AG18:AH18) -> 70 | AJ18: =IF(AI18>79,4,IF(AI18>74,3.5,IF(AI18>69,3,IF(AI18>64,2.5,IF(AI18>59,2,IF(AI18>54,1.5,IF(AI18>49,1,IF(AI18<50,0)))))))) -> 3 | AM18: 13 | AN18: แสดงวิธีคิดและหาคำตอบของปัญหาเกี่ยวกับแบบรูป | AU18: ค 1.2 ป.6/1
A19: 13 | B19: ='เวลาเรียน4-16'!B18 -> เด็กหญิงปุญญิศา อุปทุม | C19: 24 | M19: =SUM(C19:L19) -> 24 | N19: 14 | O19: =SUM(M19:N19) -> 38 | P19: 13 | Q19: =B19 -> เด็กหญิงปุญญิศา อุปทุม | R19: 28 | AB19: =SUM(R19:AA19) -> 28 | AC19: 18 | AD19: =SUM(AB19:AC19) -> 46 | AE19: 13 | AF19: ='เวลาเรียน4-16'!B18 -> เด็กหญิงปุญญิศา อุปทุม | AG19: =O19 -> 38 | AH19: =AD19 -> 46 | AI19: =SUM(AG19:AH19) -> 84 | AJ19: =IF(AI19>79,4,IF(AI19>74,3.5,IF(AI19>69,3,IF(AI19>64,2.5,IF(AI19>59,2,IF(AI19>54,1.5,IF(AI19>49,1,IF(AI19<50,0)))))))) -> 4 | AM19: 14 | AN19: แสดงวิธีหาคำตอบของโจทย์ปัญหาเกี่ยวกับปริมาตรของรูปเรขาคณิต สามมิติที่ประกอบด้วยทรงสี่เหลี่ยมมุมฉาก | AU19: ค 2.1 ป.6/1
AM20: 16 | AN20: แสดงวิธีหาคำตอบของโจทย์ปัญหาเกี่ยวกับ ความยาวรอบรูปและพื้นที่ของวงกลม | AU20: ค 2.1 ป.6/3
AM21: 17 | AN21: จำแนกรูปสามเหลี่ยมโดยพิจารณาจากสมบัติของรูป | AU21: ค 2.2 ป.6/1
AM22: 18 | AN22: สร้างรูปสามเหลี่ยมเมื่อกำหนดความยาวของด้านและขนาดของมุม | AU22: ค 2.2 ป.6/2
AM23: 19 | AN23: บอกลักษณะของรูปเรขาคณิตสามมิติชนิดต่าง ๆ | AU23: ค 2.2 ป.6/3
AM24: 20 | AN24: ระบุรูปเรขาคณิตสามมิติที่ประกอบจากรูปคลี่และระบุรูปคลี่ของรูปเรขาคณิตสามมิติ | AU24: ค 2.2 ป.6/4
AM25: 21 | AN25: ใช้ข้อมูลจากแผนภูมิรูปวงกลมในการหาคำตอบของโจทย์ปัญหา | AU25: ค 3.1 ป.6/1
AN26: เซนติเมตร กิโลเมตรและเมตร

Sheet คณิต21-24
O1: 21 | AD1: 22 | AL1: 23 | AU1: 24
A2: การวัดผลกลางปี | P2: การวัดผลปลายปี | AE2: ผลการประเมินการเรียนรู้ ปีการศึกษา 2567 | AM2: มาตรฐานและตัวชี้วัด /ผลการเรียนรู้
A3: รายวิชา คณิตศาสตร์ (ค16101) | P3: =A3 -> รายวิชา คณิตศาสตร์ (ค16101) | AE3: =A3 -> รายวิชา คณิตศาสตร์ (ค16101) | AM3: รายวิชา คณิตศาสตร์ ค16101
A4: เลขที่ | B4: ชื่อ | C4: คะแนนผลการเรียนรู้ ภาคเรียนที่ 1 | N4: ปลายภาค 1 | O4: รวมคะแนน | P4: เลขที่ | Q4: ชื่อ | R4: คะแนนผลการเรียนรู้ ภาคเรียนที่ 2 | AC4: ปลายภาค2 | AD4: รวมคะแนน | AE4: เลขที่ | AF4: ชื่อ | AG4: คะแนนภาคเรียนที่ 1 | AH4: คะแนนภาคเรียนที่ 2 | AI4: รวมคะแนนทั้งปี | AJ4: ผลการเรียน | AK4: ผลการแก้ไข | AL4: หมายเหตุ
B5: หน่วยที่ | C5: 1 | D5: 2 | E5: 3 | F5: 4 | G5: 5 | M5: รวม | Q5: หน่วยที่ | R5: 6 | S5: 7 | T5: 8 | U5: 9 | V5: 10 | AB5: รวม | AM5: 1 | AN5: เปรียบเทียบ เรียงลำดับเศษส่วนและจำนวนคละ จากสถานการณ์ต่าง ๆ | AU5: ค 1.1 ป.6/1
B6: คะแนนเต็ม | C6: 10 | D6: 10 | E6: 10 | M6: =SUM(C6:L6) -> 30 | N6: 20 | O6: =SUM(M6:N6) -> 50 | Q6: คะแนนเต็ม | R6: 10 | S6: 10 | T6: 10 | AB6: 30 | AC6: 20 | AD6: =SUM(AB6:AC6) -> 50 | AF6: คะแนนเต็ม | AG6: 50 | AH6: 50 | AI6: 100 | AM6: 2 | AN6: เขียนอัตราส่วนแสดงการเปรียบเทียบปริมาณ 2 ปริมาณ จากข้อความหรือสถานการณ์ โดยที่ปริมาณแต่ละ | AU6: ค 1.1 ป.6/2
A7: 1 | B7: ='เวลาเรียน4-16'!B6 -> เด็กชายกฤษดา บัวศรี | C7: 8 | D7: 9 | E7: 8 | M7: =SUM(C7:L7) -> 25 | N7: 16 | O7: =SUM(M7:N7) -> 41 | P7: 1 | Q7: =B7 -> เด็กชายกฤษดา บัวศรี | R7: 8 | S7: 10 | T7: 8 | AB7: =SUM(R7:AA7) -> 26 | AC7: 14 | AD7: =SUM(AB7:AC7) -> 40 | AE7: 1 | AF7: ='เวลาเรียน4-16'!B6 -> เด็กชายกฤษดา บัวศรี | AG7: =O7 -> 41 | AH7: =AD7 -> 40 | AI7: =SUM(AG7:AH7) -> 81 | AJ7: =IF(AI7>79,4,IF(AI7>74,3.5,IF(AI7>69,3,IF(AI7>64,2.5,IF(AI7>59,2,IF(AI7>54,1.5,IF(AI7>49,1,IF(AI7<50,0)))))))) -> 4 | AN7: ปริมาณเป็นจำนวนนับ
A8: 2 | B8: ='เวลาเรียน4-16'!B7 -> เด็กชายจิรายุ ดอบุตร | C8: 7 | D8: 8 | E8: 7 | M8: =SUM(C8:L8) -> 22 | N8: 15 | O8: =SUM(M8:N8) -> 37 | P8: 2 | Q8: =B8 -> เด็กชายจิรายุ ดอบุตร | R8: 7 | S8: 10 | T8: 8 | AB8: =SUM(R8:AA8) -> 25 | AC8: 15 | AD8: =SUM(AB8:AC8) -> 40 | AE8: 2 | AF8: ='เวลาเรียน4-16'!B7 -> เด็กชายจิรายุ ดอบุตร | AG8: =O8 -> 37 | AH8: =AD8 -> 40 | AI8: =SUM(AG8:AH8) -> 77 | AJ8: =IF(AI8>79,4,IF(AI8>74,3.5,IF(AI8>69,3,IF(AI8>64,2.5,IF(AI8>59,2,IF(AI8>54,1.5,IF(AI8>49,1,IF(AI8<50,0)))))))) -> 3.5 | AM8: 3 | AN8: หาอัตราส่วนที่เท่ากับอัตราส่วนที่กำหนดให้ | AU8: ค 1.1 ป.6/3
