Workbook

Sheet ปก (1)
A5: สมุดบันทึกผลการพัฒนาคุณภาพผู้เรียนรายวิชา (ปพ.5)
A6: โรงเรียนบ้านขัวก่าย อำเภอวานรนิวาส จังหวัดสกลนคร
A7: สังกัด สำนักงานเขตพื้นที่การศึกษาประถมศึกษาสกลนคร เขต 3
A8: สำนักงานคณะกรรมการการศึกษาขั้นพื้นฐาน กระทรวงศึกษาธิการ
C9: ระดับชั้นประถมศึกษาปีที่ | G9: 1 | M9: ปีการศึกษา | O9: 2569
C10: รายวิชา | E10: ภาษาไทย | J10: รหัสวิชา | L10: ท11101
C11: เวลาเรียน | E11: 5 | F11: ชั่วโมง / สัปดาห์ | J11: จำนวนหน่วยการเรียน | N11: =E11/2 -> 2.5 | O11: หน่วยกิต
C12: ครูผู้สอน | E12: นางสุพรรณี สุวะศรี
C13: ครูที่ปรึกษา | E13: นางสุพรรณี สุวะศรี
C14: ครูที่ปรึกษา
A15: จำนวนนักเรียนทั้งหมด | C15: สรุปผลการเรียน
C16: จำนวนนักเรียนที่ได้ระดับผลการเรียน | K16: นักเรียนที่มีผลการเรียน | N16: ผลการเรียนเฉลี่ย | P16: ค่าเบี่ยงเบนมาตรฐาน
C17: 4 | D17: 3.5 | E17: 3 | F17: 2.5 | G17: 2 | H17: 1.5 | I17: 1 | J17: 0 | K17: ร | L17: มส | M17: มก | N17: (X-bar) | P17: (SD)
A18: =SUM(C18:M18) -> 9 | C18: =COUNTIF('สรุปผลรวม (10)'!$R$8:$R$42,'ปก (1)'!C17) -> 0 | D18: =COUNTIF('สรุปผลรวม (10)'!$R$8:$R$42,'ปก (1)'!D17) -> 0 | E18: =COUNTIF('สรุปผลรวม (10)'!$R$8:$R$42,'ปก (1)'!E17) -> 0 | F18: =COUNTIF('สรุปผลรวม (10)'!$R$8:$R$42,'ปก (1)'!F17) -> 0 | G18: =COUNTIF('สรุปผลรวม (10)'!$R$8:$R$42,'ปก (1)'!G17) -> 0 | H18: =COUNTIF('สรุปผลรวม (10)'!$R$8:$R$42,'ปก (1)'!H17) -> 0 | I18: =COUNTIF('สรุปผลรวม (10)'!$R$8:$R$42,'ปก (1)'!I17) -> 0 | J18: =COUNTIF('สรุปผลรวม (10)'!$R$8:$R$42,'ปก (1)'!J17) -> 9 | ... M18: =COUNTIF('สรุปผลรวม (10)'!$R$8:$R$42,'ปก (1)'!M17) -> 0 | N18: =AVERAGE('สรุปผลรวม (10)'!R8:R42) -> 0 | P18: =STDEV('สรุปผลรวม (10)'!R8:R42) -> 0
A20: จำนวนนักเรียนทั้งหมด | D20: ผลการประเมินคุณลักษณะอันพึงประสงค์ | H20: ผลการประเมินการอ่านคิดวิเคราะห์และเขียนสื่อความ | L20: ผลการประเมินสมรรถนะสำคัญของผู้เรียน
D21: 3 | E21: 2 | F21: 1 | G21: 0 | H21: 3 | I21: 2 | J21: 1 | K21: 0 | L21: 3 | M21: 2 | N21: 1 | O21: 0
A22: =A18 -> 9 | D22: =COUNTIF('คุณลักษณะ -อ่าน -สมรรถนะ(11)'!$K$5:$K$22,'ปก (1)'!D21) -> 0 | E22: =COUNTIF('คุณลักษณะ -อ่าน -สมรรถนะ(11)'!$K$5:$K$22,'ปก (1)'!E21) -> 0 | F22: =COUNTIF('คุณลักษณะ -อ่าน -สมรรถนะ(11)'!$K$5:$K$22,'ปก (1)'!F21) -> 0 | G22: =COUNTIF('คุณลักษณะ -อ่าน -สมรรถนะ(11)'!$K$5:$K$22,'ปก (1)'!G21) -> 9 | H22: =COUNTIF('คุณลักษณะ -อ่าน -สมรรถนะ(11)'!$R$5:$R$22,'ปก (1)'!H21) -> 0 | I22: =COUNTIF('คุณลักษณะ -อ่าน -สมรรถนะ(11)'!$R$5:$R$22,'ปก (1)'!I21) -> 0 | J22: =COUNTIF('คุณลักษณะ -อ่าน -สมรรถนะ(11)'!$R$5:$R$22,'ปก (1)'!J21) -> 0 | K22: =COUNTIF('คุณลักษณะ -อ่าน -สมรรถนะ(11)'!$R$5:$R$22,'ปก (1)'!K21) -> 9 | L22: =COUNTIF('คุณลักษณะ -อ่าน -สมรรถนะ(11)'!$Y$5:$Y$22,'ปก (1)'!L21) -> 0 | M22: =COUNTIF('คุณลักษณะ -อ่าน -สมรรถนะ(11)'!$Y$5:$Y$22,'ปก (1)'!M21) -> 0 | N22: =COUNTIF('คุณลักษณะ -อ่าน -สมรรถนะ(11)'!$Y$5:$Y$22,'ปก (1)'!N21) -> 0 | O22: =COUNTIF('คุณลักษณะ -อ่าน -สมรรถนะ(11)'!$Y$5:$Y$22,'ปก (1)'!O21) -> 9
A24: อนุมัติผลการเรียน
A25: ลงชื่อ……………………………………..ครูผู้สอน | I25: ลงชื่อ……………………………………หัวหน้ากลุ่มสาระการเรียนรู้
F27: ลงชื่อ…………………………………...………เจ้าหน้าที่วัดผลและประเมินผล
F29: ลงชื่อ………………………..…………...….…หัวหน้างานวัดผลและประเมินผล
A30: เรียนเสนอเพื่อพิจารณา
F32: ลงชื่อ…………………………………………….. | K32: หัวหน้ากลุ่มงานวิชาการ
E34: ( ) | F34: อนุมัติ | I34: ( ) | J34: ไม่อนุมัติ
F36: ลงชื่อ……………………………………………..
E37: ผู้อำนวยการโรงเรียนบ้านขัวก่าย
E38: ………/…………/……….

Sheet เวลาเรียน (2)
BB1: 2
A2: เลขที่ | B2: เลขประจำตัว | C2: ชื่อ - สกุล | D2: เดือน | G2: พ.ค. | N2: พ.ค. | U2: พ.ค.-มิ.ย. | AB2: มิ.ย. | AI2: มิ.ย. | AP2: มิ.ย. | AW2: มิ.ย.-ก.ค.
D3: สัปดาห์ที่ | G3: 1 | N3: 2 | U3: 3 | AB3: 4 | AI3: 5 | AP3: 6 | AW3: 7
D4: วันที่ | G4: 17 | H4: 18 | I4: 19 | J4: 20 | K4: 21 | L4: 22 | M4: 23 | N4: 24 | O4: 25 | P4: 26 | Q4: 27 | R4: 28 | S4: 29 | T4: 30 | U4: 31 | V4: 1 | W4: 2 | X4: 3 | Y4: 4 | Z4: 5 | AA4: 6 | AB4: 7 | AC4: 8 | AD4: 9 | AE4: 10 | AF4: 11 | AG4: 12 | AH4: 13 | AI4: 14 | AJ4: 15 | AK4: 16 | AL4: 17 | AM4: 18 | AN4: 19 | AO4: 20 | AP4: 21 | AQ4: 22 | AR4: 23 | AS4: 24 | AT4: 25 | AU4: 26 | AV4: 27 | AW4: 28 | AX4: 29 | AY4: 30 | AZ4: 1 | BA4: 2 | BB4: 3 | BC4: 4
D5: ชั่วโมงที่
A6: 1 | B6: 4997 | C6: เด็กชายธนาธร กิติกาแดง
A7: 2 | B7: 4998 | C7: เด็กชายนิรวุฒิ วันทอง
A8: 3 | B8: 4999 | C8: เด็กชายศรันยู รัตนมงคล
A9: 4 | B9: 5000 | C9: เด็กชายสิรธีร์ เวียงอินทร์
A10: 5 | B10: 5001 | C10: เด็กหญิงจิรภิญญา เขื่อนพงษ์
A11: 6 | B11: 5002 | C11: เด็กหญิงภคพร วงค์สา
A12: 7 | B12: 5003 | C12: เด็กหญิงศิริณภา สุวรรณจันทร์
A13: 8 | B13: 5004 | C13: เด็กหญิงศุภิสรา โม้แซง
A14: 9 | B14: 5005 | C14: เด็กหญิงสุพิชชา ชาวนาฮี
A15: 10
A16: 11
A17: 12
A18: 13
A19: 14
A20: 15
A21: 16
A22: 17
A23: 18
A24: 19
A25: 20
A26: 21
... A40: 35

Sheet เวลาเรียน (3)
BB1: 3
A2: เลขที่ | B2: เลขประจำตัว | C2: ชื่อ - สกุล | D2: เดือน | G2: มิ.ย.-ก.ค. | N2: ก.ค. | U2: ก.ค. | AB2: ก.ค.-ส.ค. | AI2: ส.ค. | AP2: ส.ค. | AW2: ส.ค.
D3: สัปดาห์ที่ | G3: 8 | N3: 9 | U3: 10 | AB3: 11 | AI3: 12 | AP3: 13 | AW3: 14
D4: วันที่ | G4: 5 | H4: 6 | I4: 7 | J4: 8 | K4: 9 | L4: 10 | M4: 11 | N4: 12 | O4: 13 | P4: 14 | Q4: 15 | R4: 16 | S4: 17 | T4: 18 | U4: 19 | V4: 20 | W4: 21 | X4: 22 | Y4: 23 | Z4: 24 | AA4: 25 | AB4: 26 | AC4: 27 | AD4: 28 | AE4: 29 | AF4: 30 | AG4: 31 | AH4: 1 | AI4: 2 | AJ4: 3 | AK4: 4 | AL4: 5 | AM4: 6 | AN4: 7 | AO4: 8 | AP4: 9 | AQ4: 10 | AR4: 11 | AS4: 12 | AT4: 13 | AU4: 14 | AV4: 15 | AW4: 16 | AX4: 17 | AY4: 18 | AZ4: 19 | BA4: 20 | BB4: 21 | BC4: 22
D5: ชั่วโมงที่
A6: 1 | B6: ='เวลาเรียน (2)'!B6 -> 4997 | C6: ='เวลาเรียน (2)'!C6 -> เด็กชายธนาธร กิติกาแดง
A7: 2 | B7: ='เวลาเรียน (2)'!B7 -> 4998 | C7: ='เวลาเรียน (2)'!C7 -> เด็กชายนิรวุฒิ วันทอง
A8: 3 | B8: ='เวลาเรียน (2)'!B8 -> 4999 | C8: ='เวลาเรียน (2)'!C8 -> เด็กชายศรันยู รัตนมงคล
A9: 4 | B9: ='เวลาเรียน (2)'!B9 -> 5000 | C9: ='เวลาเรียน (2)'!C9 -> เด็กชายสิรธีร์ เวียงอินทร์
A10: 5 | B10: ='เวลาเรียน (2)'!B10 -> 5001 | C10: ='เวลาเรียน (2)'!C10 -> เด็กหญิงจิรภิญญา เขื่อนพงษ์
A11: 6 | B11: ='เวลาเรียน (2)'!B11 -> 5002 | C11: ='เวลาเรียน (2)'!C11 -> เด็กหญิงภคพร วงค์สา
A12: 7 | B12: ='เวลาเรียน (2)'!B12 -> 5003 | C12: ='เวลาเรียน (2)'!C12 -> เด็กหญิงศิริณภา สุวรรณจันทร์
A13: 8 | B13: ='เวลาเรียน (2)'!B13 -> 5004 | C13: ='เวลาเรียน (2)'!C13 -> เด็กหญิงศุภิสรา โม้แซง
A14: 9 | B14: ='เวลาเรียน (2)'!B14 -> 5005 | C14: ='เวลาเรียน (2)'!C14 -> เด็กหญิงสุพิชชา ชาวนาฮี
A15: 10
A16: 11
A17: 12
A18: 13
A19: 14
A20: 15
A21: 16
A22: 17
A23: 18
A24: 19
A25: 20
A26: 21
... A40: 35

Sheet เวลาเรียน (4)
AX1: 4
A2: เลขที่ | B2: เลขประจำตัว | C2: ชื่อ - สกุล | E2: เดือน | H2: ส.ค. | O2: ส.ค.-ก.ย. | V2: ก.ย. | AC2: ก.ย. | AJ2: ก.ย. | AQ2: ก.ย.-ต.ค. | AX2: รวม
E3: สัปดาห์ที่ | H3: 15 | O3: 16 | V3: 17 | AC3: 18 | AJ3: 19 | AQ3: 20 | AX3: กลางปี
E4: วันที่ | H4: 23 | I4: 24 | J4: 25 | K4: 26 | L4: 27 | M4: 28 | N4: 29 | O4: 30 | P4: 31 | Q4: 1 | R4: 2 | S4: 3 | T4: 4 | U4: 5 | V4: 6 | W4: 7 | X4: 8 | Y4: 9 | Z4: 10 | AA4: 11 | AB4: 12 | AC4: 13 | AD4: 14 | AE4: 15 | AF4: 16 | AG4: 17 | AH4: 18 | AI4: 19 | AJ4: 2q | AK4: 21 | AL4: 22 | AM4: 23 | AN4: 24 | AO4: 25 | AP4: 26 | AQ4: 27 | AR4: 28 | AS4: 29 | AT4: 30 | AU4: 1 | AV4: 2 | AW4: 3 | AX4: ='ปก (1)'!N11*40 -> 100
E5: ชั่วโมงที่ | AX5: =AX4*80/100 -> 80
A6: 1 | B6: ='เวลาเรียน (2)'!B6 -> 4997 | C6: ='เวลาเรียน (2)'!C6 -> เด็กชายธนาธร กิติกาแดง | AX6: =COUNTIF('เวลาเรียน (2)'!G6:BC6,"/")+COUNTIF('เวลาเรียน (3)'!G6:BC6,"/")+COUNTIF('เวลาเรียน (4)'!H6:AW6,"/") -> 0
A7: 2 | B7: ='เวลาเรียน (2)'!B7 -> 4998 | C7: ='เวลาเรียน (2)'!C7 -> เด็กชายนิรวุฒิ วันทอง | AX7: =COUNTIF('เวลาเรียน (2)'!G7:BC7,"/")+COUNTIF('เวลาเรียน (3)'!G7:BC7,"/")+COUNTIF('เวลาเรียน (4)'!H7:AW7,"/") -> 0
A8: 3 | B8: ='เวลาเรียน (2)'!B8 -> 4999 | C8: ='เวลาเรียน (2)'!C8 -> เด็กชายศรันยู รัตนมงคล | AX8: =COUNTIF('เวลาเรียน (2)'!G8:BC8,"/")+COUNTIF('เวลาเรียน (3)'!G8:BC8,"/")+COUNTIF('เวลาเรียน (4)'!H8:AW8,"/") -> 0
A9: 4 | B9: ='เวลาเรียน (2)'!B9 -> 5000 | C9: ='เวลาเรียน (2)'!C9 -> เด็กชายสิรธีร์ เวียงอินทร์ | AX9: =COUNTIF('เวลาเรียน (2)'!G9:BC9,"/")+COUNTIF('เวลาเรียน (3)'!G9:BC9,"/")+COUNTIF('เวลาเรียน (4)'!H9:AW9,"/") -> 0
A10: 5 | B10: ='เวลาเรียน (2)'!B10 -> 5001 | C10: ='เวลาเรียน (2)'!C10 -> เด็กหญิงจิรภิญญา เขื่อนพงษ์ | AX10: =COUNTIF('เวลาเรียน (2)'!G10:BC10,"/")+COUNTIF('เวลาเรียน (3)'!G10:BC10,"/")+COUNTIF('เวลาเรียน (4)'!H10:AW10,"/") -> 0
A11: 6 | B11: ='เวลาเรียน (2)'!B11 -> 5002 | C11: ='เวลาเรียน (2)'!C11 -> เด็กหญิงภคพร วงค์สา | AX11: =COUNTIF('เวลาเรียน (2)'!G11:BC11,"/")+COUNTIF('เวลาเรียน (3)'!G11:BC11,"/")+COUNTIF('เวลาเรียน (4)'!H11:AW11,"/") -> 0
A12: 7 | B12: ='เวลาเรียน (2)'!B12 -> 5003 | C12: ='เวลาเรียน (2)'!C12 -> เด็กหญิงศิริณภา สุวรรณจันทร์ | AX12: =COUNTIF('เวลาเรียน (2)'!G12:BC12,"/")+COUNTIF('เวลาเรียน (3)'!G12:BC12,"/")+COUNTIF('เวลาเรียน (4)'!H12:AW12,"/") -> 0
A13: 8 | B13: ='เวลาเรียน (2)'!B13 -> 5004 | C13: ='เวลาเรียน (2)'!C13 -> เด็กหญิงศุภิสรา โม้แซง | AX13: =COUNTIF('เวลาเรียน (2)'!G13:BC13,"/")+COUNTIF('เวลาเรียน (3)'!G13:BC13,"/")+COUNTIF('เวลาเรียน (4)'!H13:AW13,"/") -> 0
A14: 9 | B14: ='เวลาเรียน (2)'!B14 -> 5005 | C14: ='เวลาเรียน (2)'!C14 -> เด็กหญิงสุพิชชา ชาวนาฮี | AX14: =COUNTIF('เวลาเรียน (2)'!G14:BC14,"/")+COUNTIF('เวลาเรียน (3)'!G14:BC14,"/")+COUNTIF('เวลาเรียน (4)'!H14:AW14,"/") -> 0
A15: 10 | AX15: =COUNTIF('เวลาเรียน (2)'!G15:BC15,"/")+COUNTIF('เวลาเรียน (3)'!G15:BC15,"/")+COUNTIF('เวลาเรียน (4)'!H15:AW15,"/") -> 0
A16: 11
A17: 12
A18: 13
A19: 14
A20: 15
A21: 16
A22: 17
A23: 18
A24: 19
A25: 20
A26: 21
A27: 22
... A40: 35

Sheet เวลาเรียน (5)
BB1: 5
A2: เลขที่ | B2: เลขประจำตัว | C2: ชื่อ - สกุล | D2: เดือน | G2: พ.ย. | N2: พ.ย. | U2: พ.ย. | AB2: พ.ย. | AI2: พ.ย.-ธ.ค. | AP2: ธ.ค. | AW2: ธ.ค.
D3: สัปดาห์ที่ | G3: 1 | N3: 2 | U3: 3 | AB3: 4 | AI3: 5 | AP3: 6 | AW3: 7
D4: วันที่ | G4: 1 | H4: 2 | I4: 3 | J4: 4 | K4: 5 | L4: 6 | M4: 7 | N4: 8 | O4: 9 | P4: 10 | Q4: 11 | R4: 12 | S4: 13 | T4: 14 | U4: 15 | V4: 16 | W4: 17 | X4: 18 | Y4: 19 | Z4: 20 | AA4: 21 | AB4: 22 | AC4: 23 | AD4: 24 | AE4: 25 | AF4: 26 | AG4: 27 | AH4: 28 | AI4: 29 | AJ4: 30 | AK4: 1 | AL4: 2 | AM4: 3 | AN4: 4 | AO4: 5 | AP4: 6 | AQ4: 7 | AR4: 8 | AS4: 9 | AT4: 10 | AU4: 11 | AV4: 12 | AW4: 13 | AX4: 14 | AY4: 15 | AZ4: 16 | BA4: 17 | BB4: 18 | BC4: 19
D5: ชั่วโมงที่
A6: 1 | B6: ='เวลาเรียน (2)'!B6 -> 4997 | C6: ='เวลาเรียน (2)'!C6 -> เด็กชายธนาธร กิติกาแดง
A7: 2 | B7: ='เวลาเรียน (2)'!B7 -> 4998 | C7: ='เวลาเรียน (2)'!C7 -> เด็กชายนิรวุฒิ วันทอง
A8: 3 | B8: ='เวลาเรียน (2)'!B8 -> 4999 | C8: ='เวลาเรียน (2)'!C8 -> เด็กชายศรันยู รัตนมงคล
A9: 4 | B9: ='เวลาเรียน (2)'!B9 -> 5000 | C9: ='เวลาเรียน (2)'!C9 -> เด็กชายสิรธีร์ เวียงอินทร์
A10: 5 | B10: ='เวลาเรียน (2)'!B10 -> 5001 | C10: ='เวลาเรียน (2)'!C10 -> เด็กหญิงจิรภิญญา เขื่อนพงษ์
A11: 6 | B11: ='เวลาเรียน (2)'!B11 -> 5002 | C11: ='เวลาเรียน (2)'!C11 -> เด็กหญิงภคพร วงค์สา
A12: 7 | B12: ='เวลาเรียน (2)'!B12 -> 5003 | C12: ='เวลาเรียน (2)'!C12 -> เด็กหญิงศิริณภา สุวรรณจันทร์
A13: 8 | B13: ='เวลาเรียน (2)'!B13 -> 5004 | C13: ='เวลาเรียน (2)'!C13 -> เด็กหญิงศุภิสรา โม้แซง
A14: 9 | B14: ='เวลาเรียน (2)'!B14 -> 5005 | C14: ='เวลาเรียน (2)'!C14 -> เด็กหญิงสุพิชชา ชาวนาฮี
A15: 10
A16: 11
A17: 12
A18: 13
A19: 14
A20: 15
A21: 16
A22: 17
A23: 18
A24: 19
A25: 20
A26: 21
... A40: 35

Sheet เวลาเรียน (6)
BB1: 6
A2: เลขที่ | B2: เลขประจำตัว | C2: ชื่อ - สกุล | D2: เดือน | G2: ธ.ค. | N2: ธ.ค.-ม.ค. | U2: ม.ค. | AB2: ม.ค. | AI2: ม.ค. | AP2: ม.ค. | AW2: ม.ค.-ก.พ.
D3: สัปดาห์ที่ | G3: 8 | N3: 9 | U3: 10 | AB3: 11 | AI3: 12 | AP3: 13 | AW3: 14
D4: วันที่ | G4: 20 | H4: 21 | I4: 22 | J4: 23 | K4: 24 | L4: 25 | M4: 26 | N4: 27 | O4: 28 | P4: 29 | Q4: 30 | R4: 31 | S4: 1 | T4: 2 | U4: 3 | V4: 4 | W4: 5 | X4: 6 | Y4: 7 | Z4: 8 | AA4: 9 | AB4: 10 | AC4: 11 | AD4: 12 | AE4: 13 | AF4: 14 | AG4: 15 | AH4: 16 | AI4: 17 | AJ4: 18 | AK4: 19 | AL4: 20 | AM4: 21 | AN4: 22 | AO4: 23 | AP4: 24 | AQ4: 25 | AR4: 26 | AS4: 27 | AT4: 28 | AU4: 29 | AV4: 30 | AW4: 31 | AX4: 1 | AY4: 2 | AZ4: 3 | BA4: 4 | BB4: 5 | BC4: 6
D5: ชั่วโมงที่
A6: 1 | B6: ='เวลาเรียน (2)'!B6 -> 4997 | C6: ='เวลาเรียน (2)'!C6 -> เด็กชายธนาธร กิติกาแดง
A7: 2 | B7: ='เวลาเรียน (2)'!B7 -> 4998 | C7: ='เวลาเรียน (2)'!C7 -> เด็กชายนิรวุฒิ วันทอง
A8: 3 | B8: ='เวลาเรียน (2)'!B8 -> 4999 | C8: ='เวลาเรียน (2)'!C8 -> เด็กชายศรันยู รัตนมงคล
A9: 4 | B9: ='เวลาเรียน (2)'!B9 -> 5000 | C9: ='เวลาเรียน (2)'!C9 -> เด็กชายสิรธีร์ เวียงอินทร์
A10: 5 | B10: ='เวลาเรียน (2)'!B10 -> 5001 | C10: ='เวลาเรียน (2)'!C10 -> เด็กหญิงจิรภิญญา เขื่อนพงษ์
A11: 6 | B11: ='เวลาเรียน (2)'!B11 -> 5002 | C11: ='เวลาเรียน (2)'!C11 -> เด็กหญิงภคพร วงค์สา
A12: 7 | B12: ='เวลาเรียน (2)'!B12 -> 5003 | C12: ='เวลาเรียน (2)'!C12 -> เด็กหญิงศิริณภา สุวรรณจันทร์
A13: 8 | B13: ='เวลาเรียน (2)'!B13 -> 5004 | C13: ='เวลาเรียน (2)'!C13 -> เด็กหญิงศุภิสรา โม้แซง
A14: 9 | B14: ='เวลาเรียน (2)'!B14 -> 5005 | C14: ='เวลาเรียน (2)'!C14 -> เด็กหญิงสุพิชชา ชาวนาฮี
A15: 10
A16: 11
A17: 12
A18: 13
A19: 14
A20: 15
A21: 16
A22: 17
A23: 18
A24: 19
A25: 20
A26: 21
... A40: 35

Sheet เวลาเรียน (7)
AY1: 7
A2: เลขที่ | B2: เลขประจำตัว | C2: ชื่อ - สกุล | E2: เดือน | H2: ก.พ. | O2: ก.พ. | V2: ก.พ. | AC2: ก.พ.-มี.ค. | AJ2: มี.ค. | AQ2: มี.ค. | AX2: รวม | AY2: รวม
E3: สัปดาห์ที่ | H3: 15 | O3: 16 | V3: 17 | AC3: 18 | AJ3: 19 | AQ3: 20 | AX3: ปลายปี | AY3: ทั้งปี
E4: วันที่ | H4: 7 | I4: 8 | J4: 9 | K4: 10 | L4: 11 | M4: 12 | N4: 13 | O4: 14 | P4: 15 | Q4: 16 | R4: 17 | S4: 18 | T4: 19 | U4: 20 | V4: 21 | W4: 22 | X4: 23 | Y4: 24 | Z4: 25 | AA4: 26 | AB4: 27 | AC4: 28 | AD4: 1 | AE4: 2 | AF4: 9 | AG4: 4 | AH4: 5 | AI4: 6 | AJ4: 7 | AK4: 8 | AL4: 9 | AM4: 10 | AN4: 11 | AO4: 12 | AP4: 13 | AQ4: 14 | AR4: 15 | AS4: 16 | AT4: 17 | AU4: 18 | AV4: 19 | AW4: 20 | AX4: ='ปก (1)'!N11*40 -> 100 | AY4: =AX4+'เวลาเรียน (4)'!AX4 -> 200
E5: ชั่วโมงที่ | AX5: =AX4*80/100 -> 80 | AY5: =AX5+'เวลาเรียน (4)'!AX5 -> 160
A6: 1 | B6: ='เวลาเรียน (2)'!B6 -> 4997 | C6: ='เวลาเรียน (2)'!C6 -> เด็กชายธนาธร กิติกาแดง | AX6: =COUNTIF('เวลาเรียน (5)'!G6:BC6,"/")+COUNTIF('เวลาเรียน (6)'!G6:BC6,"/")+COUNTIF('เวลาเรียน (7)'!H6:AW6,"/") -> 0 | AY6: ='เวลาเรียน (4)'!AX6+'เวลาเรียน (7)'!AX6 -> 0
A7: 2 | B7: ='เวลาเรียน (2)'!B7 -> 4998 | C7: ='เวลาเรียน (2)'!C7 -> เด็กชายนิรวุฒิ วันทอง | AX7: =COUNTIF('เวลาเรียน (5)'!G7:BC7,"/")+COUNTIF('เวลาเรียน (6)'!G7:BC7,"/")+COUNTIF('เวลาเรียน (7)'!H7:AW7,"/") -> 0 | AY7: ='เวลาเรียน (4)'!AX7+'เวลาเรียน (7)'!AX7 -> 0
A8: 3 | B8: ='เวลาเรียน (2)'!B8 -> 4999 | C8: ='เวลาเรียน (2)'!C8 -> เด็กชายศรันยู รัตนมงคล | AX8: =COUNTIF('เวลาเรียน (5)'!G8:BC8,"/")+COUNTIF('เวลาเรียน (6)'!G8:BC8,"/")+COUNTIF('เวลาเรียน (7)'!H8:AW8,"/") -> 0 | AY8: ='เวลาเรียน (4)'!AX8+'เวลาเรียน (7)'!AX8 -> 0
A9: 4 | B9: ='เวลาเรียน (2)'!B9 -> 5000 | C9: ='เวลาเรียน (2)'!C9 -> เด็กชายสิรธีร์ เวียงอินทร์ | AX9: =COUNTIF('เวลาเรียน (5)'!G9:BC9,"/")+COUNTIF('เวลาเรียน (6)'!G9:BC9,"/")+COUNTIF('เวลาเรียน (7)'!H9:AW9,"/") -> 0 | AY9: ='เวลาเรียน (4)'!AX9+'เวลาเรียน (7)'!AX9 -> 0
A10: 5 | B10: ='เวลาเรียน (2)'!B10 -> 5001 | C10: ='เวลาเรียน (2)'!C10 -> เด็กหญิงจิรภิญญา เขื่อนพงษ์ | AX10: =COUNTIF('เวลาเรียน (5)'!G10:BC10,"/")+COUNTIF('เวลาเรียน (6)'!G10:BC10,"/")+COUNTIF('เวลาเรียน (7)'!H10:AW10,"/") -> 0 | AY10: ='เวลาเรียน (4)'!AX10+'เวลาเรียน (7)'!AX10 -> 0
A11: 6 | B11: ='เวลาเรียน (2)'!B11 -> 5002 | C11: ='เวลาเรียน (2)'!C11 -> เด็กหญิงภคพร วงค์สา | AX11: =COUNTIF('เวลาเรียน (5)'!G11:BC11,"/")+COUNTIF('เวลาเรียน (6)'!G11:BC11,"/")+COUNTIF('เวลาเรียน (7)'!H11:AW11,"/") -> 0 | AY11: ='เวลาเรียน (4)'!AX11+'เวลาเรียน (7)'!AX11 -> 0
A12: 7 | B12: ='เวลาเรียน (2)'!B12 -> 5003 | C12: ='เวลาเรียน (2)'!C12 -> เด็กหญิงศิริณภา สุวรรณจันทร์ | AX12: =COUNTIF('เวลาเรียน (5)'!G12:BC12,"/")+COUNTIF('เวลาเรียน (6)'!G12:BC12,"/")+COUNTIF('เวลาเรียน (7)'!H12:AW12,"/") -> 0 | AY12: ='เวลาเรียน (4)'!AX12+'เวลาเรียน (7)'!AX12 -> 0
A13: 8 | B13: ='เวลาเรียน (2)'!B13 -> 5004 | C13: ='เวลาเรียน (2)'!C13 -> เด็กหญิงศุภิสรา โม้แซง | AX13: =COUNTIF('เวลาเรียน (5)'!G13:BC13,"/")+COUNTIF('เวลาเรียน (6)'!G13:BC13,"/")+COUNTIF('เวลาเรียน (7)'!H13:AW13,"/") -> 0 | AY13: ='เวลาเรียน (4)'!AX13+'เวลาเรียน (7)'!AX13 -> 0
A14: 9 | B14: ='เวลาเรียน (2)'!B14 -> 5005 | C14: ='เวลาเรียน (2)'!C14 -> เด็กหญิงสุพิชชา ชาวนาฮี | AX14: =COUNTIF('เวลาเรียน (5)'!G14:BC14,"/")+COUNTIF('เวลาเรียน (6)'!G14:BC14,"/")+COUNTIF('เวลาเรียน (7)'!H14:AW14,"/") -> 0 | AY14: ='เวลาเรียน (4)'!AX14+'เวลาเรียน (7)'!AX14 -> 0
A15: 10
A16: 11
A17: 12
A18: 13
A19: 14
A20: 15
A21: 16
A22: 17
A23: 18
A24: 19
A25: 20
A26: 21
... A40: 35

Sheet ภาค1(8)
AA1: 8
A2: ภาคเรียนที่ 1
A3: หน่วยการเรียนรู้ที่ | C3: 1 | H3: 2 | M3: 3 | R3: 4 | W3: 5
C4: ตัวชี้วัด | F4: รวม | G4: ซ่อมเสริม | H4: ตัวชี้วัด | K4: รวม | L4: ซ่อมเสริม | M4: ตัวชี้วัด | P4: รวม | Q4: ซ่อมเสริม | R4: ตัวชี้วัด | U4: รวม | V4: ซ่อมเสริม | W4: ตัวชี้วัด | Z4: รวม | AA4: ซ่อมเสริม
A5: เลขที่ | B5: แผน / ข้อที่
B6: ชื่อ-สกุล /เต็ม | C6: 0 | F6: =SUM(C6:E6) -> 0 | H6: 0 | K6: =SUM(H6:J6) -> 0 | M6: 0 | P6: =SUM(M6:O6) -> 0 | R6: 0 | U6: =SUM(R6:T6) -> 0 | W6: 0 | Z6: =SUM(W6:Y6) -> 0
A7: 1 | B7: ='เวลาเรียน (2)'!C6 -> เด็กชายธนาธร กิติกาแดง | F7: =SUM(C7:E7) -> 0 | K7: =SUM(H7:J7) -> 0 | P7: =SUM(M7:O7) -> 0 | U7: =SUM(R7:T7) -> 0 | Z7: =SUM(W7:Y7) -> 0
A8: 2 | B8: ='เวลาเรียน (2)'!C7 -> เด็กชายนิรวุฒิ วันทอง | F8: =SUM(C8:E8) -> 0 | K8: =SUM(H8:J8) -> 0 | P8: =SUM(M8:O8) -> 0 | U8: =SUM(R8:T8) -> 0 | Z8: =SUM(W8:Y8) -> 0
A9: 3 | B9: ='เวลาเรียน (2)'!C8 -> เด็กชายศรันยู รัตนมงคล | F9: =SUM(C9:E9) -> 0 | K9: =SUM(H9:J9) -> 0 | P9: =SUM(M9:O9) -> 0 | U9: =SUM(R9:T9) -> 0 | Z9: =SUM(W9:Y9) -> 0
A10: 4 | B10: ='เวลาเรียน (2)'!C9 -> เด็กชายสิรธีร์ เวียงอินทร์ | F10: =SUM(C10:E10) -> 0 | K10: =SUM(H10:J10) -> 0 | P10: =SUM(M10:O10) -> 0 | U10: =SUM(R10:T10) -> 0 | Z10: =SUM(W10:Y10) -> 0
A11: 5 | B11: ='เวลาเรียน (2)'!C10 -> เด็กหญิงจิรภิญญา เขื่อนพงษ์ | F11: =SUM(C11:E11) -> 0 | K11: =SUM(H11:J11) -> 0 | P11: =SUM(M11:O11) -> 0 | U11: =SUM(R11:T11) -> 0 | Z11: =SUM(W11:Y11) -> 0
A12: 6 | B12: ='เวลาเรียน (2)'!C11 -> เด็กหญิงภคพร วงค์สา | F12: =SUM(C12:E12) -> 0 | K12: =SUM(H12:J12) -> 0 | P12: =SUM(M12:O12) -> 0 | U12: =SUM(R12:T12) -> 0 | Z12: =SUM(W12:Y12) -> 0
A13: 7 | B13: ='เวลาเรียน (2)'!C12 -> เด็กหญิงศิริณภา สุวรรณจันทร์ | F13: =SUM(C13:E13) -> 0 | K13: =SUM(H13:J13) -> 0 | P13: =SUM(M13:O13) -> 0 | U13: =SUM(R13:T13) -> 0 | Z13: =SUM(W13:Y13) -> 0
A14: 8 | B14: ='เวลาเรียน (2)'!C13 -> เด็กหญิงศุภิสรา โม้แซง | F14: =SUM(C14:E14) -> 0 | K14: =SUM(H14:J14) -> 0 | P14: =SUM(M14:O14) -> 0 | U14: =SUM(R14:T14) -> 0 | Z14: =SUM(W14:Y14) -> 0
A15: 9 | B15: ='เวลาเรียน (2)'!C14 -> เด็กหญิงสุพิชชา ชาวนาฮี | F15: =SUM(C15:E15) -> 0 | K15: =SUM(H15:J15) -> 0 | P15: =SUM(M15:O15) -> 0 | U15: =SUM(R15:T15) -> 0 | Z15: =SUM(W15:Y15) -> 0
A16: 10
A17: 11
A18: 12
A19: 13
A20: 14
A21: 15
A22: 16
A23: 17
A24: 18
A25: 19
A26: 20
A27: 21
... A41: 35

Sheet ภาค2 (9)
AA1: 9
A2: ภาคเรียนที่ 2
A3: หน่วยการเรียนรู้ที่ | C3: 1 | H3: 2 | M3: 3 | R3: 4 | W3: 5
C4: ตัวชี้วัด | F4: รวม | G4: ซ่อมเสริม | H4: ตัวชี้วัด | K4: รวม | L4: ซ่อมเสริม | M4: ตัวชี้วัด | P4: รวม | Q4: ซ่อมเสริม | R4: ตัวชี้วัด | U4: รวม | V4: ซ่อมเสริม | W4: ตัวชี้วัด | Z4: รวม | AA4: ซ่อมเสริม
A5: เลขที่ | B5: แผน / ข้อที่
B6: ชื่อ-สกุล /เต็ม | C6: 0 | F6: =SUM(C6:E6) -> 0 | H6: 0 | K6: =SUM(H6:J6) -> 0 | M6: 0 | P6: =SUM(M6:O6) -> 0 | R6: 0 | U6: =SUM(R6:T6) -> 0 | W6: 0 | Z6: =SUM(W6:Y6) -> 0
A7: 1 | B7: ='เวลาเรียน (2)'!C6 -> เด็กชายธนาธร กิติกาแดง | F7: =SUM(C7:E7) -> 0 | K7: =SUM(H7:J7) -> 0 | P7: =SUM(M7:O7) -> 0 | U7: =SUM(R7:T7) -> 0 | Z7: =SUM(W7:Y7) -> 0
A8: 2 | B8: ='เวลาเรียน (2)'!C7 -> เด็กชายนิรวุฒิ วันทอง | F8: =SUM(C8:E8) -> 0 | K8: =SUM(H8:J8) -> 0 | P8: =SUM(M8:O8) -> 0 | U8: =SUM(R8:T8) -> 0 | Z8: =SUM(W8:Y8) -> 0
A9: 3 | B9: ='เวลาเรียน (2)'!C8 -> เด็กชายศรันยู รัตนมงคล | F9: =SUM(C9:E9) -> 0 | K9: =SUM(H9:J9) -> 0 | P9: =SUM(M9:O9) -> 0 | U9: =SUM(R9:T9) -> 0 | Z9: =SUM(W9:Y9) -> 0
A10: 4 | B10: ='เวลาเรียน (2)'!C9 -> เด็กชายสิรธีร์ เวียงอินทร์ | F10: =SUM(C10:E10) -> 0 | K10: =SUM(H10:J10) -> 0 | P10: =SUM(M10:O10) -> 0 | U10: =SUM(R10:T10) -> 0 | Z10: =SUM(W10:Y10) -> 0
A11: 5 | B11: ='เวลาเรียน (2)'!C10 -> เด็กหญิงจิรภิญญา เขื่อนพงษ์ | F11: =SUM(C11:E11) -> 0 | K11: =SUM(H11:J11) -> 0 | P11: =SUM(M11:O11) -> 0 | U11: =SUM(R11:T11) -> 0 | Z11: =SUM(W11:Y11) -> 0
A12: 6 | B12: ='เวลาเรียน (2)'!C11 -> เด็กหญิงภคพร วงค์สา | F12: =SUM(C12:E12) -> 0 | K12: =SUM(H12:J12) -> 0 | P12: =SUM(M12:O12) -> 0 | U12: =SUM(R12:T12) -> 0 | Z12: =SUM(W12:Y12) -> 0
A13: 7 | B13: ='เวลาเรียน (2)'!C12 -> เด็กหญิงศิริณภา สุวรรณจันทร์ | F13: =SUM(C13:E13) -> 0 | K13: =SUM(H13:J13) -> 0 | P13: =SUM(M13:O13) -> 0 | U13: =SUM(R13:T13) -> 0 | Z13: =SUM(W13:Y13) -> 0
A14: 8 | B14: ='เวลาเรียน (2)'!C13 -> เด็กหญิงศุภิสรา โม้แซง | F14: =SUM(C14:E14) -> 0 | K14: =SUM(H14:J14) -> 0 | P14: =SUM(M14:O14) -> 0 | U14: =SUM(R14:T14) -> 0 | Z14: =SUM(W14:Y14) -> 0
A15: 9 | B15: ='เวลาเรียน (2)'!C14 -> เด็กหญิงสุพิชชา ชาวนาฮี | F15: =SUM(C15:E15) -> 0 | K15: =SUM(H15:J15) -> 0 | P15: =SUM(M15:O15) -> 0 | U15: =SUM(R15:T15) -> 0 | Z15: =SUM(W15:Y15) -> 0
A16: 10
A17: 11
A18: 12
A19: 13
A20: 14
A21: 15
A22: 16
A23: 17
A24: 18
A25: 19
A26: 20
A27: 21
... A41: 35

Sheet สรุปผลรวม (10)
S1: 10
A2: สรุปผลการประเมินคุณภาพผู้เรียน
A3: คะแนนรวม | C3: คะแนนหน่วยที่ | O3: สอบกลางปี | P3: สอบปลายปี | Q3: ผลการประเมิน | S3: หมายเหตุ
Q4: รวม | R4: ระดับ
C5: ภาคเรียนที่ 1 | I5: ภาคเรียนที่ 2
A6: หน่วยการเรียนรู้ | C6: 1 | D6: 2 | E6: 3 | F6: 4 | G6: 5 | I6: 1 | J6: 2 | K6: 3 | L6: 4 | M6: 5 | R6: ผล
A7: เลขที่ | B7: ชื่อ - สกุล | C7: ='ภาค1(8)'!F6 -> 0 | D7: ='ภาค1(8)'!H6 -> 0 | E7: ='ภาค1(8)'!P6 -> 0 | F7: ='ภาค1(8)'!U6 -> 0 | G7: ='ภาค1(8)'!Z6 -> 0 | I7: ='ภาค2 (9)'!F6 -> 0 | J7: ='ภาค2 (9)'!K6 -> 0 | K7: ='ภาค2 (9)'!P6 -> 0 | L7: ='ภาค2 (9)'!U6 -> 0 | M7: ='ภาค2 (9)'!Z6 -> 0 | O7: 20 | P7: 20 | Q7: =SUM(C7:P7) -> 40 | R7: การเรียน
A8: 1 | B8: ='เวลาเรียน (2)'!C6 -> เด็กชายธนาธร กิติกาแดง | C8: ='ภาค1(8)'!F7 -> 0 | D8: ='ภาค1(8)'!H7 -> 0 | E8: ='ภาค1(8)'!P7 -> 0 | F8: ='ภาค1(8)'!U7 -> 0 | G8: ='ภาค1(8)'!Z7 -> 0 | I8: ='ภาค2 (9)'!F7 -> 0 | J8: ='ภาค2 (9)'!K7 -> 0 | K8: ='ภาค2 (9)'!P7 -> 0 | L8: ='ภาค2 (9)'!U7 -> 0 | M8: ='ภาค2 (9)'!Z7 -> 0 | Q8: =SUM(C8:P8) -> 0 | R8: =IF(Q8>79,4,IF(Q8>74,3.5,IF(Q8>69,3,IF(Q8>64,2.5,IF(Q8>59,2,IF(Q8>54,1.5,IF(Q8>49,1,IF(Q8<50,0)))))))) -> 0
A9: 2 | B9: ='เวลาเรียน (2)'!C7 -> เด็กชายนิรวุฒิ วันทอง | C9: ='ภาค1(8)'!F8 -> 0 | D9: ='ภาค1(8)'!H8 -> 0 | E9: ='ภาค1(8)'!P8 -> 0 | F9: ='ภาค1(8)'!U8 -> 0 | G9: ='ภาค1(8)'!Z8 -> 0 | I9: ='ภาค2 (9)'!F8 -> 0 | J9: ='ภาค2 (9)'!K8 -> 0 | K9: ='ภาค2 (9)'!P8 -> 0 | L9: ='ภาค2 (9)'!U8 -> 0 | M9: ='ภาค2 (9)'!Z8 -> 0 | Q9: =SUM(C9:P9) -> 0 | R9: =IF(Q9>79,4,IF(Q9>74,3.5,IF(Q9>69,3,IF(Q9>64,2.5,IF(Q9>59,2,IF(Q9>54,1.5,IF(Q9>49,1,IF(Q9<50,0)))))))) -> 0
A10: 3 | B10: ='เวลาเรียน (2)'!C8 -> เด็กชายศรันยู รัตนมงคล | C10: ='ภาค1(8)'!F9 -> 0 | D10: ='ภาค1(8)'!H9 -> 0 | E10: ='ภาค1(8)'!P9 -> 0 | F10: ='ภาค1(8)'!U9 -> 0 | G10: ='ภาค1(8)'!Z9 -> 0 | I10: ='ภาค2 (9)'!F9 -> 0 | J10: ='ภาค2 (9)'!K9 -> 0 | K10: ='ภาค2 (9)'!P9 -> 0 | L10: ='ภาค2 (9)'!U9 -> 0 | M10: ='ภาค2 (9)'!Z9 -> 0 | Q10: =SUM(C10:P10) -> 0 | R10: =IF(Q10>79,4,IF(Q10>74,3.5,IF(Q10>69,3,IF(Q10>64,2.5,IF(Q10>59,2,IF(Q10>54,1.5,IF(Q10>49,1,IF(Q10<50,0)))))))) -> 0
A11: 4 | B11: ='เวลาเรียน (2)'!C9 -> เด็กชายสิรธีร์ เวียงอินทร์ | C11: ='ภาค1(8)'!F10 -> 0 | D11: ='ภาค1(8)'!H10 -> 0 | E11: ='ภาค1(8)'!P10 -> 0 | F11: ='ภาค1(8)'!U10 -> 0 | G11: ='ภาค1(8)'!Z10 -> 0 | I11: ='ภาค2 (9)'!F10 -> 0 | J11: ='ภาค2 (9)'!K10 -> 0 | K11: ='ภาค2 (9)'!P10 -> 0 | L11: ='ภาค2 (9)'!U10 -> 0 | M11: ='ภาค2 (9)'!Z10 -> 0 | Q11: =SUM(C11:P11) -> 0 | R11: =IF(Q11>79,4,IF(Q11>74,3.5,IF(Q11>69,3,IF(Q11>64,2.5,IF(Q11>59,2,IF(Q11>54,1.5,IF(Q11>49,1,IF(Q11<50,0)))))))) -> 0
A12: 5 | B12: ='เวลาเรียน (2)'!C10 -> เด็กหญิงจิรภิญญา เขื่อนพงษ์ | C12: ='ภาค1(8)'!F11 -> 0 | D12: ='ภาค1(8)'!H11 -> 0 | E12: ='ภาค1(8)'!P11 -> 0 | F12: ='ภาค1(8)'!U11 -> 0 | G12: ='ภาค1(8)'!Z11 -> 0 | I12: ='ภาค2 (9)'!F11 -> 0 | J12: ='ภาค2 (9)'!K11 -> 0 | K12: ='ภาค2 (9)'!P11 -> 0 | L12: ='ภาค2 (9)'!U11 -> 0 | M12: ='ภาค2 (9)'!Z11 -> 0 | Q12: =SUM(C12:P12) -> 0 | R12: =IF(Q12>79,4,IF(Q12>74,3.5,IF(Q12>69,3,IF(Q12>64,2.5,IF(Q12>59,2,IF(Q12>54,1.5,IF(Q12>49,1,IF(Q12<50,0)))))))) -> 0
A13: 6 | B13: ='เวลาเรียน (2)'!C11 -> เด็กหญิงภคพร วงค์สา | C13: ='ภาค1(8)'!F12 -> 0 | D13: ='ภาค1(8)'!H12 -> 0 | E13: ='ภาค1(8)'!P12 -> 0 | F13: ='ภาค1(8)'!U12 -> 0 | G13: ='ภาค1(8)'!Z12 -> 0 | I13: ='ภาค2 (9)'!F12 -> 0 | J13: ='ภาค2 (9)'!K12 -> 0 | K13: ='ภาค2 (9)'!P12 -> 0 | L13: ='ภาค2 (9)'!U12 -> 0 | M13: ='ภาค2 (9)'!Z12 -> 0 | Q13: =SUM(C13:P13) -> 0 | R13: =IF(Q13>79,4,IF(Q13>74,3.5,IF(Q13>69,3,IF(Q13>64,2.5,IF(Q13>59,2,IF(Q13>54,1.5,IF(Q13>49,1,IF(Q13<50,0)))))))) -> 0
A14: 7 | B14: ='เวลาเรียน (2)'!C12 -> เด็กหญิงศิริณภา สุวรรณจันทร์ | C14: ='ภาค1(8)'!F13 -> 0 | D14: ='ภาค1(8)'!H13 -> 0 | E14: ='ภาค1(8)'!P13 -> 0 | F14: ='ภาค1(8)'!U13 -> 0 | G14: ='ภาค1(8)'!Z13 -> 0 | I14: ='ภาค2 (9)'!F13 -> 0 | J14: ='ภาค2 (9)'!K13 -> 0 | K14: ='ภาค2 (9)'!P13 -> 0 | L14: ='ภาค2 (9)'!U13 -> 0 | M14: ='ภาค2 (9)'!Z13 -> 0 | Q14: =SUM(C14:P14) -> 0 | R14: =IF(Q14>79,4,IF(Q14>74,3.5,IF(Q14>69,3,IF(Q14>64,2.5,IF(Q14>59,2,IF(Q14>54,1.5,IF(Q14>49,1,IF(Q14<50,0)))))))) -> 0
A15: 8 | B15: ='เวลาเรียน (2)'!C13 -> เด็กหญิงศุภิสรา โม้แซง | C15: ='ภาค1(8)'!F14 -> 0 | D15: ='ภาค1(8)'!H14 -> 0 | E15: ='ภาค1(8)'!P14 -> 0 | F15: ='ภาค1(8)'!U14 -> 0 | G15: ='ภาค1(8)'!Z14 -> 0 | I15: ='ภาค2 (9)'!F14 -> 0 | J15: ='ภาค2 (9)'!K14 -> 0 | K15: ='ภาค2 (9)'!P14 -> 0 | L15: ='ภาค2 (9)'!U14 -> 0 | M15: ='ภาค2 (9)'!Z14 -> 0 | Q15: =SUM(C15:P15) -> 0 | R15: =IF(Q15>79,4,IF(Q15>74,3.5,IF(Q15>69,3,IF(Q15>64,2.5,IF(Q15>59,2,IF(Q15>54,1.5,IF(Q15>49,1,IF(Q15<50,0)))))))) -> 0
A16: 9 | B16: ='เวลาเรียน (2)'!C14 -> เด็กหญิงสุพิชชา ชาวนาฮี | C16: ='ภาค1(8)'!F15 -> 0 | D16: ='ภาค1(8)'!H15 -> 0 | E16: ='ภาค1(8)'!P15 -> 0 | F16: ='ภาค1(8)'!U15 -> 0 | G16: ='ภาค1(8)'!Z15 -> 0 | I16: ='ภาค2 (9)'!F15 -> 0 | J16: ='ภาค2 (9)'!K15 -> 0 | K16: ='ภาค2 (9)'!P15 -> 0 | L16: ='ภาค2 (9)'!U15 -> 0 | M16: ='ภาค2 (9)'!Z15 -> 0 | Q16: =SUM(C16:P16) -> 0 | R16: =IF(Q16>79,4,IF(Q16>74,3.5,IF(Q16>69,3,IF(Q16>64,2.5,IF(Q16>59,2,IF(Q16>54,1.5,IF(Q16>49,1,IF(Q16<50,0)))))))) -> 0
A17: 10
A18: 11
A19: 12
A20: 13
A21: 14
A22: 15
A23: 16
A24: 17
A25: 18
A26: 19
A27: 20
A28: 21
... A42: 35

Sheet คุณลักษณะ -อ่าน -สมรรถนะ(11)
Z1: 11
A2: ผลการประเมินคุณภาพผู้เรียน | C2: คุณลักษณะอันพึงประสงค์ | M2: การอ่าน การคิดวิเคราะห์ และเขียนสื่อความ | T2: สมรรถนะสำคัญของผู้เรียน
A3: เลขที่ | B3: หน่วย | C3: 1. รักชาติศาสน์กษัตริย์ | D3: 2.ซื่อสัตย์สุจริต | E3: 3. วินัย | F3: 4.ใฝ่เรียนรู้ | G3: 5.อยู่อย่างพอเพียง | H3: 6.มุ่งมั่นทำงาน | I3: 7. รักความเป็นไทย | J3: 8.มีจิตสาธารณะ | K3: สรุปผลรวม | L3: หมายเหตุ | M3: 1. การคัดสรรสื่อ | N3: 2. จับประเด็นสำคัญ | O3: 3. วิเคราะห์ วิจารณ์ | P3: 4. สรุปคุณค่า แง่คิดที่ดี | Q3: 5. สรุปอภิปรายขยายความ | R3: สรุปผลรวม | S3: หมายเหตุ | T3: 1. การสื่อสาร | U3: 2. การคิด | V3: 3. การแก้ปัญหา | W3: 4. การใช้ทักษะชีวิต | X3: 5. การใช้เทคโนโลยี | Y3: สรุปผลรวม | Z3: หมายเหตุ
B4: ชื่อ-สกุล | C4: 3 | D4: 3 | E4: 3 | F4: 3 | G4: 3 | H4: 3 | I4: 3 | J4: 3 | K4: 3 | M4: 3 | N4: 3 | O4: 3 | P4: 3 | Q4: 3 | R4: 3 | T4: 3 | U4: 3 | V4: 3 | W4: 3 | X4: 3 | Y4: 3
A5: 1 | B5: ='เวลาเรียน (2)'!C6 -> เด็กชายธนาธร กิติกาแดง | C5: =K5 -> 0 | D5: =C5 -> 0 | E5: =D5 -> 0 | F5: =E5 -> 0 | G5: =F5 -> 0 | H5: =G5 -> 0 | I5: =H5 -> 0 | J5: =I5 -> 0 | K5: =IF('สรุปผลรวม (10)'!Q8>70,3,IF('สรุปผลรวม (10)'!Q8>59,2,IF('สรุปผลรวม (10)'!Q8>49,1,IF('สรุปผลรวม (10)'!Q8<50,0)))) -> 0 | M5: =R5 -> 0 | N5: =M5 -> 0 | O5: =N5 -> 0 | P5: =O5 -> 0 | Q5: =P5 -> 0 | R5: =IF('สรุปผลรวม (10)'!Q8>74,3,IF('สรุปผลรวม (10)'!Q8>59,2,IF('สรุปผลรวม (10)'!Q8>49,1,IF('สรุปผลรวม (10)'!Q8<50,0)))) -> 0 | T5: =Y5 -> 0 | U5: =T5 -> 0 | V5: =U5 -> 0 | W5: =V5 -> 0 | X5: =W5 -> 0 | Y5: =IF('สรุปผลรวม (10)'!Q8>74,3,IF('สรุปผลรวม (10)'!Q8>59,2,IF('สรุปผลรวม (10)'!Q8>49,1,IF('สรุปผลรวม (10)'!Q8<50,0)))) -> 0
A6: 2 | B6: ='เวลาเรียน (2)'!C7 -> เด็กชายนิรวุฒิ วันทอง | C6: =K6 -> 0 | D6: =C6 -> 0 | E6: =D6 -> 0 | F6: =E6 -> 0 | G6: =F6 -> 0 | H6: =G6 -> 0 | I6: =H6 -> 0 | J6: =I6 -> 0 | K6: =IF('สรุปผลรวม (10)'!Q9>70,3,IF('สรุปผลรวม (10)'!Q9>59,2,IF('สรุปผลรวม (10)'!Q9>49,1,IF('สรุปผลรวม (10)'!Q9<50,0)))) -> 0 | M6: =R6 -> 0 | N6: =M6 -> 0 | O6: =N6 -> 0 | P6: =O6 -> 0 | Q6: =P6 -> 0 | R6: =IF('สรุปผลรวม (10)'!Q9>74,3,IF('สรุปผลรวม (10)'!Q9>59,2,IF('สรุปผลรวม (10)'!Q9>49,1,IF('สรุปผลรวม (10)'!Q9<50,0)))) -> 0 | T6: =Y6 -> 0 | U6: =T6 -> 0 | V6: =U6 -> 0 | W6: =V6 -> 0 | X6: =W6 -> 0 | Y6: =IF('สรุปผลรวม (10)'!Q9>74,3,IF('สรุปผลรวม (10)'!Q9>59,2,IF('สรุปผลรวม (10)'!Q9>49,1,IF('สรุปผลรวม (10)'!Q9<50,0)))) -> 0
A7: 3 | B7: ='เวลาเรียน (2)'!C8 -> เด็กชายศรันยู รัตนมงคล | C7: =K7 -> 0 | D7: =C7 -> 0 | E7: =D7 -> 0 | F7: =E7 -> 0 | G7: =F7 -> 0 | H7: =G7 -> 0 | I7: =H7 -> 0 | J7: =I7 -> 0 | K7: =IF('สรุปผลรวม (10)'!Q10>70,3,IF('สรุปผลรวม (10)'!Q10>59,2,IF('สรุปผลรวม (10)'!Q10>49,1,IF('สรุปผลรวม (10)'!Q10<50,0)))) -> 0 | M7: =R7 -> 0 | N7: =M7 -> 0 | O7: =N7 -> 0 | P7: =O7 -> 0 | Q7: =P7 -> 0 | R7: =IF('สรุปผลรวม (10)'!Q10>74,3,IF('สรุปผลรวม (10)'!Q10>59,2,IF('สรุปผลรวม (10)'!Q10>49,1,IF('สรุปผลรวม (10)'!Q10<50,0)))) -> 0 | T7: =Y7 -> 0 | U7: =T7 -> 0 | V7: =U7 -> 0 | W7: =V7 -> 0 | X7: =W7 -> 0 | Y7: =IF('สรุปผลรวม (10)'!Q10>74,3,IF('สรุปผลรวม (10)'!Q10>59,2,IF('สรุปผลรวม (10)'!Q10>49,1,IF('สรุปผลรวม (10)'!Q10<50,0)))) -> 0
A8: 4 | B8: ='เวลาเรียน (2)'!C9 -> เด็กชายสิรธีร์ เวียงอินทร์ | C8: =K8 -> 0 | D8: =C8 -> 0 | E8: =D8 -> 0 | F8: =E8 -> 0 | G8: =F8 -> 0 | H8: =G8 -> 0 | I8: =H8 -> 0 | J8: =I8 -> 0 | K8: =IF('สรุปผลรวม (10)'!Q11>70,3,IF('สรุปผลรวม (10)'!Q11>59,2,IF('สรุปผลรวม (10)'!Q11>49,1,IF('สรุปผลรวม (10)'!Q11<50,0)))) -> 0 | M8: =R8 -> 0 | N8: =M8 -> 0 | O8: =N8 -> 0 | P8: =O8 -> 0 | Q8: =P8 -> 0 | R8: =IF('สรุปผลรวม (10)'!Q11>74,3,IF('สรุปผลรวม (10)'!Q11>59,2,IF('สรุปผลรวม (10)'!Q11>49,1,IF('สรุปผลรวม (10)'!Q11<50,0)))) -> 0 | T8: =Y8 -> 0 | U8: =T8 -> 0 | V8: =U8 -> 0 | W8: =V8 -> 0 | X8: =W8 -> 0 | Y8: =IF('สรุปผลรวม (10)'!Q11>74,3,IF('สรุปผลรวม (10)'!Q11>59,2,IF('สรุปผลรวม (10)'!Q11>49,1,IF('สรุปผลรวม (10)'!Q11<50,0)))) -> 0
A9: 5 | B9: ='เวลาเรียน (2)'!C10 -> เด็กหญิงจิรภิญญา เขื่อนพงษ์ | C9: =K9 -> 0 | D9: =C9 -> 0 | E9: =D9 -> 0 | F9: =E9 -> 0 | G9: =F9 -> 0 | H9: =G9 -> 0 | I9: =H9 -> 0 | J9: =I9 -> 0 | K9: =IF('สรุปผลรวม (10)'!Q12>70,3,IF('สรุปผลรวม (10)'!Q12>59,2,IF('สรุปผลรวม (10)'!Q12>49,1,IF('สรุปผลรวม (10)'!Q12<50,0)))) -> 0 | M9: =R9 -> 0 | N9: =M9 -> 0 | O9: =N9 -> 0 | P9: =O9 -> 0 | Q9: =P9 -> 0 | R9: =IF('สรุปผลรวม (10)'!Q12>74,3,IF('สรุปผลรวม (10)'!Q12>59,2,IF('สรุปผลรวม (10)'!Q12>49,1,IF('สรุปผลรวม (10)'!Q12<50,0)))) -> 0 | T9: =Y9 -> 0 | U9: =T9 -> 0 | V9: =U9 -> 0 | W9: =V9 -> 0 | X9: =W9 -> 0 | Y9: =IF('สรุปผลรวม (10)'!Q12>74,3,IF('สรุปผลรวม (10)'!Q12>59,2,IF('สรุปผลรวม (10)'!Q12>49,1,IF('สรุปผลรวม (10)'!Q12<50,0)))) -> 0
A10: 6 | B10: ='เวลาเรียน (2)'!C11 -> เด็กหญิงภคพร วงค์สา | C10: =K10 -> 0 | D10: =C10 -> 0 | E10: =D10 -> 0 | F10: =E10 -> 0 | G10: =F10 -> 0 | H10: =G10 -> 0 | I10: =H10 -> 0 | J10: =I10 -> 0 | K10: =IF('สรุปผลรวม (10)'!Q13>70,3,IF('สรุปผลรวม (10)'!Q13>59,2,IF('สรุปผลรวม (10)'!Q13>49,1,IF('สรุปผลรวม (10)'!Q13<50,0)))) -> 0 | M10: =R10 -> 0 | N10: =M10 -> 0 | O10: =N10 -> 0 | P10: =O10 -> 0 | Q10: =P10 -> 0 | R10: =IF('สรุปผลรวม (10)'!Q13>74,3,IF('สรุปผลรวม (10)'!Q13>59,2,IF('สรุปผลรวม (10)'!Q13>49,1,IF('สรุปผลรวม (10)'!Q13<50,0)))) -> 0 | T10: =Y10 -> 0 | U10: =T10 -> 0 | V10: =U10 -> 0 | W10: =V10 -> 0 | X10: =W10 -> 0 | Y10: =IF('สรุปผลรวม (10)'!Q13>74,3,IF('สรุปผลรวม (10)'!Q13>59,2,IF('สรุปผลรวม (10)'!Q13>49,1,IF('สรุปผลรวม (10)'!Q13<50,0)))) -> 0
A11: 7 | B11: ='เวลาเรียน (2)'!C12 -> เด็กหญิงศิริณภา สุวรรณจันทร์ | C11: =K11 -> 0 | D11: =C11 -> 0 | E11: =D11 -> 0 | F11: =E11 -> 0 | G11: =F11 -> 0 | H11: =G11 -> 0 | I11: =H11 -> 0 | J11: =I11 -> 0 | K11: =IF('สรุปผลรวม (10)'!Q14>70,3,IF('สรุปผลรวม (10)'!Q14>59,2,IF('สรุปผลรวม (10)'!Q14>49,1,IF('สรุปผลรวม (10)'!Q14<50,0)))) -> 0 | M11: =R11 -> 0 | N11: =M11 -> 0 | O11: =N11 -> 0 | P11: =O11 -> 0 | Q11: =P11 -> 0 | R11: =IF('สรุปผลรวม (10)'!Q14>74,3,IF('สรุปผลรวม (10)'!Q14>59,2,IF('สรุปผลรวม (10)'!Q14>49,1,IF('สรุปผลรวม (10)'!Q14<50,0)))) -> 0 | T11: =Y11 -> 0 | U11: =T11 -> 0 | V11: =U11 -> 0 | W11: =V11 -> 0 | X11: =W11 -> 0 | Y11: =IF('สรุปผลรวม (10)'!Q14>74,3,IF('สรุปผลรวม (10)'!Q14>59,2,IF('สรุปผลรวม (10)'!Q14>49,1,IF('สรุปผลรวม (10)'!Q14<50,0)))) -> 0
A12: 8 | B12: ='เวลาเรียน (2)'!C13 -> เด็กหญิงศุภิสรา โม้แซง | C12: =K12 -> 0 | D12: =C12 -> 0 | E12: =D12 -> 0 | F12: =E12 -> 0 | G12: =F12 -> 0 | H12: =G12 -> 0 | I12: =H12 -> 0 | J12: =I12 -> 0 | K12: =IF('สรุปผลรวม (10)'!Q15>70,3,IF('สรุปผลรวม (10)'!Q15>59,2,IF('สรุปผลรวม (10)'!Q15>49,1,IF('สรุปผลรวม (10)'!Q15<50,0)))) -> 0 | M12: =R12 -> 0 | N12: =M12 -> 0 | O12: =N12 -> 0 | P12: =O12 -> 0 | Q12: =P12 -> 0 | R12: =IF('สรุปผลรวม (10)'!Q15>74,3,IF('สรุปผลรวม (10)'!Q15>59,2,IF('สรุปผลรวม (10)'!Q15>49,1,IF('สรุปผลรวม (10)'!Q15<50,0)))) -> 0 | T12: =Y12 -> 0 | U12: =T12 -> 0 | V12: =U12 -> 0 | W12: =V12 -> 0 | X12: =W12 -> 0 | Y12: =IF('สรุปผลรวม (10)'!Q15>74,3,IF('สรุปผลรวม (10)'!Q15>59,2,IF('สรุปผลรวม (10)'!Q15>49,1,IF('สรุปผลรวม (10)'!Q15<50,0)))) -> 0
A13: 9 | B13: ='เวลาเรียน (2)'!C14 -> เด็กหญิงสุพิชชา ชาวนาฮี | C13: =K13 -> 0 | D13: =C13 -> 0 | E13: =D13 -> 0 | F13: =E13 -> 0 | G13: =F13 -> 0 | H13: =G13 -> 0 | I13: =H13 -> 0 | J13: =I13 -> 0 | K13: =IF('สรุปผลรวม (10)'!Q16>70,3,IF('สรุปผลรวม (10)'!Q16>59,2,IF('สรุปผลรวม (10)'!Q16>49,1,IF('สรุปผลรวม (10)'!Q16<50,0)))) -> 0 | M13: =R13 -> 0 | N13: =M13 -> 0 | O13: =N13 -> 0 | P13: =O13 -> 0 | Q13: =P13 -> 0 | R13: =IF('สรุปผลรวม (10)'!Q16>74,3,IF('สรุปผลรวม (10)'!Q16>59,2,IF('สรุปผลรวม (10)'!Q16>49,1,IF('สรุปผลรวม (10)'!Q16<50,0)))) -> 0 | T13: =Y13 -> 0 | U13: =T13 -> 0 | V13: =U13 -> 0 | W13: =V13 -> 0 | X13: =W13 -> 0 | Y13: =IF('สรุปผลรวม (10)'!Q16>74,3,IF('สรุปผลรวม (10)'!Q16>59,2,IF('สรุปผลรวม (10)'!Q16>49,1,IF('สรุปผลรวม (10)'!Q16<50,0)))) -> 0
A14: 10
A15: 11
A16: 12
A17: 13
A18: 14
A19: 15
A20: 16
A21: 17
A22: 18
A23: 19
A24: 20
A25: 21
... A39: 35

Sheet ผลการเรียนรู้ (12)
I1: 12
A2: มาตรฐานและตัวชี้วัด /ผลการเรียนรู้
A3: ='ปก (1)'!C10&'ปก (1)'!E10&" "&'ปก (1)'!J10&" "&'ปก (1)'!L10 -> รายวิชาภาษาไทย รหัสวิชา ท11101

Sheet คำอธิบายการใช้ (13)
B1: คำอธิบายการใช้ ปพ.5 โรงเรียนบ้านขัวก่าย | K1: 13
A2: การบันทึกข้อมูลนักเรียน-เวลาเรียน
A3: 1 | B3: ชั่วโมงที่ ให้เขียนชั่วโมงที่สอนโดยนับต่อเนื่องกันไป จนสิ้นภาคเรียน เช่น 1,2,3,...,40 หรือ 1-2,3,4-5,6,...,60
A4: 2 | B4: การบันทึกเวลาเรียน ให้บันทึกรายละเอียดดังนี้
B5: 2.1 ผู้มาเรียน ให้เขียนเครื่องหมาย / ส่วนผู้ไม่มาเรียนให้ทำเครื่องหมาย O ด้วยหมึกสีแดง และระบุสาเหตุที่ไม่เข้า เช่น ลาป่วย "ป" ลากิจ "ล" ด้วยหมึกสีน้ำเงินหรือสีดำ
B6: ลงใน O แล้วแต่กรณี ถ้าขาดหรือไม่ทราบสาเหตุให้ทำเครื่องหมาย O
B7: 2.2 ถ้านักเรียนถูกพักการเรียนหรือย้ายหรือออกกลางคัน ให้ขีดเส้นแดงทับช่องตรงรายชื่อแล้วระบุสาเหตุไว้ที่ช่องหมายเหตุ ยกเว้นถูกสั่งพักการเรียนชั่วคราว
B8: (3,5,7 วัน โดยยังไม่ลาออก) ให้ปฏิบัติเหมือนกับการขาดเรียน
B9: 2.3 เมื่อสิ้นสุดสัปดาห์ที่ 5,10,15,18 และสิ้นสุดภาคเรียน ให้สรุปเวลามาเรียนไว้ในช่องรวมเวลารายภาค ถ้านักเรียนคนใดมีเวลาเรียนน้อยกว่าร้อยละ 80 ของรายวิชานั้นๆ
B10: ให้เขียนเวลาเรียนรวมด้วยหมึกสีแดง
A11: การบันทึกการพัฒนาคุณภาพผู้เรียน
A12: 1 | B12: ให้เขียนผลการเรียนรู้ไว้ในหน้าที่ 10 โดยแยกเป็นหน่วยและระบุมาตรฐานการเรียนรู้กลุ่มสาระหรือตัวชี้วัดให้ชัดเจน
A13: 2 | B13: ให้เขียนมาตรฐานการเรียนรู้กลุ่มสาระ ตัวชี้วัดหรือผลการเรียนรู้โดยแยกเป็นหน่วยให้ชัดเจน ไว้ในหน้า 10 และกำหนดรายละเอียดการประเมินผล เป็นคะแนนในช่องวิธีการวัดผล
B14: ในแต่ละข้อ ตามแผนการจัดการเรียนรู้
A15: 3 | B15: การบันทึกผลการประเมินคุณภาพผู้เรียนรายภาค มีรายละเอียดดังนี้
B16: 3.1 เขียนหมายเลขข้อผลการเรียนรู้หรือตัวชี้วัดและน้ำหนักคะแนนรวมในแต่ละข้อ (หน้า 5-7) และในช่องรวมให้เขียนคะแนนเต็ม สำหรับช่องซ่อมเสริมให้เขียนคะแนนตามเกณฑ์ผ่าน
B17: คือ ร้อยละ 60 ของคะแนนเต็ม
B18: 3.2 ให้กรอกคะแนนตามที่นักเรียนได้จริง ถ้าคะแนนไม่ผ่านเกณฑ์ (ต่ำกว่าร้อยละ 60) ให้ลงด้วยดินสอไว้ก่อนเมื่อซ่อมเสริมเสร็จ และผ่านเกณฑ์การประเมินจึงลงคะแนนด้วยปากกา
B19: 3.3 ถ้าผลการประเมินไม่ผ่านให้สอนซ่อมเสริม เพื่อให้นักเรียนมีความรู้ความสามารถตามเกณฑ์ของแต่ละผลการเรียนรู้ เมื่อสอบแก้ตัวเสร็จแล้วให้กรอกคะแนนตามเกณฑ์ที่สถานศึกษา
B20: กำหนด (ไม่น้อยกว่าร้อยละ 60)
A21: 4 | B21: การสรุปผลการประเมินคุณภาพผู้เรียนในหน้า 8 ให้นำคะแนนแต่ละหน่วยจากหน้า 5-7 บันทึกลงในช่องรายหน่วย แล้วรวมกับคะแนนสอบกลางภาคและคะแนนสอบปลายภาค
A22: 5 | B22: เปลี่ยนระดับคะแนนที่ได้เป็นผลการเรียน โดยใช้ช่วงระดับคะแนนดังนี้
D23: ช่วงคะแนนเป็นร้อยละ | F23: ระดับผลการเรียน
D24: 80 - 100 | F24: 4
D25: 75 - 79 | F25: 3.5
D26: 70 - 74 | F26: 3
D27: 65 - 69 | F27: 2.5
D28: 60 - 64 | F28: 2
D29: 55 - 59 | F29: 1.5
D30: 50 - 54 | F30: 1
D31: 0 - 49 | F31: 0
A32: 6 | B32: สรุปจำนวนนักเรียนที่ได้ผลการเรียน 4, 3.5, 3, 2.5, 2, 1.5, 1, 0 หรือ "ร" , "มส" ,"มก" ไว้ในช่องสรุปผลการเรียน (หน้าแรก)
A33: การบันทึกผลการประเมินคุณลักษณะอันพึงประสงค์
A34: 1 | B34: การประเมินคุณลักษณะอันพึงประสงค์ให้ประเมินควบคู่ไปกับการประเมินผลการเรียนในแต่ละกิจกรรมในหน่วยการเรียนรู้ประเมินตามคุณลักษณะอันพึงประสงค์ตามที่
B35: สำนักงานคณะกรรมการการศึกษาขั้นพื้นฐานกำหนดไว้ จำนวน 8 ข้อ (อยู่ในหน้า 9)
A36: 2 | B36: ให้เขียนระดับการประเมินในแต่ละข้อ ลงในหน้า 9 โดยยึดการประเมินตามหลักสูตรแกนกลางการศึกษาขั้นพื้นฐาน พุทธศักราช 2551 (หน้า12)
A37: 3 | B37: การสรุปผลการประเมิน ให้นำช่องสรุปของทุกข้อมาหาฐานนิยมและกรอกลงในช่องสรุปผล
A38: 4 | B38: ระดับของการประเมิน มีความหมายดังนี้
C39: ระดับ | D39: ความหมาย
C40: 3 | D40: ดีเยี่ยม | F40: มีพฤติกรรมสูงกว่าเกณฑ์ในระดับดีเยี่ยม
...

Sheet คำอธิบายการใช้ (14)
J1: 14
A2: การบันทึกผลการประเมินการอ่าน คิดวิเคราะห์ และเขียนสื่อความ
A3: 1 | B3: ให้ประเมินทักษะการอ่าน คิดวิเคราะห์ และเขียนสื่อความ ตามที่สำนักงานคณะกรรมการการศึกษาขั้นพื้นฐานกำหนดไว้ จำนวน 5 ข้อ (อยู่ในหน้า 9)
A4: 2 | B4: การประเมินการอ่าน คิดวิเคราะห์ และเขียนสื่อความ ให้ประเมินด้วยวิธีการที่หลากหลายที่สะท้อนถึงการอ่าน คิดวิเคราะห์ และเขียนสื่อความ โดยประเมินควบคู่ไปกับ
B5: การประเมินผลการเรียนในแต่ละกิจกรรมในหน่วยการเรียนรู้
A6: 3 | B6: ให้เขียนระดับการประเมินในแต่ละข้อ ลงในหน้า 9
A7: 4 | B7: การสรุปผลการประเมิน ให้นำช่องสรุปของทุกข้อมาหาฐานนิยมและกรอกลงในช่องสรุปผล
A8: 5 | B8: ระดับของการประเมิน มีความหมายดังนี้
C9: ระดับ | D9: ความหมาย
C10: 3 | D10: ดีเยี่ยม | F10: มีความสามารถในระดับดีเยี่ยม
C11: 2 | D11: ดี | F11: มีความสามารถในระดับดี
C12: 1 | D12: ผ่านเกณฑ์ | F12: มีความสามารถตามเกณฑ์ที่สถานศึกษากำหนด
C13: 0 | D13: ควรปรับปรุง | F13: ควรปรับปรุง
A14: 6 | B14: กรณีที่ผู้เรียนมีผลการประเมินย่อยเป็น 0 ให้ดำเนินการปรับปรุงพัฒนาทักษะการอ่าน คิดวิเคราะห์และเขียนสื่อความของผู้เรียนให้ผ่านเกณฑ์และแก้ไขได้ระดับไม่เกิน 1
A15: 7 | B15: สรุปจำนวนนักเรียนที่มีผลการประเมิน 3,2,1,0 ไว้ในช่องผลการประเมินการอ่าน คิดวิเคราะห์ และเขียนสื่อความ (หน้าแรก)
A16: 8 | B16: กรณีที่ผู้เรียนมีผลการประเมินรวมเป็น 0 ให้ดำเนินการปรับปรุงพัฒนาทักษะการอ่าน คิดวิเคราะห์และเขียนสื่อความของผู้เรียน ให้ผ่านเกณฑ์ในภาคเรียนถัดไป
A17: คุณลักษณะอันพึงประสงค์ ตามหลักสูตรแกนกลางการศึกษาขั้นพื้นฐาน พุทธศักราช 2551
B18: คุณลักษณะที่พึงประสงค์ | D18: ตัวชี้วัด
B19: 1. รักชาติ ศาสน์ กษัตริย์ | D19: 1.1 เป็นพลเมืองดีของชาติ
D20: 1.2 ธำรงไว้ซึ่งความเป็นชาติไทย
D21: 1.3 ศรัทธา ยึดมั่น และปฏิบัติตนตามหลักของศาสนา
D22: 1.4 เคารพเทิดทูนพระมหากษัตริย์
B23: 2. ซื่อสัตย์สุจริต | D23: 2.1 ประพฤติตนตามความเป็นจริงต่อตนเอง ทั้งกาย วาจา ใจ
D24: 2.2 ประพฤติตนตามความเป็นจริงต่อผู้อื่น ทั้งกาย วาจา ใจ
B25: 3. มีวินัย | D25: 3.1 ปฏิบัติตามข้อตกลง กฎเกณฑ์ ระเบียบ ข้อบังคับของครอบครัว โรงเรียนและสังคม
B26: 4. ใฝ่เรียนรู้ | D26: 4.1 ตั้งใจ เพียรพยายามในการเรียนและเข้าร่วมกิจกรรมการเรียนรู้
D27: 4.2 แสวงหาความรู้จากแหล่งเรียนรู้ต่างๆ ทั้งภายในและภายนอกโรงเรียน ด้วยการเลือกสื่ออย่างเหมาะสม บันทึกความรู้
D28: วิเคราะห์ สรุปเป็นองค์ความรู้ สามารถนำไปใช้นีวิตประจำวันได้
B29: 5. อยู่อย่างพอเพียง | D29: 5.1 ดำเนินชีวิตอย่างพอประมาณ มีเหตุผล รอบคอบ มีคุณธรรม
D30: 5.2 มีภูมิคุ้มกันในตัวที่ดี เพื่อปรับตัวอยู่ในสังคมได้อย่างมีความสุข
B31: 6. มุ่งมั่นในการทำงาน | D31: 6.1 ตั้งใจและรับผิดชอบในการปฏิบัติหน้าที่การงาน
D32: 6.2 ทำงานด้วยความเพียรพยายามและอดทนเพื่อให้งานสำเร็จตามเป้าหมาย
B33: 7. รักความเป็นไทย | D33: 7.1 ภาคภูมิใจในขนบธรรมเนียมประเพณี ศิลปะ วัฒนธรรมไทย มีความกตัญญูกตเวที
D34: 7.2 เห็นคุณค่าและใช้ภาษาไทยในการสื่อสารได้อย่างถูกต้อง เหมาะสม
D35: 7.3 อนุรักษ์และสืบทอดภูมิปัญญาไทย
B36: 8. มีจิตสาธารณะ | D36: 8.1 ช่วยเหลือผู้อื่นด้วยความเต็มใจและพึงพอใจ โดยไม่หวังผลตอบแทน
D37: 8.2 เข้าร่วมกิจกรรมที่เป็นประโยน์ต่อโรงเรียน ชุมชน และสังคม
B39: การอ่าน คิดวิเคราะห์และเขียนสื่อความ โรงเรียนบ้านขัวก่าย
B40: 1. สามารถคัดสรรสื่อที่ต้องการอ่านเพื่อหาข้อมูลสารสนเทศได้ตามวัตถุประสงค์
B41: 2. สามารถจับประเด็นสำคัญและประเด็นสนับสนุน โต้แย้ง
...

Sheet ผลการเรียน
A1: ="ผลการเรียนนักเรียน"&" "&'ปก (1)'!C9&" "&'ปก (1)'!G9 -> ผลการเรียนนักเรียน ระดับชั้นประถมศึกษาปีที่ 1
A2: ='ปก (1)'!M9&" "&'ปก (1)'!O9 -> ปีการศึกษา 2569
A3: โรงเรียนบ้านขัวก่าย สำนักงานเขตพื้นที่การศึกษาประถมศึกษาสกลนคร เขต 3
B5: รายวิชา | C5: ='ปก (1)'!E10 -> ภาษาไทย | E5: รหัสวิชา | F5: ='ปก (1)'!L10 -> ท11101 | G5: ครูผู้สอน | I5: ='ปก (1)'!E12 -> นางสุพรรณี สุวะศรี
B7: เลขที่ | C7: เลขประจำตัว | D7: ชื่อ-นามสกุล | E7: คะแนน | F7: ผลการเรียน | G7: ผลการประเมิน | K7: จำนวนนักเรียน
E8: 100 | G8: ลักษณะอันพึงประสงค์ | H8: การอ่าน คิดวิเคราะห์ฯ | I8: สมรรถนะสำคัญฯ | K8: ชาย | L8: หญิง | M8: รวม
B9: 1 | C9: ='เวลาเรียน (2)'!B6 -> 4997 | D9: ='เวลาเรียน (2)'!C6 -> เด็กชายธนาธร กิติกาแดง | E9: ='สรุปผลรวม (10)'!Q8 -> 0 | F9: ='สรุปผลรวม (10)'!R8 -> 0 | G9: ='คุณลักษณะ -อ่าน -สมรรถนะ(11)'!K5 -> 0 | H9: ='คุณลักษณะ -อ่าน -สมรรถนะ(11)'!R5 -> 0 | I9: ='คุณลักษณะ -อ่าน -สมรรถนะ(11)'!Y5 -> 0 | K9: =COUNTIF(D9:D33, "เด็กชาย*") -> 4 | L9: =COUNTIF(D9:D33, "เด็กหญิง*") -> 5 | M9: =SUM(K9:L9) -> 9
B10: 2 | C10: ='เวลาเรียน (2)'!B7 -> 4998 | D10: ='เวลาเรียน (2)'!C7 -> เด็กชายนิรวุฒิ วันทอง | E10: ='สรุปผลรวม (10)'!Q9 -> 0 | F10: ='สรุปผลรวม (10)'!R9 -> 0 | G10: ='คุณลักษณะ -อ่าน -สมรรถนะ(11)'!K6 -> 0 | H10: ='คุณลักษณะ -อ่าน -สมรรถนะ(11)'!R6 -> 0 | I10: ='คุณลักษณะ -อ่าน -สมรรถนะ(11)'!Y6 -> 0
B11: 3 | C11: ='เวลาเรียน (2)'!B8 -> 4999 | D11: ='เวลาเรียน (2)'!C8 -> เด็กชายศรันยู รัตนมงคล | E11: ='สรุปผลรวม (10)'!Q10 -> 0 | F11: ='สรุปผลรวม (10)'!R10 -> 0 | G11: ='คุณลักษณะ -อ่าน -สมรรถนะ(11)'!K7 -> 0 | H11: ='คุณลักษณะ -อ่าน -สมรรถนะ(11)'!R7 -> 0 | I11: ='คุณลักษณะ -อ่าน -สมรรถนะ(11)'!Y7 -> 0 | K11: ผลการเรียน
B12: 4 | C12: ='เวลาเรียน (2)'!B9 -> 5000 | D12: ='เวลาเรียน (2)'!C9 -> เด็กชายสิรธีร์ เวียงอินทร์ | E12: ='สรุปผลรวม (10)'!Q11 -> 0 | F12: ='สรุปผลรวม (10)'!R11 -> 0 | G12: ='คุณลักษณะ -อ่าน -สมรรถนะ(11)'!K8 -> 0 | H12: ='คุณลักษณะ -อ่าน -สมรรถนะ(11)'!R8 -> 0 | I12: ='คุณลักษณะ -อ่าน -สมรรถนะ(11)'!Y8 -> 0 | K12: เกรด | L12: จำนวน | M12: ร้อยละ
B13: 5 | C13: ='เวลาเรียน (2)'!B10 -> 5001 | D13: ='เวลาเรียน (2)'!C10 -> เด็กหญิงจิรภิญญา เขื่อนพงษ์ | E13: ='สรุปผลรวม (10)'!Q12 -> 0 | F13: ='สรุปผลรวม (10)'!R12 -> 0 | G13: ='คุณลักษณะ -อ่าน -สมรรถนะ(11)'!K9 -> 0 | H13: ='คุณลักษณะ -อ่าน -สมรรถนะ(11)'!R9 -> 0 | I13: ='คุณลักษณะ -อ่าน -สมรรถนะ(11)'!Y9 -> 0 | K13: 4 | L13: =COUNTIF($F$9:$F$33,K13) -> 0 | M13: =L13*100/$M$9 -> 0
B14: 6 | C14: ='เวลาเรียน (2)'!B11 -> 5002 | D14: ='เวลาเรียน (2)'!C11 -> เด็กหญิงภคพร วงค์สา | E14: ='สรุปผลรวม (10)'!Q13 -> 0 | F14: ='สรุปผลรวม (10)'!R13 -> 0 | G14: ='คุณลักษณะ -อ่าน -สมรรถนะ(11)'!K10 -> 0 | H14: ='คุณลักษณะ -อ่าน -สมรรถนะ(11)'!R10 -> 0 | I14: ='คุณลักษณะ -อ่าน -สมรรถนะ(11)'!Y10 -> 0 | K14: 3.5 | L14: =COUNTIF($F$9:$F$33,K14) -> 0 | M14: =L14*100/$M$9 -> 0
B15: 7 | C15: ='เวลาเรียน (2)'!B12 -> 5003 | D15: ='เวลาเรียน (2)'!C12 -> เด็กหญิงศิริณภา สุวรรณจันทร์ | E15: ='สรุปผลรวม (10)'!Q14 -> 0 | F15: ='สรุปผลรวม (10)'!R14 -> 0 | G15: ='คุณลักษณะ -อ่าน -สมรรถนะ(11)'!K11 -> 0 | H15: ='คุณลักษณะ -อ่าน -สมรรถนะ(11)'!R11 -> 0 | I15: ='คุณลักษณะ -อ่าน -สมรรถนะ(11)'!Y11 -> 0 | K15: 3 | L15: =COUNTIF($F$9:$F$33,K15) -> 0 | M15: =L15*100/$M$9 -> 0
B16: 8 | C16: ='เวลาเรียน (2)'!B13 -> 5004 | D16: ='เวลาเรียน (2)'!C13 -> เด็กหญิงศุภิสรา โม้แซง | E16: ='สรุปผลรวม (10)'!Q15 -> 0 | F16: ='สรุปผลรวม (10)'!R15 -> 0 | G16: ='คุณลักษณะ -อ่าน -สมรรถนะ(11)'!K12 -> 0 | H16: ='คุณลักษณะ -อ่าน -สมรรถนะ(11)'!R12 -> 0 | I16: ='คุณลักษณะ -อ่าน -สมรรถนะ(11)'!Y12 -> 0 | K16: 2.5 | L16: =COUNTIF($F$9:$F$33,K16) -> 0 | M16: =L16*100/$M$9 -> 0
B17: 9 | C17: ='เวลาเรียน (2)'!B14 -> 5005 | D17: ='เวลาเรียน (2)'!C14 -> เด็กหญิงสุพิชชา ชาวนาฮี | E17: ='สรุปผลรวม (10)'!Q16 -> 0 | F17: ='สรุปผลรวม (10)'!R16 -> 0 | G17: ='คุณลักษณะ -อ่าน -สมรรถนะ(11)'!K13 -> 0 | H17: ='คุณลักษณะ -อ่าน -สมรรถนะ(11)'!R13 -> 0 | I17: ='คุณลักษณะ -อ่าน -สมรรถนะ(11)'!Y13 -> 0 | K17: 2 | L17: =COUNTIF($F$9:$F$33,K17) -> 0 | M17: =L17*100/$M$9 -> 0
K18: 1.5 | L18: =COUNTIF($F$9:$F$33,K18) -> 0 | M18: =L18*100/$M$9 -> 0
K19: 1 | L19: =COUNTIF($F$9:$F$33,K19) -> 0 | M19: =L19*100/$M$9 -> 0
K20: 0 | L20: =COUNTIF($F$9:$F$33,K20) -> 9 | M20: =L20*100/$M$9 -> 100
K21: ร | L21: =COUNTIF($F$9:$F$33,K21) -> 0 | M21: =L21*100/$M$9 -> 0
K22: มส | L22: =COUNTIF($F$9:$F$33,K22) -> 0 | M22: =L22*100/$M$9 -> 0
K23: รวม | L23: =SUM(L13:L22) -> 9 | M23: =L23*100/$M$9 -> 100
K25: คุณลักษณะอันพึงประสงค์
K26: 3 | L26: =COUNTIF($G$9:$G$33,K26) -> 0 | M26: =L26*100/$M$9 -> 0
K27: 2 | L27: =COUNTIF($G$9:$G$33,K27) -> 0 | M27: =L27*100/$M$9 -> 0
K28: 1 | L28: =COUNTIF($G$9:$G$33,K28) -> 0 | M28: =L28*100/$M$9 -> 0
K29: 0 | L29: =COUNTIF($G$9:$G$33,K29) -> 9 | M29: =L29*100/$M$9 -> 100
K30: รวม | L30: =SUM(L26:L29) -> 9 | M30: =L30*100/$M$9 -> 100
K32: การอ่าน คิดวิเคราห์ฯ
K33: 3 | L33: =COUNTIF($H$9:$H$33,K33) -> 0 | M33: =L33*100/$M$9 -> 0
B34: ผลการเรียนเฉลี่ย | E34: =SUM(E9:E33) -> 0 | F34: =AVERAGE(F9:F33) -> 0 | K34: 2 | L34: =COUNTIF($H$9:$H$33,K34) -> 0 | M34: =L34*100/$M$9 -> 0
K35: 1 | L35: =COUNTIF($H$9:$H$33,K35) -> 0 | M35: =L35*100/$M$9 -> 0
D36: (ลงชื่อ).....................................................ครูผู้สอน | K36: 0 | L36: =COUNTIF($H$9:$H$33,K36) -> 9 | M36: =L36*100/$M$9 -> 100
D37: ="("&I5&")" -> (นางสุพรรณี สุวะศรี) | K37: รวม | L37: =SUM(L33:L36) -> 9 | M37: =L37*100/$M$9 -> 100
D38: ...../............../.......
D39: (ลงชื่อ).....................................................งานวัดผล | K39: สมรรถนะสำคัญของผู้เรียน
D40: (นางขวัญจิต สุวรรณคุณ) | K40: 3 | L40: =COUNTIF($I$9:$I$33,K40) -> 0 | M40: =L40*100/$M$9 -> 0
D41: ...../............../....... | K41: 2 | L41: =COUNTIF($I$9:$I$33,K41) -> 0 | M41: =L41*100/$M$9 -> 0
D42: (ลงชื่อ).....................................................ผู้อำนวยการโรงเรียน | K42: 1 | L42: =COUNTIF($I$9:$I$33,K42) -> 0 | M42: =L42*100/$M$9 -> 0
D43: (นายอภัย ปังอุทา) | K43: 0 | L43: =COUNTIF($I$9:$I$33,K43) -> 9 | M43: =L43*100/$M$9 -> 100
D44: ...../............../....... | K44: รวม | L44: =SUM(L40:L43) -> 9 | M44: =L44*100/$M$9 -> 100
